Workbook
Name A_Ja_Nein_Liste: [1]sysAuswahl!$A$5:$A$6
Name A_Ja_Nein_Rev: [1]sysAuswahl!$F$5:$G$7
Name A_Ja_Nein_Wert: [1]sysAuswahl!$C$5:$D$7
Name A_MASSN_Liste: [1]sysAuswahl!$A$23:$A$31
Name A_MASSN_Rev: [1]sysAuswahl!$F$23:$G$32
Name A_MASSN_Wert: [1]sysAuswahl!$C$23:$D$32
Name A_ProjArt_Liste: [1]sysAuswahl!$A$14:$A$16
Name F_FondsBez: [1]Eingabe_1_bis_4!$F$15
Name F_Massnahme: [1]Eingabe_1_bis_4!$F$19
Name F_MONSYS_Aktenzeichen: [1]Eingabe_1_bis_4!$F$7
Name F_MONSYS_Eingangsdatum: [1]Eingabe_1_bis_4!$F$5
Name F_MONSYS_eingegangenBei: [1]Eingabe_1_bis_4!$F$4
Name F_MONSYS_FassungVom: [1]Eingabe_1_bis_4!$F$6
Name F_MONSYS_Projektcode: [1]Eingabe_1_bis_4!$F$9
Name F_MONSYS_Vertragsnummer: [1]Eingabe_1_bis_4!$F$8
Name F_PA1_Ansprech: [1]Eingabe_5!$F$20
Name F_PA1_Email: [1]Eingabe_5!$F$26
Name F_PA1_Fax: [1]Eingabe_5!$F$24
Name F_PA1_Telefon: [1]Eingabe_5!$F$22
Name F_PA2_Ansprech: [1]Eingabe_5!$F$44
Name F_PA2_Email: [1]Eingabe_5!$F$50
Name F_PA2_Fax: [1]Eingabe_5!$F$48
Name F_PA2_Telefon: [1]Eingabe_5!$F$46
Name F_PK_KACode_L00: [1]Eingabe_6!$F$48
Name F_PK_KACode_L01: [1]Eingabe_6!$F$52
Name F_PK_KACode_L02: [1]Eingabe_6!$F$56
Name F_PK_KACode_L03: [1]Eingabe_6!$F$60
Name F_PK_KACode_L04: [1]Eingabe_6!$F$64
Name F_PK_KACode_L05: [1]Eingabe_6!$F$68
Name F_PK_KACode_L06: [1]Eingabe_6!$F$72
Name F_PK_KACode_L07: [1]Eingabe_6!$F$76
Name F_PK_KACode_L08: [1]Eingabe_6!$F$80
Name F_PK_KACode_L09: [1]Eingabe_6!$F$84
Name F_PK_PK_Notiz_L00: [1]Eingabe_6!$F$50
Name F_PK_PK_Notiz_L01: [1]Eingabe_6!$F$54
Name F_PK_PK_Notiz_L02: [1]Eingabe_6!$F$58
Name F_PK_PK_Notiz_L03: [1]Eingabe_6!$F$62
Name F_PK_PK_Notiz_L04: [1]Eingabe_6!$F$66
Name F_PK_PK_Notiz_L05: [1]Eingabe_6!$F$70
Name F_PK_PK_Notiz_L06: [1]Eingabe_6!$F$74
Name F_PK_PK_Notiz_L07: [1]Eingabe_6!$F$78
Name F_PK_PK_Notiz_L08: [1]Eingabe_6!$F$82
Name F_PK_PK_Notiz_L09: [1]Eingabe_6!$F$86
Name F_PK_Z01: [1]Eingabe_6!$F$34
Name F_PK_Z02: [1]Eingabe_6!$F$36
Name F_PK_Z03: [1]Eingabe_6!$F$38
Name F_PK_Z04: [1]Eingabe_6!$F$40
Name F_PR_AZVFS: [1]Eingabe_1_bis_4!$F$25
Name F_PR_FEAnsprech: [1]Eingabe_1_bis_4!$F$71
Name F_PR_FEAnsprech_Email: [1]Eingabe_1_bis_4!$F$77
Name F_PR_FEAnsprech_Fax: [1]Eingabe_1_bis_4!$F$75
Name F_PR_FEAnsprech_Telefon: [1]Eingabe_1_bis_4!$F$73
Name F_PR_FEBLZ: [1]Eingabe_1_bis_4!$F$87
Name F_PR_FEKontonr: [1]Eingabe_1_bis_4!$F$85
Name F_PR_FeMWST: [1]Eingabe_1_bis_4!$F$61
Name F_PR_FEZeichBerecht: [1]Eingabe_1_bis_4!$F$57
Name F_PR_Grenzland: [1]Eingabe_1_bis_4!$F$67
Name F_PR_Link: [1]Eingabe_1_bis_4!$F$81
Name F_PR_Projdf_anf: [1]Eingabe_6!$F$7
Name F_PR_Projdf_end: [1]Eingabe_6!$F$9

Sheet Overview IB
C3: Indikatorenbericht Nationale Integrationsförderung 2022 und 2023 | S3: Bitte auswählen! | T3: Bitte auswählen! | U3: Bitte auswählen!
C4: Projektträger/-in | D4: TARO - Verein zur interkulturellen Gesundheitsförderung | K4: Burgenland | S4: Sprache und Bildung | T4: Frauen | U4: Burgenland
C5: Projekttitel | D5: Wurzeln fassen – Traumasensible Begleitung | K5: Kärnten | S5: Arbeit und Beruf | T5: Deutsch | U5: Kärnten
C6: Projektnummer | K6: Niederösterreich | N6: 0.05 | S6: Rechtsstaat und Werte | T6: Kinder, Jugendliche und Elternarbeit | U6: Niederösterreich
C7: Handlungsfeld | D7: Gesundheit, Soziales | K7: Oberösterreich | S7: Gesundheit und Soziales | T7: Gemeinde und Identität | U7: Oberösterreich
C8: Förderschwerpunkt | D8: Kinder, Jugendliche und Elternarbeit | K8: Salzburg | S8: Interkultureller Dialog | T8: Arbeitsmarkt | U8: Salzburg
C9: Standort Projektmanagment | D9: Wien | K9: Steiermark | N9: 0.2 | S9: Sport und Freizeit | T9: Sport und Freizeit | U9: Steiermark
C10: Haupttprojektstandort | D10: Wien | K10: Tirol | S10: Wohnen und die regionale Dimension der Integration | T10: x | U10: Tirol
C11: Laufzeit Beginn | D11: 44562 | K11: Vorarlberg | N11: 0.05 | T11: x | U11: Vorarlberg
C12: Laufzeit Ende | D12: 45291 | K12: Wien | N12: 0.7 | U12: Wien
C13: Projektdauer in Monaten | D13: =IF(IF(OR(D11="",D12=""),"",(D12-D11)/30)="","befüllt sich automatisch",IF(OR(D11="",D12=""),"",(D12-D11)/30)) -> 24.3
H14: Anteil an Laufzeit | I14: ='1. ZWB '!D7 -> 0.24691358 | K14: Anteil an Laufzeit | L14: ='2. ZWB '!D7 -> 0.49931413 | N14: Anteil an Laufzeit | O14: ='3. ZWB '!D7 -> 0.74759945 | Q14: Anteil an Laufzeit | R14: ='EB '!D7 -> 1
C15: Zielindikatoren | D15: Anzahl SOLL | H15: IST bis 1.ZWB | I15: Erfüllt in % | K15: IST bis 2.ZWB | L15: Erfüllt in % | N15: IST bis 3.ZWB | O15: Erfüllt in % | Q15: IST bis Endbericht | R15: Erfüllt in %
C16: Anzahl der Projektteilnehmenden gesamt | D16: 818 | H16: ='1. ZWB '!H10 -> 336 | I16: ='1. ZWB '!I10 -> 0.41075795 | K16: ='2. ZWB '!H10 -> 607 | L16: ='2. ZWB '!I10 -> 0.74205379 | N16: ='3. ZWB '!H10 -> 1045 | O16: ='3. ZWB '!I10 -> 1.2775061 | P16: =IF(O16=0,0,O16/D16) -> 0.0015617434 | Q16: ='EB '!H10 -> 1204 | R16: ='EB '!I10 -> 1.4718826
C17: Bereich Veranstaltungen | D17: Anzahl SOLL | E17: Bezeichnung der Maßnahme (lt. Projektbeschreibung)
C18: Anzahl der Veranstaltungen | D18: 38 | E18: Elterninfo parallel zum TRT Programm | H18: ='1. ZWB '!H12 -> 3 | I18: ='1. ZWB '!I12 -> 0.078947368 | K18: ='2. ZWB '!H12 -> 10 | L18: ='2. ZWB '!I12 -> 0.26315789 | N18: ='3. ZWB '!H12 -> 41 | O18: ='3. ZWB '!I12 -> 1.0789474 | Q18: ='EB '!H12 -> 45 | R18: ='EB '!I12 -> 1.1842105
C19: Anzahl der Veranstaltungsteilnehmenden gesamt | D19: 190 | H19: ='1. ZWB '!H13 -> 18 | I19: ='1. ZWB '!I13 -> 0.094736842 | K19: ='2. ZWB '!H13 -> 59 | L19: ='2. ZWB '!I13 -> 0.31052632 | N19: ='3. ZWB '!H13 -> 214 | O19: ='3. ZWB '!I13 -> 1.1263158 | Q19: ='EB '!H13 -> 233 | R19: ='EB '!I13 -> 1.2263158
C20: Anzahl der Kurse/Workshops/Trainings | D20: 10 | E20: a) Traumapädagogische Seminare für Lehrkräfte b) Aus- und Fortbildung von mutterprachlichen TRT TrainerInnen | H20: ='1. ZWB '!H14 -> 7 | I20: ='1. ZWB '!I14 -> 0.7 | K20: ='2. ZWB '!H14 -> 15 | L20: ='2. ZWB '!I14 -> 1.5 | N20: ='3. ZWB '!H14 -> 22 | O20: ='3. ZWB '!I14 -> 2.2 | Q20: ='EB '!H14 -> 23 | R20: ='EB '!I14 -> 2.3
C21: Anzahl der Kurs-, Workshop- bzw. Trainingsplätze | H21: ='1. ZWB '!H15 -> 0 | I21: ='1. ZWB '!I15 -> 0 | K21: ='2. ZWB '!H15 -> 0 | L21: ='2. ZWB '!I15 -> 0 | N21: ='3. ZWB '!H15 -> 0 | O21: ='3. ZWB '!I15 -> 0 | Q21: ='EB '!H15 -> 0 | R21: ='EB '!I15 -> 0
C22: Anzahl der Teilnehmenden an Kursen/Workshops/ Trainings | D22: 162 | H22: ='1. ZWB '!H16 -> 162 | I22: ='1. ZWB '!I16 -> 1 | K22: ='2. ZWB '!H16 -> 279 | L22: ='2. ZWB '!I16 -> 1.7222222 | N22: ='3. ZWB '!H16 -> 268 | O22: ='3. ZWB '!I16 -> 1.654321 | Q22: ='EB '!H16 -> 292 | R22: ='EB '!I16 -> 1.8024691
C23: Anzahl der Kurs-, Workshop- bzw. Trainingsstunden | D23: 60 | H23: ='1. ZWB '!H17 -> 65 | I23: ='1. ZWB '!I17 -> 1.0833333 | K23: ='2. ZWB '!H17 -> 139 | L23: ='2. ZWB '!I17 -> 2.3166667 | N23: ='3. ZWB '!H17 -> 291 | O23: ='3. ZWB '!I17 -> 4.85 | Q23: ='EB '!H17 -> 299 | R23: ='EB '!I17 -> 4.9833333
C24: Bereich Beratung | D24: Anzahl SOLL | E24: Bezeichnung der Maßnahme (lt. Projektbeschreibung) | H24: IST | I24: Erfüllt in % | K24: IST | L24: Erfüllt in % | N24: IST | O24: Erfüllt in % | Q24: IST | R24: Erfüllt in %
C25: Anzahl der Einzelberatungen bzw. -betreuung | D25: 100 | E25: Begleitgespräche zum Traumaprogramm | H25: ='1. ZWB '!H19 -> 24 | I25: ='1. ZWB '!I19 -> 0.24 | K25: ='2. ZWB '!H19 -> 50 | L25: ='2. ZWB '!I19 -> 0.5 | N25: ='3. ZWB '!H19 -> 70 | O25: ='3. ZWB '!I19 -> 0.7 | Q25: ='EB '!H19 -> 80 | R25: ='EB '!I19 -> 0.8
C26: Anzahl der in Einzelberatung beratenen, betreuten oder gecoachten Personen | D26: 50 | H26: ='1. ZWB '!H20 -> 16 | I26: ='1. ZWB '!I20 -> 0.32 | K26: ='2. ZWB '!H20 -> 35 | L26: ='2. ZWB '!I20 -> 0.7 | N26: ='3. ZWB '!H20 -> 50 | O26: ='3. ZWB '!I20 -> 1 | Q26: ='EB '!H20 -> 54 | R26: ='EB '!I20 -> 1.08
C27: Anzahl der Einzelberatungs-/Betreuungs-/ Coachingstunden | D27: 100 | H27: ='1. ZWB '!H21 -> 18 | I27: ='1. ZWB '!I21 -> 0.18 | K27: ='2. ZWB '!H21 -> 35 | L27: ='2. ZWB '!I21 -> 0.35 | N27: ='3. ZWB '!H21 -> 50 | O27: ='3. ZWB '!I21 -> 0.5 | Q27: ='EB '!H21 -> 54 | R27: ='EB '!I21 -> 0.54
C28: Anzahl der Gruppenberatungen bzw. -betreuung (min. 3 Personen) | D28: 60 | E28: i) TRT Programm ii) Gesundheitskreise für Eltern | H28: ='1. ZWB '!H22 -> 13 | I28: ='1. ZWB '!I22 -> 0.21666667 | K28: ='2. ZWB '!H22 -> 24 | L28: ='2. ZWB '!I22 -> 0.4 | N28: ='3. ZWB '!H22 -> 59 | O28: ='3. ZWB '!I22 -> 0.98333333 | Q28: ='EB '!H22 -> 70 | R28: ='EB '!I22 -> 1.1666667
C29: Anzahl der in Gruppenberatung beratenen oder betreuten Personen | D29: 426 | H29: ='1. ZWB '!H23 -> 105 | I29: ='1. ZWB '!I23 -> 0.24647887 | K29: ='2. ZWB '!H23 -> 184 | L29: ='2. ZWB '!I23 -> 0.43192488 | N29: ='3. ZWB '!H23 -> 513 | O29: ='3. ZWB '!I23 -> 1.2042254 | Q29: ='EB '!H23 -> 617 | R29: ='EB '!I23 -> 1.4483568
C30: Anzahl der Gruppenberatungs-/Betreuungsstunden | D30: 960 | H30: ='1. ZWB '!H24 -> 126 | I30: ='1. ZWB '!I24 -> 0.13125 | K30: ='2. ZWB '!H24 -> 258 | L30: ='2. ZWB '!I24 -> 0.26875 | N30: ='3. ZWB '!H24 -> 1080 | O30: ='3. ZWB '!I24 -> 1.125 | Q30: ='EB '!H24 -> 1280 | R30: ='EB '!I24 -> 1.3333333
C31: Anzahl der Familienberatungen (pro Familie) | D31: 10 | E31: TRT Family | H31: ='1. ZWB '!H25 -> 8 | I31: ='1. ZWB '!I25 -> 0.8 | K31: ='2. ZWB '!H25 -> 8 | L31: ='2. ZWB '!I25 -> 0.8 | N31: ='3. ZWB '!H25 -> 8 | O31: ='3. ZWB '!I25 -> 0.8 | Q31: ='EB '!H25 -> 8 | R31: ='EB '!I25 -> 0.8
C32: Anzahl der familienberatenen oder betreuten Personen | D32: 30 | H32: ='1. ZWB '!H26 -> 35 | I32: ='1. ZWB '!I26 -> 1.1666667 | K32: ='2. ZWB '!H26 -> 50 | L32: ='2. ZWB '!I26 -> 1.6666667 | N32: ='3. ZWB '!H26 -> 50 | O32: ='3. ZWB '!I26 -> 1.6666667 | Q32: ='EB '!H26 -> 62 | R32: ='EB '!I26 -> 2.0666667
C33: Anzahl der Beratungs-/Betreuungsstunden für Familien | D33: 120 | H33: ='1. ZWB '!H27 -> 102 | I33: ='1. ZWB '!I27 -> 0.85 | K33: ='2. ZWB '!H27 -> 178 | L33: ='2. ZWB '!I27 -> 1.4833333 | N33: ='3. ZWB '!H27 -> 178 | O33: ='3. ZWB '!I27 -> 1.4833333 | Q33: ='EB '!H27 -> 263 | R33: ='EB '!I27 -> 2.1916667
C34: Anzahl der Hausbesuche | D34: 48 | H34: ='1. ZWB '!H28 -> 51 | I34: ='1. ZWB '!I28 -> 1.0625 | K34: ='2. ZWB '!H28 -> 89 | L34: ='2. ZWB '!I28 -> 1.8541667 | N34: ='3. ZWB '!H28 -> 89 | O34: ='3. ZWB '!I28 -> 1.8541667 | Q34: ='EB '!H28 -> 105 | R34: ='EB '!I28 -> 2.1875
C35: Anzahl besuchter Haushalte | D35: 6 | H35: ='1. ZWB '!H29 -> 8 | I35: ='1. ZWB '!I29 -> 1.3333333 | K35: ='2. ZWB '!H29 -> 13 | L35: ='2. ZWB '!I29 -> 2.1666667 | N35: ='3. ZWB '!H29 -> 13 | O35: ='3. ZWB '!I29 -> 2.1666667 | Q35: ='EB '!H29 -> 14 | R35: ='EB '!I29 -> 2.3333333
C36: Anzahl besuchter Personen | H36: ='1. ZWB '!H30 -> 0 | I36: ='1. ZWB '!I30 -> 0 | K36: ='2. ZWB '!H30 -> 0 | L36: ='2. ZWB '!I30 -> 0 | N36: ='3. ZWB '!H30 -> 0 | O36: ='3. ZWB '!I30 -> 0 | Q36: ='EB '!H30 -> 0 | R36: ='EB '!I30 -> 0
C37: Bereich Sprache | D37: Anzahl SOLL | E37: Bezeichnung der Maßnahme (lt. Projektbeschreibung) | H37: IST | I37: Erfüllt in % | K37: IST | L37: Erfüllt in % | N37: IST | O37: Erfüllt in % | Q37: IST | R37: Erfüllt in %
C38: Anzahl der Fachsprach- bzw. Sprachkurse gesamt | D38: =SUM(D39:E43) -> 0 | H38: ='1. ZWB '!H32 -> 0 | I38: ='1. ZWB '!I32 -> 0 | K38: ='2. ZWB '!H32 -> 0 | L38: ='2. ZWB '!I32 -> 0 | N38: ='3. ZWB '!H32 -> 0 | O38: ='3. ZWB '!I32 -> 0 | Q38: ='EB '!H32 -> 0 | R38: ='EB '!I32 -> 0
C39: davon Alphabetisierung | H39: ='1. ZWB '!H33 -> 0 | I39: ='1. ZWB '!I33 -> 0 | K39: ='2. ZWB '!H33 -> 0 | L39: ='2. ZWB '!I33 -> 0 | N39: ='3. ZWB '!H33 -> 0 | O39: ='3. ZWB '!I33 -> 0 | Q39: ='EB '!H33 -> 0 | R39: ='EB '!I33 -> 0
C40: davon A1 | H40: ='1. ZWB '!H34 -> 0 | I40: ='1. ZWB '!I34 -> 0 | K40: ='2. ZWB '!H34 -> 0 | L40: ='2. ZWB '!I34 -> 0 | N40: ='3. ZWB '!H34 -> 0 | O40: ='3. ZWB '!I34 -> 0 | Q40: ='EB '!H34 -> 0 | R40: ='EB '!I34 -> 0
C41: davon A2 | H41: ='1. ZWB '!H35 -> 0 | I41: ='1. ZWB '!I35 -> 0 | K41: ='2. ZWB '!H35 -> 0 | L41: ='2. ZWB '!I35 -> 0 | N41: ='3. ZWB '!H35 -> 0 | O41: ='3. ZWB '!I35 -> 0 | Q41: ='EB '!H35 -> 0 | R41: ='EB '!I35 -> 0
C42: davon B1 | H42: ='1. ZWB '!H36 -> 0 | I42: ='1. ZWB '!I36 -> 0 | K42: ='2. ZWB '!H36 -> 0 | L42: ='2. ZWB '!I36 -> 0 | N42: ='3. ZWB '!H36 -> 0 | O42: ='3. ZWB '!I36 -> 0 | Q42: ='EB '!H36 -> 0 | R42: ='EB '!I36 -> 0
...

Sheet 1. ZWB 
C4: Zeitraum des Indikatorenberichts | J4: Angaben zum Projekt
C5: von | D5: 44562 | J5: Laufzeit Beginn | L5: =IF('Overview IB'!D11="","",'Overview IB'!D11) -> 44562
C6: bis | D6: 44742 | J6: Laufzeit Ende | L6: =IF('Overview IB'!D12="","",'Overview IB'!D12) -> 45291
C7: Anteil an Laufzeit | D7: =IF(OR(D5="",L7="befüllt sich automatisch"),0,((D6-D5)/30)/L7) -> 0.24691358 | J7: Projektdauer in Monaten | L7: =IF(IF(OR(L6="",L5=""),"",(L6-L5)/30)="","befüllt sich automatisch",IF(OR(L6="",L5=""),"",(L6-L5)/30)) -> 24.3
C9: Zielindikatoren | D9: Anzahl SOLL | H9: IST | I9: Erfüllt in % | J9: Anmerkungen
C10: Anzahl der Projektteilnehmenden gesamt | D10: ='Overview IB'!D16 -> 818 | E10: =IF('Overview IB'!E16 > 0, 'Overview IB'!E16, "") | H10: =H13+H16+H20+H23+H26 -> 336 | I10: =IF(H10=0,0,H10/D10) -> 0.41075795
C11: Bereich Veranstaltungen | D11: Anzahl SOLL | E11: Bezeichnung der Maßnahme (lt. Projektbeschreibung)
C12: Anzahl der Veranstaltungen | D12: ='Overview IB'!D18 -> 38 | E12: =IF('Overview IB'!E18 > 0, 'Overview IB'!E18, "") -> Elterninfo parallel zum TRT Programm | H12: 3 | I12: =IF(H12=0,0,H12/D12) -> 0.078947368 | J12: Covidbedingt wg Eltern-Veranstaltungen an Schulen
C13: Anzahl der Veranstaltungsteilnehmenden gesamt | D13: ='Overview IB'!D19 -> 190 | H13: 18 | I13: =IF(H13=0,0,H13/D13) -> 0.094736842 | J13: s.o.
C14: Anzahl der Kurse/Workshops/Trainings | D14: ='Overview IB'!D20 -> 10 | E14: =IF('Overview IB'!E20 > 0, 'Overview IB'!E20, "") -> a) Traumapädagogische Seminare für Lehrkräfte b) Aus- und Fortbildung von mutterprachlichen TRT TrainerInnen | H14: 7 | I14: =IF(H14=0,0,H14/D14) -> 0.7 | J14: 2 ToT TRT, 1 WS, 2 Schule, 2 ZOOM/Ukraine
C15: Anzahl der Kurs-, Workshop- bzw. Trainingsplätze | D15: ='Overview IB'!D21 -> 0 | I15: =IF(H15=0,0,H15/D15) -> 0
C16: Anzahl der Teilnehmenden an Kursen/Workshops/ Trainings | D16: ='Overview IB'!D22 -> 162 | H16: =20+22+35+85 -> 162 | I16: =IF(H16=0,0,H16/D16) -> 1 | J16: ToT TRT 12 u 8, WS Tirol 22, Pädagoginnen gesamt 35, . Päd Zoom 85
C17: Anzahl der Kurs-, Workshop- bzw. Trainingsstunden | D17: ='Overview IB'!D23 -> 60 | H17: 65 | I17: =IF(H17=0,0,H17/D17) -> 1.0833333 | J17: 2 ToT TRT á 24h, 1 WS 8h, 2 WS 3h, 2 ZOOM FB (Ukraine) á 1,5h
C18: Bereich Beratung | D18: Anzahl SOLL | E18: Bezeichnung der Maßnahme (lt. Projektbeschreibung) | H18: IST | I18: Erfüllt in % | J18: Anmerkungen
C19: Anzahl der Einzelberatungen bzw. -betreuung | D19: ='Overview IB'!D25 -> 100 | E19: =IF('Overview IB'!E25 > 0, 'Overview IB'!E25, "") -> Begleitgespräche zum Traumaprogramm | H19: 24 | I19: =IF(H19=0,0,H19/D19) -> 0.24
C20: Anzahl der in Einzelberatung beratenen, betreuten oder gecoachten Personen | D20: ='Overview IB'!D26 -> 50 | H20: 16 | I20: =IF(H20=0,0,H20/D20) -> 0.32
C21: Anzahl der Einzelberatungs-/Betreuungs-/ Coachingstunden | D21: ='Overview IB'!D27 -> 100 | H21: 18 | I21: =IF(H21=0,0,H21/D21) -> 0.18
C22: Anzahl der Gruppenberatungen bzw. -betreuung (min 3 Personen) | D22: ='Overview IB'!D28 -> 60 | H22: 13 | I22: =IF(H22=0,0,H22/D22) -> 0.21666667 | J22: 12 TRT, 1 GK
C23: Anzahl der in Gruppenberatung beratenen oder betreuten Personen | D23: ='Overview IB'!D29 -> 426 | H23: 105 | I23: =IF(H23=0,0,H23/D23) -> 0.24647887 | J23: 96 TRT, 9 GK
C24: Anzahl der Gruppenberatungs-/Betreuungsstunden | D24: ='Overview IB'!D30 -> 960 | H24: =55*2+8*2 -> 126 | I24: =IF(H24=0,0,H24/D24) -> 0.13125 | J24: Ukraine Kurzinterventionen
C25: Anzahl der Familienberatungen (pro Familie) | D25: ='Overview IB'!D31 -> 10 | E25: =IF('Overview IB'!E31 > 0, 'Overview IB'!E31, "") -> TRT Family | H25: 8 | I25: =IF(H25=0,0,H25/D25) -> 0.8 | J25: pro Familie;
C26: Anzahl der familienberatenen oder betreuten Personen | D26: ='Overview IB'!D32 -> 30 | H26: 35 | I26: =IF(H26=0,0,H26/D26) -> 1.1666667
C27: Anzahl der Beratungs-/Betreuungsstunden für Familien | D27: ='Overview IB'!D33 -> 120 | H27: 102 | I27: =IF(H27=0,0,H27/D27) -> 0.85
C28: Anzahl der Hausbesuche | D28: ='Overview IB'!D34 -> 48 | H28: 51 | I28: =IF(H28=0,0,H28/D28) -> 1.0625
C29: Anzahl besuchter Haushalte | D29: ='Overview IB'!D35 -> 6 | H29: 8 | I29: =IF(H29=0,0,H29/D29) -> 1.3333333
C30: Anzahl besuchter Personen | D30: ='Overview IB'!D36 -> 0 | I30: =IF(H30=0,0,H30/D30) -> 0
C31: Bereich Sprache | D31: Anzahl SOLL | E31: Bezeichnung der Maßnahme (lt. Projektbeschreibung) | H31: IST | I31: Erfüllt in % | J31: Anmerkungen
C32: Anzahl der Fachsprach- bzw. Sprachkurse gesamt | D32: ='Overview IB'!D38 -> 0 | E32: =IF('Overview IB'!E38 > 0, 'Overview IB'!E38, "") | H32: =SUM(H33:H37) -> 0 | I32: =IF(H32=0,0,H32/D32) -> 0
C33: davon Alphabetisierung | D33: ='Overview IB'!D39 -> 0 | I33: =IF(H33=0,0,H33/D33) -> 0
C34: davon A1 | D34: ='Overview IB'!D40 -> 0 | I34: =IF(H34=0,0,H34/D34) -> 0
C35: davon A2 | D35: ='Overview IB'!D41 -> 0 | I35: =IF(H35=0,0,H35/D35) -> 0
C36: davon B1 | D36: ='Overview IB'!D42 -> 0 | I36: =IF(H36=0,0,H36/D36) -> 0
C37: davon B2 | D37: ='Overview IB'!D43 -> 0 | I37: =IF(H37=0,0,H37/D37) -> 0
C38: Anzahl der Fachsprach- bzw. Sprachkursplätze gesamt | D38: ='Overview IB'!D44 -> 0 | I38: =IF(H38=0,0,H38/D38) -> 0
C39: Anzahl der Fachsprach- bzw. Sprachkursteilnehmenden gesamt | D39: ='Overview IB'!D45 -> 0 | I39: =IF(H39=0,0,H39/D39) -> 0
C40: Anzahl der Unterrichtseinheiten gesamt | D40: ='Overview IB'!D46 -> 0 | I40: =IF(H40=0,0,H40/D40) -> 0
C41: Anzahl der Teilnehmenden an einer zertifizierten Abschlussprüfung | D41: ='Overview IB'!D47 -> 0 | I41: =IF(H41=0,0,H41/D41) -> 0
C42: Anteil der Teilnehmenden mit positiv absolvierter Abschlussprüfung in % | D42: ='Overview IB'!D48 -> 0 | I42: =IF(H42=0,0,H42/D42) -> 0
C43: davon ÖIF zertifiziert | D43: ='Overview IB'!D49 -> 0 | I43: =IF(H43=0,0,H43/D43) -> 0
C44: Anzahl der niederschwelligen Sprachlerntreffen | D44: ='Overview IB'!D50 -> 0 | E44: =IF('Overview IB'!E50 > 0, 'Overview IB'!E50, "") | I44: =IF(H44=0,0,H44/D44) -> 0
...

Sheet 2. ZWB 
C4: Zeitraum des Indikatorenberichts | J4: Angaben zum Projekt
C5: von | D5: 44562 | J5: Laufzeit Beginn | L5: =IF('Overview IB'!D11="","",'Overview IB'!D11) -> 44562
C6: bis | D6: 44926 | J6: Laufzeit Ende | L6: =IF('Overview IB'!D12="","",'Overview IB'!D12) -> 45291
C7: Anteil an Laufzeit | D7: =IF(OR(D5="",L7="befüllt sich automatisch"),0,((D6-D5)/30)/L7) -> 0.49931413 | J7: Projektdauer in Monaten | L7: =IF(IF(OR(L6="",L5=""),"",(L6-L5)/30)="","befüllt sich automatisch",IF(OR(L6="",L5=""),"",(L6-L5)/30)) -> 24.3
C9: Zielindikatoren | D9: Anzahl SOLL | H9: IST | I9: Erfüllt in % | J9: Anmerkungen
C10: Anzahl der Projektteilnehmenden gesamt | D10: ='Overview IB'!D16 -> 818 | E10: =IF('Overview IB'!E16 > 0, 'Overview IB'!E16, "") | H10: =H13+H16+H20+H23+H26 -> 607 | I10: =IF(H10=0,0,H10/D10) -> 0.74205379
C11: Bereich Veranstaltungen | D11: Anzahl SOLL | E11: Bezeichnung der Maßnahme (lt. Projektbeschreibung)
C12: Anzahl der Veranstaltungen | D12: ='Overview IB'!D18 -> 38 | E12: =IF('Overview IB'!E18 > 0, 'Overview IB'!E18, "") -> Elterninfo parallel zum TRT Programm | H12: 10 | I12: =IF(H12=0,0,H12/D12) -> 0.26315789
C13: Anzahl der Veranstaltungsteilnehmenden gesamt | D13: ='Overview IB'!D19 -> 190 | H13: 59 | I13: =IF(H13=0,0,H13/D13) -> 0.31052632
C14: Anzahl der Kurse/Workshops/Trainings | D14: ='Overview IB'!D20 -> 10 | E14: =IF('Overview IB'!E20 > 0, 'Overview IB'!E20, "") -> a) Traumapädagogische Seminare für Lehrkräfte b) Aus- und Fortbildung von mutterprachlichen TRT TrainerInnen | H14: 15 | I14: =IF(H14=0,0,H14/D14) -> 1.5 | J14: TRT Ukraine, TfA, Wien x-tra, PH Ukr, PH wieNGs; PH, PH Sbg, BBU 10+15+14+10+23+12+15+18
C15: Anzahl der Kurs-, Workshop- bzw. Trainingsplätze | D15: ='Overview IB'!D21 -> 0 | I15: =IF(H15=0,0,H15/D15) -> 0
C16: Anzahl der Teilnehmenden an Kursen/Workshops/ Trainings | D16: ='Overview IB'!D22 -> 162 | H16: 279 | I16: =IF(H16=0,0,H16/D16) -> 1.7222222
C17: Anzahl der Kurs-, Workshop- bzw. Trainingsstunden | D17: ='Overview IB'!D23 -> 60 | H17: 139 | I17: =IF(H17=0,0,H17/D17) -> 2.3166667 | J17: 50 + 24 ToT TRT
C18: Bereich Beratung | D18: Anzahl SOLL | E18: Bezeichnung der Maßnahme (lt. Projektbeschreibung) | H18: IST | I18: Erfüllt in % | J18: Anmerkungen
C19: Anzahl der Einzelberatungen bzw. -betreuung | D19: ='Overview IB'!D25 -> 100 | E19: =IF('Overview IB'!E25 > 0, 'Overview IB'!E25, "") -> Begleitgespräche zum Traumaprogramm | H19: 50 | I19: =IF(H19=0,0,H19/D19) -> 0.5
C20: Anzahl der in Einzelberatung beratenen, betreuten oder gecoachten Personen | D20: ='Overview IB'!D26 -> 50 | H20: 35 | I20: =IF(H20=0,0,H20/D20) -> 0.7
C21: Anzahl der Einzelberatungs-/Betreuungs-/ Coachingstunden | D21: ='Overview IB'!D27 -> 100 | H21: 35 | I21: =IF(H21=0,0,H21/D21) -> 0.35
C22: Anzahl der Gruppenberatungen bzw. -betreuung (min 3 Personen) | D22: ='Overview IB'!D28 -> 60 | H22: 24 | I22: =IF(H22=0,0,H22/D22) -> 0.4 | J22: 22 TRT + 2 GK
C23: Anzahl der in Gruppenberatung beratenen oder betreuten Personen | D23: ='Overview IB'!D29 -> 426 | H23: 184 | I23: =IF(H23=0,0,H23/D23) -> 0.43192488
C24: Anzahl der Gruppenberatungs-/Betreuungsstunden | D24: ='Overview IB'!D30 -> 960 | H24: 258 | I24: =IF(H24=0,0,H24/D24) -> 0.26875
C25: Anzahl der Familienberatungen (pro Familie) | D25: ='Overview IB'!D31 -> 10 | E25: =IF('Overview IB'!E31 > 0, 'Overview IB'!E31, "") -> TRT Family | H25: 8 | I25: =IF(H25=0,0,H25/D25) -> 0.8
C26: Anzahl der familienberatenen oder betreuten Personen | D26: ='Overview IB'!D32 -> 30 | H26: 50 | I26: =IF(H26=0,0,H26/D26) -> 1.6666667
C27: Anzahl der Beratungs-/Betreuungsstunden für Familien | D27: ='Overview IB'!D33 -> 120 | H27: 178 | I27: =IF(H27=0,0,H27/D27) -> 1.4833333
C28: Anzahl der Hausbesuche | D28: ='Overview IB'!D34 -> 48 | H28: 89 | I28: =IF(H28=0,0,H28/D28) -> 1.8541667
C29: Anzahl besuchter Haushalte | D29: ='Overview IB'!D35 -> 6 | H29: 13 | I29: =IF(H29=0,0,H29/D29) -> 2.1666667
C30: Anzahl besuchter Personen | D30: ='Overview IB'!D36 -> 0 | I30: =IF(H30=0,0,H30/D30) -> 0
C31: Bereich Sprache | D31: Anzahl SOLL | E31: Bezeichnung der Maßnahme (lt. Projektbeschreibung) | H31: IST | I31: Erfüllt in % | J31: Anmerkungen
C32: Anzahl der Fachsprach- bzw. Sprachkurse gesamt | D32: ='Overview IB'!D38 -> 0 | E32: =IF('Overview IB'!E38 > 0, 'Overview IB'!E38, "") | H32: =SUM(H33:H37) -> 0 | I32: =IF(H32=0,0,H32/D32) -> 0
C33: davon Alphabetisierung | D33: ='Overview IB'!D39 -> 0 | I33: =IF(H33=0,0,H33/D33) -> 0
C34: davon A1 | D34: ='Overview IB'!D40 -> 0 | I34: =IF(H34=0,0,H34/D34) -> 0
C35: davon A2 | D35: ='Overview IB'!D41 -> 0 | I35: =IF(H35=0,0,H35/D35) -> 0
C36: davon B1 | D36: ='Overview IB'!D42 -> 0 | I36: =IF(H36=0,0,H36/D36) -> 0
C37: davon B2 | D37: ='Overview IB'!D43 -> 0 | I37: =IF(H37=0,0,H37/D37) -> 0
C38: Anzahl der Fachsprach- bzw. Sprachkursplätze gesamt | D38: ='Overview IB'!D44 -> 0 | I38: =IF(H38=0,0,H38/D38) -> 0
C39: Anzahl der Fachsprach- bzw. Sprachkursteilnehmenden gesamt | D39: ='Overview IB'!D45 -> 0 | I39: =IF(H39=0,0,H39/D39) -> 0
C40: Anzahl der Unterrichtseinheiten gesamt | D40: ='Overview IB'!D46 -> 0 | I40: =IF(H40=0,0,H40/D40) -> 0
C41: Anzahl der Teilnehmenden an einer zertifizierten Abschlussprüfung | D41: ='Overview IB'!D47 -> 0 | I41: =IF(H41=0,0,H41/D41) -> 0
C42: Anteil der Teilnehmenden mit positiv absolvierter Abschlussprüfung in % | D42: ='Overview IB'!D48 -> 0 | I42: =IF(H42=0,0,H42/D42) -> 0
C43: davon ÖIF zertifiziert | D43: ='Overview IB'!D49 -> 0 | I43: =IF(H43=0,0,H43/D43) -> 0
C44: Anzahl der niederschwelligen Sprachlerntreffen | D44: ='Overview IB'!D50 -> 0 | E44: =IF('Overview IB'!E50 > 0, 'Overview IB'!E50, "") | I44: =IF(H44=0,0,H44/D44) -> 0
...

Sheet 3. ZWB 
C4: Zeitraum des Indikatorenberichts | J4: Angaben zum Projekt
C5: von | D5: 44562 | J5: Laufzeit Beginn | L5: =IF('Overview IB'!D11="","",'Overview IB'!D11) -> 44562
C6: bis | D6: 45107 | J6: Laufzeit Ende | L6: =IF('Overview IB'!D12="","",'Overview IB'!D12) -> 45291
C7: Anteil an Laufzeit | D7: =IF(OR(D5="",L7="befüllt sich automatisch"),0,((D6-D5)/30)/L7) -> 0.74759945 | J7: Projektdauer in Monaten | L7: =IF(IF(OR(L6="",L5=""),"",(L6-L5)/30)="","befüllt sich automatisch",IF(OR(L6="",L5=""),"",(L6-L5)/30)) -> 24.3
C9: Zielindikatoren | D9: Anzahl SOLL | H9: IST | I9: Erfüllt in % | J9: Anmerkungen
C10: Anzahl der Projektteilnehmenden gesamt | D10: ='Overview IB'!D16 -> 818 | E10: =IF('Overview IB'!E16 > 0, 'Overview IB'!E16, "") | H10: 1045 | I10: =IF(H10=0,0,H10/D10) -> 1.2775061 | J10: TRT Schule+GK+TRT Familie+Elterngruppe+Fortbildung (alt 1.413)
C11: Bereich Veranstaltungen | D11: Anzahl SOLL | E11: Bezeichnung der Maßnahme (lt. Projektbeschreibung)
C12: Anzahl der Veranstaltungen | D12: ='Overview IB'!D18 -> 38 | E12: =IF('Overview IB'!E18 > 0, 'Overview IB'!E18, "") -> Elterninfo parallel zum TRT Programm | H12: 41 | I12: =IF(H12=0,0,H12/D12) -> 1.0789474 | J12: Elterngruppen (alt 38)
C13: Anzahl der Veranstaltungsteilnehmenden gesamt | D13: ='Overview IB'!D19 -> 190 | H13: 214 | I13: =IF(H13=0,0,H13/D13) -> 1.1263158 | J13: TeilnehmerInnen (alt 282)
C14: Anzahl der Kurse/Workshops/Trainings | D14: ='Overview IB'!D20 -> 10 | E14: =IF('Overview IB'!E20 > 0, 'Overview IB'!E20, "") -> a) Traumapädagogische Seminare für Lehrkräfte b) Aus- und Fortbildung von mutterprachlichen TRT TrainerInnen | H14: 22 | I14: =IF(H14=0,0,H14/D14) -> 2.2 | J14: TRT Ukraine, TfA, Wien x-tra, PH Ukr, PH wieNGs; PH, PH Sbg, BBU, SFZ, FoBi TrainerInnen AFYA
C15: Anzahl der Kurs-, Workshop- bzw. Trainingsplätze | D15: ='Overview IB'!D21 -> 0 | I15: =IF(H15=0,0,H15/D15) -> 0
C16: Anzahl der Teilnehmenden an Kursen/Workshops/ Trainings | D16: ='Overview IB'!D22 -> 162 | H16: 268 | I16: =IF(H16=0,0,H16/D16) -> 1.654321 | J16: (alt 335)
C17: Anzahl der Kurs-, Workshop- bzw. Trainingsstunden | D17: ='Overview IB'!D23 -> 60 | H17: 291 | I17: =IF(H17=0,0,H17/D17) -> 4.85 | J17: (alt 167)
C18: Bereich Beratung | D18: Anzahl SOLL | E18: Bezeichnung der Maßnahme (lt. Projektbeschreibung) | H18: IST | I18: Erfüllt in % | J18: Anmerkungen
C19: Anzahl der Einzelberatungen bzw. -betreuung | D19: ='Overview IB'!D25 -> 100 | E19: =IF('Overview IB'!E25 > 0, 'Overview IB'!E25, "") -> Begleitgespräche zum Traumaprogramm | H19: 70 | I19: =IF(H19=0,0,H19/D19) -> 0.7
C20: Anzahl der in Einzelberatung beratenen, betreuten oder gecoachten Personen | D20: ='Overview IB'!D26 -> 50 | H20: 50 | I20: =IF(H20=0,0,H20/D20) -> 1
C21: Anzahl der Einzelberatungs-/Betreuungs-/ Coachingstunden | D21: ='Overview IB'!D27 -> 100 | H21: 50 | I21: =IF(H21=0,0,H21/D21) -> 0.5
C22: Anzahl der Gruppenberatungen bzw. -betreuung (min 3 Personen) | D22: ='Overview IB'!D28 -> 60 | H22: 59 | I22: =IF(H22=0,0,H22/D22) -> 0.98333333 | J22: 56 TRT + 3 GK
C23: Anzahl der in Gruppenberatung beratenen oder betreuten Personen | D23: ='Overview IB'!D29 -> 426 | H23: 513 | I23: =IF(H23=0,0,H23/D23) -> 1.2042254 | J23: 486 TRT + 27 GK
C24: Anzahl der Gruppenberatungs-/Betreuungsstunden | D24: ='Overview IB'!D30 -> 960 | H24: 1080 | I24: =IF(H24=0,0,H24/D24) -> 1.125 | J24: 432 Einheiten á 2,5 Stunden (alt 1.038)
C25: Anzahl der Familienberatungen (pro Familie) | D25: ='Overview IB'!D31 -> 10 | E25: =IF('Overview IB'!E31 > 0, 'Overview IB'!E31, "") -> TRT Family | H25: 8 | I25: =IF(H25=0,0,H25/D25) -> 0.8 | J25: (alt 13)
C26: Anzahl der familienberatenen oder betreuten Personen | D26: ='Overview IB'!D32 -> 30 | H26: 50 | I26: =IF(H26=0,0,H26/D26) -> 1.6666667 | J26: (alt 58)
C27: Anzahl der Beratungs-/Betreuungsstunden für Familien | D27: ='Overview IB'!D33 -> 120 | H27: 178 | I27: =IF(H27=0,0,H27/D27) -> 1.4833333
C28: Anzahl der Hausbesuche | D28: ='Overview IB'!D34 -> 48 | H28: 89 | I28: =IF(H28=0,0,H28/D28) -> 1.8541667
C29: Anzahl besuchter Haushalte | D29: ='Overview IB'!D35 -> 6 | H29: 13 | I29: =IF(H29=0,0,H29/D29) -> 2.1666667
C30: Anzahl besuchter Personen | D30: ='Overview IB'!D36 -> 0 | H30: 0 | I30: =IF(H30=0,0,H30/D30) -> 0
C31: Bereich Sprache | D31: Anzahl SOLL | E31: Bezeichnung der Maßnahme (lt. Projektbeschreibung) | H31: IST | I31: Erfüllt in % | J31: Anmerkungen
C32: Anzahl der Fachsprach- bzw. Sprachkurse gesamt | D32: ='Overview IB'!D38 -> 0 | E32: =IF('Overview IB'!E38 > 0, 'Overview IB'!E38, "") | H32: =SUM(H33:H37) -> 0 | I32: =IF(H32=0,0,H32/D32) -> 0
C33: davon Alphabetisierung | D33: ='Overview IB'!D39 -> 0 | I33: =IF(H33=0,0,H33/D33) -> 0
C34: davon A1 | D34: ='Overview IB'!D40 -> 0 | I34: =IF(H34=0,0,H34/D34) -> 0
C35: davon A2 | D35: ='Overview IB'!D41 -> 0 | I35: =IF(H35=0,0,H35/D35) -> 0
C36: davon B1 | D36: ='Overview IB'!D42 -> 0 | I36: =IF(H36=0,0,H36/D36) -> 0
C37: davon B2 | D37: ='Overview IB'!D43 -> 0 | I37: =IF(H37=0,0,H37/D37) -> 0
C38: Anzahl der Fachsprach- bzw. Sprachkursplätze gesamt | D38: ='Overview IB'!D44 -> 0 | I38: =IF(H38=0,0,H38/D38) -> 0
C39: Anzahl der Fachsprach- bzw. Sprachkursteilnehmenden gesamt | D39: ='Overview IB'!D45 -> 0 | I39: =IF(H39=0,0,H39/D39) -> 0
C40: Anzahl der Unterrichtseinheiten gesamt | D40: ='Overview IB'!D46 -> 0 | I40: =IF(H40=0,0,H40/D40) -> 0
C41: Anzahl der Teilnehmenden an einer zertifizierten Abschlussprüfung | D41: ='Overview IB'!D47 -> 0 | I41: =IF(H41=0,0,H41/D41) -> 0
C42: Anteil der Teilnehmenden mit positiv absolvierter Abschlussprüfung in % | D42: ='Overview IB'!D48 -> 0 | I42: =IF(H42=0,0,H42/D42) -> 0
C43: davon ÖIF zertifiziert | D43: ='Overview IB'!D49 -> 0 | I43: =IF(H43=0,0,H43/D43) -> 0
C44: Anzahl der niederschwelligen Sprachlerntreffen | D44: ='Overview IB'!D50 -> 0 | E44: =IF('Overview IB'!E50 > 0, 'Overview IB'!E50, "") | I44: =IF(H44=0,0,H44/D44) -> 0
...

Sheet EB 
C4: Zeitraum des Indikatorenberichts | J4: Angaben zum Projekt
C5: von | D5: 44562 | J5: Laufzeit Beginn | L5: =IF('Overview IB'!D11="","",'Overview IB'!D11) -> 44562
C6: bis | D6: 45291 | J6: Laufzeit Ende | L6: =IF('Overview IB'!D12="","",'Overview IB'!D12) -> 45291
C7: Anteil an Laufzeit | D7: =IF(OR(D5="",L7="befüllt sich automatisch"),0,((D6-D5)/30)/L7) -> 1 | J7: Projektdauer in Monaten | L7: =IF(IF(OR(L6="",L5=""),"",(L6-L5)/30)="","befüllt sich automatisch",IF(OR(L6="",L5=""),"",(L6-L5)/30)) -> 24.3
C9: Zielindikatoren | D9: Anzahl SOLL | H9: IST | I9: Erfüllt in % | J9: Anmerkungen
C10: Anzahl der Projektteilnehmenden gesamt | D10: ='Overview IB'!D16 -> 818 | E10: =IF('Overview IB'!E16 > 0, 'Overview IB'!E16, "") | H10: 1204 | I10: =IF(H10=0,0,H10/D10) -> 1.4718826 | J10: TRT Schule+GK+TRT Familie+Elterngruppe+Fortbildung
C11: Bereich Veranstaltungen | D11: Anzahl SOLL | E11: Bezeichnung der Maßnahme (lt. Projektbeschreibung)
C12: Anzahl der Veranstaltungen | D12: ='Overview IB'!D18 -> 38 | E12: =IF('Overview IB'!E18 > 0, 'Overview IB'!E18, "") -> Elterninfo parallel zum TRT Programm | H12: 45 | I12: =IF(H12=0,0,H12/D12) -> 1.1842105 | J12: Elterninfo-Veranstaltungstermine (30 Elterngruppen, 1-2 Termine pro Gruppe)
C13: Anzahl der Veranstaltungsteilnehmenden gesamt | D13: ='Overview IB'!D19 -> 190 | H13: 233 | I13: =IF(H13=0,0,H13/D13) -> 1.2263158 | J13: Teilnehmer:innen
C14: Anzahl der Kurse/Workshops/Trainings | D14: ='Overview IB'!D20 -> 10 | E14: =IF('Overview IB'!E20 > 0, 'Overview IB'!E20, "") -> a) Traumapädagogische Seminare für Lehrkräfte b) Aus- und Fortbildung von mutterprachlichen TRT TrainerInnen | H14: 23 | I14: =IF(H14=0,0,H14/D14) -> 2.3 | J14: TRT-Ausbildung, Fortbildungen Team + Pädagogen-Schulungen
C15: Anzahl der Kurs-, Workshop- bzw. Trainingsplätze | D15: ='Overview IB'!D21 -> 0 | I15: =IF(H15=0,0,H15/D15) -> 0
C16: Anzahl der Teilnehmenden an Kursen/Workshops/ Trainings | D16: ='Overview IB'!D22 -> 162 | H16: 292 | I16: =IF(H16=0,0,H16/D16) -> 1.8024691 | J16: 250 Traumap. Seminare+42 muttersprachl. TRT Trainer:innen
C17: Anzahl der Kurs-, Workshop- bzw. Trainingsstunden | D17: ='Overview IB'!D23 -> 60 | H17: 299 | I17: =IF(H17=0,0,H17/D17) -> 4.9833333 | J17: inklusive Fortbildungen Team
C18: Bereich Beratung | D18: Anzahl SOLL | E18: Bezeichnung der Maßnahme (lt. Projektbeschreibung) | H18: IST | I18: Erfüllt in % | J18: Anmerkungen
C19: Anzahl der Einzelberatungen bzw. -betreuung | D19: ='Overview IB'!D25 -> 100 | E19: =IF('Overview IB'!E25 > 0, 'Overview IB'!E25, "") -> Begleitgespräche zum Traumaprogramm | H19: 80 | I19: =IF(H19=0,0,H19/D19) -> 0.8
C20: Anzahl der in Einzelberatung beratenen, betreuten oder gecoachten Personen | D20: ='Overview IB'!D26 -> 50 | H20: 54 | I20: =IF(H20=0,0,H20/D20) -> 1.08
C21: Anzahl der Einzelberatungs-/Betreuungs-/ Coachingstunden | D21: ='Overview IB'!D27 -> 100 | H21: 54 | I21: =IF(H21=0,0,H21/D21) -> 0.54
C22: Anzahl der Gruppenberatungen bzw. -betreuung (min 3 Personen) | D22: ='Overview IB'!D28 -> 60 | H22: 70 | I22: =IF(H22=0,0,H22/D22) -> 1.1666667 | J22: 62 TRT-Gruppen + 8 Gesundheitskreise
C23: Anzahl der in Gruppenberatung beratenen oder betreuten Personen | D23: ='Overview IB'!D29 -> 426 | H23: 617 | I23: =IF(H23=0,0,H23/D23) -> 1.4483568 | J23: 553 TRT-Teilnehmer:innen + 64 GK Teilnehmer:innen
C24: Anzahl der Gruppenberatungs-/Betreuungsstunden | D24: ='Overview IB'!D30 -> 960 | H24: 1280 | I24: =IF(H24=0,0,H24/D24) -> 1.3333333 | J24: 450 Termine TRT + 62 GK - Termine á2,5h
C25: Anzahl der Familienberatungen (pro Familie) | D25: ='Overview IB'!D31 -> 10 | E25: =IF('Overview IB'!E31 > 0, 'Overview IB'!E31, "") -> TRT Family | H25: 8 | I25: =IF(H25=0,0,H25/D25) -> 0.8
C26: Anzahl der familienberatenen oder betreuten Personen | D26: ='Overview IB'!D32 -> 30 | H26: 62 | I26: =IF(H26=0,0,H26/D26) -> 2.0666667
C27: Anzahl der Beratungs-/Betreuungsstunden für Familien | D27: ='Overview IB'!D33 -> 120 | H27: 263 | I27: =IF(H27=0,0,H27/D27) -> 2.1916667 | J27: 105 Termine á2,5 h
C28: Anzahl der Hausbesuche | D28: ='Overview IB'!D34 -> 48 | H28: 105 | I28: =IF(H28=0,0,H28/D28) -> 2.1875 | J28: Pro Termin 1 Hausbesuch
C29: Anzahl besuchter Haushalte | D29: ='Overview IB'!D35 -> 6 | H29: 14 | I29: =IF(H29=0,0,H29/D29) -> 2.3333333
C30: Anzahl besuchter Personen | D30: ='Overview IB'!D36 -> 0 | H30: 0 | I30: =IF(H30=0,0,H30/D30) -> 0
C31: Bereich Sprache | D31: Anzahl SOLL | E31: Bezeichnung der Maßnahme (lt. Projektbeschreibung) | H31: IST | I31: Erfüllt in % | J31: Anmerkungen
C32: Anzahl der Fachsprach- bzw. Sprachkurse gesamt | D32: ='Overview IB'!D38 -> 0 | E32: =IF('Overview IB'!E38 > 0, 'Overview IB'!E38, "") | H32: =SUM(H33:H37) -> 0 | I32: =IF(H32=0,0,H32/D32) -> 0
C33: davon Alphabetisierung | D33: ='Overview IB'!D39 -> 0 | I33: =IF(H33=0,0,H33/D33) -> 0
C34: davon A1 | D34: ='Overview IB'!D40 -> 0 | I34: =IF(H34=0,0,H34/D34) -> 0
C35: davon A2 | D35: ='Overview IB'!D41 -> 0 | I35: =IF(H35=0,0,H35/D35) -> 0
C36: davon B1 | D36: ='Overview IB'!D42 -> 0 | I36: =IF(H36=0,0,H36/D36) -> 0
C37: davon B2 | D37: ='Overview IB'!D43 -> 0 | I37: =IF(H37=0,0,H37/D37) -> 0
C38: Anzahl der Fachsprach- bzw. Sprachkursplätze gesamt | D38: ='Overview IB'!D44 -> 0 | I38: =IF(H38=0,0,H38/D38) -> 0
C39: Anzahl der Fachsprach- bzw. Sprachkursteilnehmenden gesamt | D39: ='Overview IB'!D45 -> 0 | I39: =IF(H39=0,0,H39/D39) -> 0
C40: Anzahl der Unterrichtseinheiten gesamt | D40: ='Overview IB'!D46 -> 0 | I40: =IF(H40=0,0,H40/D40) -> 0
C41: Anzahl der Teilnehmenden an einer zertifizierten Abschlussprüfung | D41: ='Overview IB'!D47 -> 0 | I41: =IF(H41=0,0,H41/D41) -> 0
C42: Anteil der Teilnehmenden mit positiv absolvierter Abschlussprüfung in % | D42: ='Overview IB'!D48 -> 0 | I42: =IF(H42=0,0,H42/D42) -> 0
C43: davon ÖIF zertifiziert | D43: ='Overview IB'!D49 -> 0 | I43: =IF(H43=0,0,H43/D43) -> 0
C44: Anzahl der niederschwelligen Sprachlerntreffen | D44: ='Overview IB'!D50 -> 0 | E44: =IF('Overview IB'!E50 > 0, 'Overview IB'!E50, "") | I44: =IF(H44=0,0,H44/D44) -> 0
...
