Workbook
Name A_Ja_Nein_Liste: [1]sysAuswahl!$A$5:$A$6
Name A_Ja_Nein_Rev: [1]sysAuswahl!$F$5:$G$7
Name A_Ja_Nein_Wert: [1]sysAuswahl!$C$5:$D$7
Name A_MASSN_Liste: [1]sysAuswahl!$A$23:$A$31
Name A_MASSN_Rev: [1]sysAuswahl!$F$23:$G$32
Name A_MASSN_Wert: [1]sysAuswahl!$C$23:$D$32
Name A_ProjArt_Liste: [1]sysAuswahl!$A$14:$A$16
Name F_FondsBez: [1]Eingabe_1_bis_4!$F$15
Name F_Massnahme: [1]Eingabe_1_bis_4!$F$19
Name F_MONSYS_Aktenzeichen: [1]Eingabe_1_bis_4!$F$7
Name F_MONSYS_Eingangsdatum: [1]Eingabe_1_bis_4!$F$5
Name F_MONSYS_eingegangenBei: [1]Eingabe_1_bis_4!$F$4
Name F_MONSYS_FassungVom: [1]Eingabe_1_bis_4!$F$6
Name F_MONSYS_Projektcode: [1]Eingabe_1_bis_4!$F$9
Name F_MONSYS_Vertragsnummer: [1]Eingabe_1_bis_4!$F$8
Name F_PA1_Ansprech: [1]Eingabe_5!$F$20
Name F_PA1_Email: [1]Eingabe_5!$F$26
Name F_PA1_Fax: [1]Eingabe_5!$F$24
Name F_PA1_Telefon: [1]Eingabe_5!$F$22
Name F_PA2_Ansprech: [1]Eingabe_5!$F$44
Name F_PA2_Email: [1]Eingabe_5!$F$50
Name F_PA2_Fax: [1]Eingabe_5!$F$48
Name F_PA2_Telefon: [1]Eingabe_5!$F$46
Name F_PK_KACode_L00: [1]Eingabe_6!$F$48
Name F_PK_KACode_L01: [1]Eingabe_6!$F$52
Name F_PK_KACode_L02: [1]Eingabe_6!$F$56
Name F_PK_KACode_L03: [1]Eingabe_6!$F$60
Name F_PK_KACode_L04: [1]Eingabe_6!$F$64
Name F_PK_KACode_L05: [1]Eingabe_6!$F$68
Name F_PK_KACode_L06: [1]Eingabe_6!$F$72
Name F_PK_KACode_L07: [1]Eingabe_6!$F$76
Name F_PK_KACode_L08: [1]Eingabe_6!$F$80
Name F_PK_KACode_L09: [1]Eingabe_6!$F$84
Name F_PK_PK_Notiz_L00: [1]Eingabe_6!$F$50
Name F_PK_PK_Notiz_L01: [1]Eingabe_6!$F$54
Name F_PK_PK_Notiz_L02: [1]Eingabe_6!$F$58
Name F_PK_PK_Notiz_L03: [1]Eingabe_6!$F$62
Name F_PK_PK_Notiz_L04: [1]Eingabe_6!$F$66
Name F_PK_PK_Notiz_L05: [1]Eingabe_6!$F$70
Name F_PK_PK_Notiz_L06: [1]Eingabe_6!$F$74
Name F_PK_PK_Notiz_L07: [1]Eingabe_6!$F$78
Name F_PK_PK_Notiz_L08: [1]Eingabe_6!$F$82
Name F_PK_PK_Notiz_L09: [1]Eingabe_6!$F$86
Name F_PK_Z01: [1]Eingabe_6!$F$34
Name F_PK_Z02: [1]Eingabe_6!$F$36
Name F_PK_Z03: [1]Eingabe_6!$F$38
Name F_PK_Z04: [1]Eingabe_6!$F$40
Name F_PR_AZVFS: [1]Eingabe_1_bis_4!$F$25
Name F_PR_FEAnsprech: [1]Eingabe_1_bis_4!$F$71
Name F_PR_FEAnsprech_Email: [1]Eingabe_1_bis_4!$F$77
Name F_PR_FEAnsprech_Fax: [1]Eingabe_1_bis_4!$F$75
Name F_PR_FEAnsprech_Telefon: [1]Eingabe_1_bis_4!$F$73
Name F_PR_FEBLZ: [1]Eingabe_1_bis_4!$F$87
Name F_PR_FEKontonr: [1]Eingabe_1_bis_4!$F$85
Name F_PR_FeMWST: [1]Eingabe_1_bis_4!$F$61
Name F_PR_FEZeichBerecht: [1]Eingabe_1_bis_4!$F$57
Name F_PR_Grenzland: [1]Eingabe_1_bis_4!$F$67
Name F_PR_Link: [1]Eingabe_1_bis_4!$F$81
Name F_PR_Projdf_anf: [1]Eingabe_6!$F$7
Name F_PR_Projdf_end: [1]Eingabe_6!$F$9

Sheet Overview IB
C3: Indikatorenbericht Nationale Integrationsförderung 2024 und 2025 | AE3: Bitte auswählen! | AF3: Bitte auswählen! | AG3: Bitte auswählen!
C4: Projektträger/-in | D4: Qualifizierung & Karriere GmbH | AE4: Sprache und Bildung | AF4: Frauen | AG4: Burgenland
C5: Projekttitel | D5: Finish Strong – Prüfungsvorbereitung und Begleitung für Lehrling | AE5: Arbeit und Beruf | AF5: Deutsch | AG5: Kärnten
C6: Projektnummer | D6: 131-2024/25 | AE6: Rechtsstaat und Werte | AF6: Kinder, Jugendliche und Elternarbeit | AG6: Niederösterreich
C7: Standort Projektmanagement | D7: Tirol | AE7: Sport und Freizeit | AF7: Sport und Freizeit | AG7: Steiermark
C8: Hauptprojektstandort | D8: Tirol | AE8: Wohnen und die regionale Dimension der Integration | AF8: x | AG8: Tirol
C9: Laufzeit Beginn | D9: 45292 | AF9: x | AG9: Vorarlberg
C10: Laufzeit Ende | D10: 46022 | AG10: Wien
C11: Projektdauer in Monaten | D11: =IF(IF(OR(D9="",D10=""),"",(D10-D9)/30.4)="","befüllt sich automatisch",IF(OR(D9="",D10=""),"",(D10-D9)/30.4)) -> 24.013158
C13: Bundesländeraufteilung in % | D13: Burgenland | F13: Bitte hier nur ganze Zahlen angeben!
D14: Kärnten
D15: Niederösterreich
D16: Oberösterreich
D17: Salzburg
D18: Steiermark
D19: Tirol | E19: 100
D20: Vorarlberg
D21: Wien
D22: gesamt | E22: =SUM(E13:E21) -> 100
C24: Zielindikatoren | D24: Anzahl SOLL lt. Vertrag | E24: Anzahl SOLL berichtigt lt. Vertrag | F24: Anmerkungen (lt. Projektbeschreibung) | I24: Maßnahmen Soll lt. Vertrag | T24: Anteil an Laufzeit | U24: ='1. ZWB'!D7 -> 0.24794521 | W24: Anteil an Laufzeit | X24: ='2. ZWB'!D7 -> 0.5 | Z24: Anteil an Laufzeit | AA24: ='3. ZWB'!D7 -> 0.74794521 | AC24: Anteil an Laufzeit | AD24: =EB!D7 -> -62.043836
I25: M 1 | J25: M 2 | K25: M 3 | L25: M 4 | M25: M 5 | N25: M 6 | O25: M 7 | P25: M 8 | Q25: M 9 | R25: M 10 | T25: IST bis 1. ZWB | U25: Erfüllt in % | W25: IST bis 2. ZWB | X25: Erfüllt in % | Z25: IST bis 3. ZWB | AA25: Erfüllt in % | AC25: IST bis EB | AD25: Erfüllt in %
C26: Anzahl der Projektteilnehmenden gesamt | D26: =SUM(I26:R26) -> 194 | E26: 72 | I26: 72 | J26: 72 | K26: 50 | T26: =IF('1. ZWB'!R11=0,'1. ZWB'!Q11,'1. ZWB'!R11) -> 42 | U26: ='1. ZWB'!S11 -> 0.58333333 | W26: =IF('2. ZWB'!R11=0,'2. ZWB'!Q11,'2. ZWB'!R11) -> 55 | X26: ='2. ZWB'!S11 -> 0.76388889 | Z26: =IF('3. ZWB'!R11=0,'3. ZWB'!Q11,'3. ZWB'!R11) -> 74 | AA26: ='3. ZWB'!S11 -> 1.0277778 | AB26: =IF(AA26=0,0,AA26/D26) -> 0.0052978236 | AC26: =IF(EB!R11=0,EB!Q11,EB!R11) -> 82 | AD26: =EB!S11 -> 1.1388889
C27: Anzahl der verfügbaren Plätze im Projekt | D27: =SUM(I27:R27) -> 194 | E27: 72 | I27: 72 | J27: 72 | K27: 50 | T27: =IF('1. ZWB'!R12=0,'1. ZWB'!Q12,'1. ZWB'!R12) -> 42 | U27: ='1. ZWB'!S12 -> 0.58333333 | W27: =IF('2. ZWB'!R12=0,'2. ZWB'!Q12,'2. ZWB'!R12) -> 55 | X27: ='2. ZWB'!S12 -> 0.76388889 | Z27: =IF('3. ZWB'!R12=0,'3. ZWB'!Q12,'3. ZWB'!R12) -> 74 | AA27: ='3. ZWB'!S12 -> 1.0277778 | AC27: =IF(EB!R12=0,EB!Q12,EB!R12) -> 82 | AD27: =EB!S12 -> 1.1388889
C28: Anzahl der Standorte, an denen die Maßnahmen durchgeführt werden | D28: =SUM(I28:R28) -> 3 | E28: 1 | F28: Innsbruck | I28: 1 | J28: 1 | K28: 1 | T28: =IF('1. ZWB'!R13=0,'1. ZWB'!Q13,'1. ZWB'!R13) -> 1 | U28: ='1. ZWB'!S13 -> 1 | W28: =IF('2. ZWB'!R13=0,'2. ZWB'!Q13,'2. ZWB'!R13) -> 1 | X28: ='2. ZWB'!S13 -> 1 | Z28: =IF('3. ZWB'!R13=0,'3. ZWB'!Q13,'3. ZWB'!R13) -> 1 | AA28: ='3. ZWB'!S13 -> 1 | AC28: =IF(EB!R13=0,EB!Q13,EB!R13) -> 1 | AD28: =EB!S13 -> 1
C29: Bereich Veranstaltungen | D29: Anzahl SOLL | E29: Anzahl SOLL berichtigt lt. Vertrag | F29: Anmerkungen (lt. Projektbeschreibung) | I29: M 1 | J29: M 2 | K29: M 3 | L29: M 4 | M29: M 5 | N29: M 6 | O29: M 7 | P29: M 8 | Q29: M 9 | R29: M 10 | T29: IST bis 1. ZWB | U29: ='1. ZWB'!S14 -> Erfüllt in % | W29: IST bis 2. ZWB | X29: Erfüllt in % | Z29: IST bis 3. ZWB | AA29: Erfüllt in % | AC29: IST bis EB | AD29: Erfüllt in %
C30: Anzahl der Veranstaltungen | D30: =SUM(I30:R30) -> 0 | T30: =IF('1. ZWB'!R15=0,'1. ZWB'!Q15,'1. ZWB'!R15) -> 0 | U30: ='1. ZWB'!S15 -> 0 | W30: =IF('2. ZWB'!R15=0,'2. ZWB'!Q15,'2. ZWB'!R15) -> 0 | X30: ='2. ZWB'!S15 -> 0 | Z30: =IF('3. ZWB'!R15=0,'3. ZWB'!Q15,'3. ZWB'!R15) -> 0 | AA30: ='3. ZWB'!S15 -> 0 | AC30: =IF(EB!R15=0,EB!Q15,EB!R15) -> 0 | AD30: =EB!S15 -> 0
C31: Anzahl der Veranstaltungsteilnehmenden gesamt | D31: =SUM(I31:R31) -> 0 | T31: =IF('1. ZWB'!R16=0,'1. ZWB'!Q16,'1. ZWB'!R16) -> 0 | U31: ='1. ZWB'!S16 -> 0 | W31: =IF('2. ZWB'!R16=0,'2. ZWB'!Q16,'2. ZWB'!R16) -> 0 | X31: ='2. ZWB'!S16 -> 0 | Z31: =IF('3. ZWB'!R16=0,'3. ZWB'!Q16,'3. ZWB'!R16) -> 0 | AA31: ='3. ZWB'!S16 -> 0 | AC31: =IF(EB!R16=0,EB!Q16,EB!R16) -> 0 | AD31: =EB!S16 -> 0
C32: Anzahl der Kurse/Workshops/Trainings | D32: =SUM(I32:R32) -> 0 | T32: =IF('1. ZWB'!R17=0,'1. ZWB'!Q17,'1. ZWB'!R17) -> 0 | U32: ='1. ZWB'!S17 -> 0 | W32: =IF('2. ZWB'!R17=0,'2. ZWB'!Q17,'2. ZWB'!R17) -> 0 | X32: ='2. ZWB'!S17 -> 0 | Z32: =IF('3. ZWB'!R17=0,'3. ZWB'!Q17,'3. ZWB'!R17) -> 0 | AA32: ='3. ZWB'!S17 -> 0 | AC32: =IF(EB!R17=0,EB!Q17,EB!R17) -> 0 | AD32: =EB!S17 -> 0
C33: Anzahl der Teilnehmenden an Kursen/Workshops/ Trainings | D33: =SUM(I33:R33) -> 0 | T33: =IF('1. ZWB'!R18=0,'1. ZWB'!Q18,'1. ZWB'!R18) -> 0 | U33: ='1. ZWB'!S18 -> 0 | W33: =IF('2. ZWB'!R18=0,'2. ZWB'!Q18,'2. ZWB'!R18) -> 0 | X33: ='2. ZWB'!S18 -> 0 | Z33: =IF('3. ZWB'!R18=0,'3. ZWB'!Q18,'3. ZWB'!R18) -> 0 | AA33: ='3. ZWB'!S18 -> 0 | AC33: =IF(EB!R18=0,EB!Q18,EB!R18) -> 0 | AD33: =EB!S18 -> 0
C34: Anzahl der Kurs-, Workshop- bzw. Trainingsstunden | D34: =SUM(I34:R34) -> 0 | T34: =IF('1. ZWB'!R19=0,'1. ZWB'!Q19,'1. ZWB'!R19) -> 0 | U34: ='1. ZWB'!S19 -> 0 | W34: =IF('2. ZWB'!R19=0,'2. ZWB'!Q19,'2. ZWB'!R19) -> 0 | X34: ='2. ZWB'!S19 -> 0 | Z34: =IF('3. ZWB'!R19=0,'3. ZWB'!Q19,'3. ZWB'!R19) -> 0 | AA34: ='3. ZWB'!S19 -> 0 | AC34: =IF(EB!R19=0,EB!Q19,EB!R19) -> 0 | AD34: =EB!S19 -> 0
C35: Bereich Beratung | D35: Anzahl SOLL | E35: Anzahl SOLL berichtigt lt. Vertrag | F35: Anmerkungen (lt. Projektbeschreibung) | I35: M 1 | J35: M 2 | K35: M 3 | L35: M 4 | M35: M 5 | N35: M 6 | O35: M 7 | P35: M 8 | Q35: M 9 | R35: M 10 | T35: IST bis 1. ZWB | U35: Erfüllt in % | W35: IST bis 2. ZWB | X35: Erfüllt in % | Z35: IST bis 3. ZWB | AA35: Erfüllt in % | AC35: IST bis EB | AD35: Erfüllt in %
C36: Anzahl der Einzelberatungen bzw. -betreuung | D36: =SUM(I36:R36) -> 0 | F36: "Individuelle LAP-Beratung" & "Fachspezifische Lernbegleitung im Einzelsetting" (1-2 Personen) | T36: =IF('1. ZWB'!R21=0,'1. ZWB'!Q21,'1. ZWB'!R21) -> 0 | U36: ='1. ZWB'!S21 -> 0 | W36: =IF('2. ZWB'!R21=0,'2. ZWB'!Q21,'2. ZWB'!R21) -> 0 | X36: ='2. ZWB'!S21 -> 0 | Z36: =IF('3. ZWB'!R21=0,'3. ZWB'!Q21,'3. ZWB'!R21) -> 0 | AA36: ='3. ZWB'!S21 -> 0 | AC36: =IF(EB!R21=0,EB!Q21,EB!R21) -> 0 | AD36: =EB!S21 -> 0
C37: Anzahl der in Einzelberatung beratenen, betreuten oder gecoachten Personen | D37: =SUM(I37:R37) -> 144 | E37: 72 | I37: 72 | J37: 72 | T37: =IF('1. ZWB'!R22=0,'1. ZWB'!Q22,'1. ZWB'!R22) -> 42 | U37: ='1. ZWB'!S22 -> 0.58333333 | W37: =IF('2. ZWB'!R22=0,'2. ZWB'!Q22,'2. ZWB'!R22) -> 55 | X37: ='2. ZWB'!S22 -> 0.76388889 | Z37: =IF('3. ZWB'!R22=0,'3. ZWB'!Q22,'3. ZWB'!R22) -> 74 | AA37: ='3. ZWB'!S22 -> 1.0277778 | AC37: =IF(EB!R22=0,EB!Q22,EB!R22) -> 82 | AD37: =EB!S22 -> 1.1388889
C38: Anzahl der Einzelberatungs-/Betreuungs-/ Coachingstunden | D38: =SUM(I38:R38) -> 1170 | E38: 1170 | I38: 360 | J38: 810 | T38: =IF('1. ZWB'!R23=0,'1. ZWB'!Q23,'1. ZWB'!R23) -> 311 | U38: ='1. ZWB'!S23 -> 0.26581197 | W38: =IF('2. ZWB'!R23=0,'2. ZWB'!Q23,'2. ZWB'!R23) -> 654 | X38: ='2. ZWB'!S23 -> 0.55897436 | Z38: =IF('3. ZWB'!R23=0,'3. ZWB'!Q23,'3. ZWB'!R23) -> 952 | AA38: ='3. ZWB'!S23 -> 0.81367521 | AC38: =IF(EB!R23=0,EB!Q23,EB!R23) -> 1218.5 | AD38: =EB!S23 -> 1.041453
C39: Anzahl der Gruppenberatungen bzw. -betreuung (min. 3 Personen) | D39: =SUM(I39:R39) -> 0 | F39: "Fachspezifische Lernbegleitung im Gruppensetting" (ab 3 Personen) | T39: =IF('1. ZWB'!R24=0,'1. ZWB'!Q24,'1. ZWB'!R24) -> 0 | U39: ='1. ZWB'!S24 -> 0 | W39: =IF('2. ZWB'!R24=0,'2. ZWB'!Q24,'2. ZWB'!R24) -> 0 | X39: ='2. ZWB'!S24 -> 0 | Z39: =IF('3. ZWB'!R24=0,'3. ZWB'!Q24,'3. ZWB'!R24) -> 0 | AA39: ='3. ZWB'!S24 -> 0 | AC39: =IF(EB!R24=0,EB!Q24,EB!R24) -> 0 | AD39: =EB!S24 -> 0
C40: Anzahl der in Gruppenberatung beratenen oder betreuten Personen | D40: =SUM(I40:R40) -> 50 | E40: 50 | K40: 50 | T40: =IF('1. ZWB'!R25=0,'1. ZWB'!Q25,'1. ZWB'!R25) -> 33 | U40: ='1. ZWB'!S25 -> 0.66 | W40: =IF('2. ZWB'!R25=0,'2. ZWB'!Q25,'2. ZWB'!R25) -> 39 | X40: ='2. ZWB'!S25 -> 0.78 | Z40: =IF('3. ZWB'!R25=0,'3. ZWB'!Q25,'3. ZWB'!R25) -> 46 | AA40: ='3. ZWB'!S25 -> 0.92 | AC40: =IF(EB!R25=0,EB!Q25,EB!R25) -> 50 | AD40: =EB!S25 -> 1
C41: Anzahl der Gruppenberatungs-/Betreuungsstunden | D41: =SUM(I41:R41) -> 540 | E41: 540 | K41: 540 | T41: =IF('1. ZWB'!R26=0,'1. ZWB'!Q26,'1. ZWB'!R26) -> 192 | U41: ='1. ZWB'!S26 -> 0.35555556 | W41: =IF('2. ZWB'!R26=0,'2. ZWB'!Q26,'2. ZWB'!R26) -> 298 | X41: ='2. ZWB'!S26 -> 0.55185185 | Z41: =IF('3. ZWB'!R26=0,'3. ZWB'!Q26,'3. ZWB'!R26) -> 435.5 | AA41: ='3. ZWB'!S26 -> 0.80648148 | AC41: =IF(EB!R26=0,EB!Q26,EB!R26) -> 540.5 | AD41: =EB!S26 -> 1.0009259
C42: Anzahl der Familienberatungen (pro Familie) | D42: =SUM(I42:R42) -> 0 | T42: =IF('1. ZWB'!R27=0,'1. ZWB'!Q27,'1. ZWB'!R27) -> 0 | U42: ='1. ZWB'!S27 -> 0 | W42: =IF('2. ZWB'!R27=0,'2. ZWB'!Q27,'2. ZWB'!R27) -> 0 | X42: ='2. ZWB'!S27 -> 0 | Z42: =IF('3. ZWB'!R27=0,'3. ZWB'!Q27,'3. ZWB'!R27) -> 0 | AA42: ='3. ZWB'!S27 -> 0 | AC42: =IF(EB!R27=0,EB!Q27,EB!R27) -> 0 | AD42: =EB!S27 -> 0
C43: Anzahl der familienberatenen oder betreuten Personen | D43: =SUM(I43:R43) -> 0 | T43: =IF('1. ZWB'!R28=0,'1. ZWB'!Q28,'1. ZWB'!R28) -> 0 | U43: ='1. ZWB'!S28 -> 0 | W43: =IF('2. ZWB'!R28=0,'2. ZWB'!Q28,'2. ZWB'!R28) -> 0 | X43: ='2. ZWB'!S28 -> 0 | Z43: =IF('3. ZWB'!R28=0,'3. ZWB'!Q28,'3. ZWB'!R28) -> 0 | AA43: ='3. ZWB'!S28 -> 0 | AC43: =IF(EB!R28=0,EB!Q28,EB!R28) -> 0 | AD43: =EB!S28 -> 0
C44: Anzahl der Beratungs-/Betreuungsstunden für Familien | D44: =SUM(I44:R44) -> 0 | T44: =IF('1. ZWB'!R29=0,'1. ZWB'!Q29,'1. ZWB'!R29) -> 0 | U44: ='1. ZWB'!S29 -> 0 | W44: =IF('2. ZWB'!R29=0,'2. ZWB'!Q29,'2. ZWB'!R29) -> 0 | X44: ='2. ZWB'!S29 -> 0 | Z44: =IF('3. ZWB'!R29=0,'3. ZWB'!Q29,'3. ZWB'!R29) -> 0 | AA44: ='3. ZWB'!S29 -> 0 | AC44: =IF(EB!R29=0,EB!Q29,EB!R29) -> 0 | AD44: =EB!S29 -> 0
...

Sheet Drop Down
A1: Wählen Sie ein Bundesland aus:
A2: Burgenland
A3: Kärnten
A4: Niederösterreich
A5: Oberösterreich
A6: Salzburg
A7: Steiermark
A8: Tirol
A9: Vorarlberg
A10: Wien

Sheet 1. ZWB
C4: Zeitraum des Indikatorenberichts | I4: Angaben zum Projekt
C5: von | D5: =L5 -> 45292 | I5: Laufzeit Beginn | L5: =IF('Overview IB'!D9="","",'Overview IB'!D9) -> 45292
C6: bis | D6: 45473 | I6: Laufzeit Ende | L6: =IF('Overview IB'!D10="","",'Overview IB'!D10) -> 46022
C7: Anteil an Laufzeit | D7: =IF(OR(D5="",L7="befüllt sich automatisch"),0,((D6-D5)/30)/L7) -> 0.24794521 | I7: Projektdauer in Monaten | L7: =IF(IF(OR(L6="",L5=""),"",(L6-L5)/30)="","befüllt sich automatisch",IF(OR(L6="",L5=""),"",(L6-L5)/30)) -> 24.333333
C9: Zielindikatoren | D9: Anzahl SOLL lt. Vertrag | E9: Anzahl SOLL berichtigt lt. Vertrag | F9: Maßnahmen Soll lt. Vertrag | Q9: Anzahl IST - gesamt | R9: Anzahl IST - gesamt - berichtigt | S9: Erfüllt in % | T9: allgemeine Anmerkungen zu den IST-Indikatoren | U9: Maßnahmen IST lt. Vertrag
F10: M 1 | G10: M 2 | H10: M 3 | I10: M 4 | J10: M 5 | K10: M 6 | L10: M 7 | M10: M 8 | N10: M 9 | O10: M 10 | U10: M 1 | V10: M 2 | W10: M 3 | X10: M 4 | Y10: M 5 | Z10: M 6 | AA10: M 7 | AB10: M 8 | AC10: M 9 | AD10: M 10
C11: Anzahl der Projektteilnehmenden gesamt | D11: ='Overview IB'!D26 -> 194 | E11: ='Overview IB'!E26 -> 72 | F11: ='Overview IB'!I26 -> 72 | G11: ='Overview IB'!J26 -> 72 | H11: ='Overview IB'!K26 -> 50 | I11: ='Overview IB'!L26 -> 0 | J11: ='Overview IB'!M26 -> 0 | K11: ='Overview IB'!N26 -> 0 | L11: ='Overview IB'!O26 -> 0 | M11: ='Overview IB'!P26 -> 0 | ... O11: ='Overview IB'!R26 -> 0 | Q11: =SUM(U11:AD11) -> 0 | R11: 42 | S11: =IF(D11=0,0,IF(E11=0,IF(R11=0,Q11/D11,R11/D11),IF(R11=0,Q11/E11,R11/E11))) -> 0.58333333
C12: Anzahl der verfügbaren Plätze im Projekt | D12: ='Overview IB'!D27 -> 194 | E12: ='Overview IB'!E27 -> 72 | F12: ='Overview IB'!I27 -> 72 | G12: ='Overview IB'!J27 -> 72 | H12: ='Overview IB'!K27 -> 50 | I12: ='Overview IB'!L27 -> 0 | J12: ='Overview IB'!M27 -> 0 | K12: ='Overview IB'!N27 -> 0 | L12: ='Overview IB'!O27 -> 0 | M12: ='Overview IB'!P27 -> 0 | ... O12: ='Overview IB'!R27 -> 0 | Q12: =SUM(U12:AD12) -> 0 | R12: 42 | S12: =IF(D12=0,0,IF(E12=0,IF(R12=0,Q12/D12,R12/D12),IF(R12=0,Q12/E12,R12/E12))) -> 0.58333333
C13: Anzahl der Standorte, an denen die Maßnahmen durchgeführt werden | D13: ='Overview IB'!D28 -> 3 | E13: ='Overview IB'!E28 -> 1 | F13: ='Overview IB'!I28 -> 1 | G13: ='Overview IB'!J28 -> 1 | H13: ='Overview IB'!K28 -> 1 | I13: ='Overview IB'!L28 -> 0 | J13: ='Overview IB'!M28 -> 0 | K13: ='Overview IB'!N28 -> 0 | L13: ='Overview IB'!O28 -> 0 | M13: ='Overview IB'!P28 -> 0 | ... O13: ='Overview IB'!R28 -> 0 | Q13: =SUM(U13:AD13) -> 0 | R13: 1 | S13: =IF(D13=0,0,IF(E13=0,IF(R13=0,Q13/D13,R13/D13),IF(R13=0,Q13/E13,R13/E13))) -> 1
C14: Bereich Veranstaltungen | D14: Anzahl SOLL | E14: Anzahl SOLL berichtigt | F14: M 1 | G14: M 2 | H14: M 3 | I14: M 4 | J14: M 5 | K14: M 6 | L14: M 7 | M14: M 8 | N14: M 9 | O14: M 10 | Q14: IST | R14: IST berichtigt | S14: Erfüllt in % | T14: Anmerkungen | U14: M 1 | V14: M 2 | W14: M 3 | X14: M 4 | Y14: M 5 | Z14: M 6 | AA14: M 7 | AB14: M 8 | AC14: M 9 | AD14: M 10
C15: Anzahl der Veranstaltungen | D15: ='Overview IB'!D30 -> 0 | E15: ='Overview IB'!E30 -> 0 | F15: ='Overview IB'!I30 -> 0 | G15: ='Overview IB'!J30 -> 0 | H15: ='Overview IB'!K30 -> 0 | I15: ='Overview IB'!L30 -> 0 | J15: ='Overview IB'!M30 -> 0 | K15: ='Overview IB'!N30 -> 0 | L15: ='Overview IB'!O30 -> 0 | M15: ='Overview IB'!P30 -> 0 | ... O15: ='Overview IB'!R30 -> 0 | Q15: =SUM(U15:AD15) -> 0 | S15: =IF(D15=0,0,IF(E15=0,IF(R15=0,Q15/D15,R15/D15),IF(R15=0,Q15/E15,R15/E15))) -> 0
C16: Anzahl der Veranstaltungsteilnehmenden gesamt | D16: ='Overview IB'!D31 -> 0 | E16: ='Overview IB'!E31 -> 0 | F16: ='Overview IB'!I31 -> 0 | G16: ='Overview IB'!J31 -> 0 | H16: ='Overview IB'!K31 -> 0 | I16: ='Overview IB'!L31 -> 0 | J16: ='Overview IB'!M31 -> 0 | K16: ='Overview IB'!N31 -> 0 | L16: ='Overview IB'!O31 -> 0 | M16: ='Overview IB'!P31 -> 0 | ... O16: ='Overview IB'!R31 -> 0 | Q16: =SUM(U16:AD16) -> 0 | S16: =IF(D16=0,0,IF(E16=0,IF(R16=0,Q16/D16,R16/D16),IF(R16=0,Q16/E16,R16/E16))) -> 0
C17: Anzahl der Kurse/Workshops/Trainings | D17: ='Overview IB'!D32 -> 0 | E17: ='Overview IB'!E32 -> 0 | F17: ='Overview IB'!I32 -> 0 | G17: ='Overview IB'!J32 -> 0 | H17: ='Overview IB'!K32 -> 0 | I17: ='Overview IB'!L32 -> 0 | J17: ='Overview IB'!M32 -> 0 | K17: ='Overview IB'!N32 -> 0 | L17: ='Overview IB'!O32 -> 0 | M17: ='Overview IB'!P32 -> 0 | ... O17: ='Overview IB'!R32 -> 0 | Q17: =SUM(U17:AD17) -> 0 | S17: =IF(D17=0,0,IF(E17=0,IF(R17=0,Q17/D17,R17/D17),IF(R17=0,Q17/E17,R17/E17))) -> 0
C18: Anzahl der Teilnehmenden an Kursen/Workshops/ Trainings | D18: ='Overview IB'!D33 -> 0 | E18: ='Overview IB'!E33 -> 0 | F18: ='Overview IB'!I33 -> 0 | G18: ='Overview IB'!J33 -> 0 | H18: ='Overview IB'!K33 -> 0 | I18: ='Overview IB'!L33 -> 0 | J18: ='Overview IB'!M33 -> 0 | K18: ='Overview IB'!N33 -> 0 | L18: ='Overview IB'!O33 -> 0 | M18: ='Overview IB'!P33 -> 0 | ... O18: ='Overview IB'!R33 -> 0 | Q18: =SUM(U18:AD18) -> 0 | S18: =IF(D18=0,0,IF(E18=0,IF(R18=0,Q18/D18,R18/D18),IF(R18=0,Q18/E18,R18/E18))) -> 0
C19: Anzahl der Kurs-, Workshop- bzw. Trainingsstunden | D19: ='Overview IB'!D34 -> 0 | E19: ='Overview IB'!E34 -> 0 | F19: ='Overview IB'!I34 -> 0 | G19: ='Overview IB'!J34 -> 0 | H19: ='Overview IB'!K34 -> 0 | I19: ='Overview IB'!L34 -> 0 | J19: ='Overview IB'!M34 -> 0 | K19: ='Overview IB'!N34 -> 0 | L19: ='Overview IB'!O34 -> 0 | M19: ='Overview IB'!P34 -> 0 | ... O19: ='Overview IB'!R34 -> 0 | Q19: =SUM(U19:AD19) -> 0 | S19: =IF(D19=0,0,IF(E19=0,IF(R19=0,Q19/D19,R19/D19),IF(R19=0,Q19/E19,R19/E19))) -> 0
C20: Bereich Beratung | D20: Anzahl SOLL | E20: Anzahl SOLL berichtigt | F20: M 1 | G20: M 2 | H20: M 3 | I20: M 4 | J20: M 5 | K20: M 6 | L20: M 7 | M20: M 8 | N20: M 9 | O20: M 10 | Q20: IST | R20: IST berichtigt | S20: Erfüllt in % | T20: Anmerkungen | U20: M 1 | V20: M 2 | W20: M 3 | X20: M 4 | Y20: M 5 | Z20: M 6 | AA20: M 7 | AB20: M 8 | AC20: M 9 | AD20: M 10
C21: Anzahl der Einzelberatungen bzw. -betreuung | D21: ='Overview IB'!D36 -> 0 | E21: ='Overview IB'!E36 -> 0 | F21: ='Overview IB'!I36 -> 0 | G21: ='Overview IB'!J36 -> 0 | H21: ='Overview IB'!K36 -> 0 | I21: ='Overview IB'!L36 -> 0 | J21: ='Overview IB'!M36 -> 0 | K21: ='Overview IB'!N36 -> 0 | L21: ='Overview IB'!O36 -> 0 | M21: ='Overview IB'!P36 -> 0 | ... O21: ='Overview IB'!R36 -> 0 | Q21: =SUM(U21:AD21) -> 0 | S21: =IF(D21=0,0,IF(E21=0,IF(R21=0,Q21/D21,R21/D21),IF(R21=0,Q21/E21,R21/E21))) -> 0
C22: Anzahl der in Einzelberatung beratenen, betreuten oder gecoachten Personen | D22: ='Overview IB'!D37 -> 144 | E22: ='Overview IB'!E37 -> 72 | F22: ='Overview IB'!I37 -> 72 | G22: ='Overview IB'!J37 -> 72 | H22: ='Overview IB'!K37 -> 0 | I22: ='Overview IB'!L37 -> 0 | J22: ='Overview IB'!M37 -> 0 | K22: ='Overview IB'!N37 -> 0 | L22: ='Overview IB'!O37 -> 0 | M22: ='Overview IB'!P37 -> 0 | ... O22: ='Overview IB'!R37 -> 0 | Q22: =SUM(U22:AD22) -> 0 | R22: 42 | S22: =IF(D22=0,0,IF(E22=0,IF(R22=0,Q22/D22,R22/D22),IF(R22=0,Q22/E22,R22/E22))) -> 0.58333333
C23: Anzahl der Einzelberatungs-/Betreuungs-/ Coachingstunden | D23: ='Overview IB'!D38 -> 1170 | E23: ='Overview IB'!E38 -> 1170 | F23: ='Overview IB'!I38 -> 360 | G23: ='Overview IB'!J38 -> 810 | H23: ='Overview IB'!K38 -> 0 | I23: ='Overview IB'!L38 -> 0 | J23: ='Overview IB'!M38 -> 0 | K23: ='Overview IB'!N38 -> 0 | L23: ='Overview IB'!O38 -> 0 | M23: ='Overview IB'!P38 -> 0 | ... O23: ='Overview IB'!R38 -> 0 | Q23: =SUM(U23:AD23) -> 0 | R23: 311 | S23: =IF(D23=0,0,IF(E23=0,IF(R23=0,Q23/D23,R23/D23),IF(R23=0,Q23/E23,R23/E23))) -> 0.26581197
C24: Anzahl der Gruppenberatungen bzw. -betreuung (min 3 Personen) | D24: ='Overview IB'!D39 -> 0 | E24: ='Overview IB'!E39 -> 0 | F24: ='Overview IB'!I39 -> 0 | G24: ='Overview IB'!J39 -> 0 | H24: ='Overview IB'!K39 -> 0 | I24: ='Overview IB'!L39 -> 0 | J24: ='Overview IB'!M39 -> 0 | K24: ='Overview IB'!N39 -> 0 | L24: ='Overview IB'!O39 -> 0 | M24: ='Overview IB'!P39 -> 0 | ... O24: ='Overview IB'!R39 -> 0 | Q24: =SUM(U24:AD24) -> 0 | S24: =IF(D24=0,0,IF(E24=0,IF(R24=0,Q24/D24,R24/D24),IF(R24=0,Q24/E24,R24/E24))) -> 0
C25: Anzahl der in Gruppenberatung beratenen oder betreuten Personen | D25: ='Overview IB'!D40 -> 50 | E25: ='Overview IB'!E40 -> 50 | F25: ='Overview IB'!I40 -> 0 | G25: ='Overview IB'!J40 -> 0 | H25: ='Overview IB'!K40 -> 50 | I25: ='Overview IB'!L40 -> 0 | J25: ='Overview IB'!M40 -> 0 | K25: ='Overview IB'!N40 -> 0 | L25: ='Overview IB'!O40 -> 0 | M25: ='Overview IB'!P40 -> 0 | ... O25: ='Overview IB'!R40 -> 0 | Q25: =SUM(U25:AD25) -> 0 | R25: 33 | S25: =IF(D25=0,0,IF(E25=0,IF(R25=0,Q25/D25,R25/D25),IF(R25=0,Q25/E25,R25/E25))) -> 0.66
C26: Anzahl der Gruppenberatungs-/Betreuungsstunden | D26: ='Overview IB'!D41 -> 540 | E26: ='Overview IB'!E41 -> 540 | F26: ='Overview IB'!I41 -> 0 | G26: ='Overview IB'!J41 -> 0 | H26: ='Overview IB'!K41 -> 540 | I26: ='Overview IB'!L41 -> 0 | J26: ='Overview IB'!M41 -> 0 | K26: ='Overview IB'!N41 -> 0 | L26: ='Overview IB'!O41 -> 0 | M26: ='Overview IB'!P41 -> 0 | ... O26: ='Overview IB'!R41 -> 0 | Q26: =SUM(U26:AD26) -> 0 | R26: 192 | S26: =IF(D26=0,0,IF(E26=0,IF(R26=0,Q26/D26,R26/D26),IF(R26=0,Q26/E26,R26/E26))) -> 0.35555556
C27: Anzahl der Familienberatungen (pro Familie) | D27: ='Overview IB'!D42 -> 0 | E27: ='Overview IB'!E42 -> 0 | F27: ='Overview IB'!I42 -> 0 | G27: ='Overview IB'!J42 -> 0 | H27: ='Overview IB'!K42 -> 0 | I27: ='Overview IB'!L42 -> 0 | J27: ='Overview IB'!M42 -> 0 | K27: ='Overview IB'!N42 -> 0 | L27: ='Overview IB'!O42 -> 0 | M27: ='Overview IB'!P42 -> 0 | ... O27: ='Overview IB'!R42 -> 0 | Q27: =SUM(U27:AD27) -> 0 | S27: =IF(D27=0,0,IF(E27=0,IF(R27=0,Q27/D27,R27/D27),IF(R27=0,Q27/E27,R27/E27))) -> 0
C28: Anzahl der familienberatenen oder betreuten Personen | D28: ='Overview IB'!D43 -> 0 | E28: ='Overview IB'!E43 -> 0 | F28: ='Overview IB'!I43 -> 0 | G28: ='Overview IB'!J43 -> 0 | H28: ='Overview IB'!K43 -> 0 | I28: ='Overview IB'!L43 -> 0 | J28: ='Overview IB'!M43 -> 0 | K28: ='Overview IB'!N43 -> 0 | L28: ='Overview IB'!O43 -> 0 | M28: ='Overview IB'!P43 -> 0 | ... O28: ='Overview IB'!R43 -> 0 | Q28: =SUM(U28:AD28) -> 0 | S28: =IF(D28=0,0,IF(E28=0,IF(R28=0,Q28/D28,R28/D28),IF(R28=0,Q28/E28,R28/E28))) -> 0
C29: Anzahl der Beratungs-/Betreuungsstunden für Familien | D29: ='Overview IB'!D44 -> 0 | E29: ='Overview IB'!E44 -> 0 | F29: ='Overview IB'!I44 -> 0 | G29: ='Overview IB'!J44 -> 0 | H29: ='Overview IB'!K44 -> 0 | I29: ='Overview IB'!L44 -> 0 | J29: ='Overview IB'!M44 -> 0 | K29: ='Overview IB'!N44 -> 0 | L29: ='Overview IB'!O44 -> 0 | M29: ='Overview IB'!P44 -> 0 | ... O29: ='Overview IB'!R44 -> 0 | Q29: =SUM(U29:AD29) -> 0 | S29: =IF(D29=0,0,IF(E29=0,IF(R29=0,Q29/D29,R29/D29),IF(R29=0,Q29/E29,R29/E29))) -> 0
C30: Anzahl der Hausbesuche | D30: ='Overview IB'!D45 -> 0 | E30: ='Overview IB'!E45 -> 0 | F30: ='Overview IB'!I45 -> 0 | G30: ='Overview IB'!J45 -> 0 | H30: ='Overview IB'!K45 -> 0 | I30: ='Overview IB'!L45 -> 0 | J30: ='Overview IB'!M45 -> 0 | K30: ='Overview IB'!N45 -> 0 | L30: ='Overview IB'!O45 -> 0 | M30: ='Overview IB'!P45 -> 0 | ... O30: ='Overview IB'!R45 -> 0 | Q30: =SUM(U30:AD30) -> 0 | S30: =IF(D30=0,0,IF(E30=0,IF(R30=0,Q30/D30,R30/D30),IF(R30=0,Q30/E30,R30/E30))) -> 0
C31: Anzahl besuchter Haushalte | D31: ='Overview IB'!D46 -> 0 | E31: ='Overview IB'!E46 -> 0 | F31: ='Overview IB'!I46 -> 0 | G31: ='Overview IB'!J46 -> 0 | H31: ='Overview IB'!K46 -> 0 | I31: ='Overview IB'!L46 -> 0 | J31: ='Overview IB'!M46 -> 0 | K31: ='Overview IB'!N46 -> 0 | L31: ='Overview IB'!O46 -> 0 | M31: ='Overview IB'!P46 -> 0 | ... O31: ='Overview IB'!R46 -> 0 | Q31: =SUM(U31:AD31) -> 0 | S31: =IF(D31=0,0,IF(E31=0,IF(R31=0,Q31/D31,R31/D31),IF(R31=0,Q31/E31,R31/E31))) -> 0
C32: Anzahl besuchter Personen | D32: ='Overview IB'!D47 -> 0 | E32: ='Overview IB'!E47 -> 0 | F32: ='Overview IB'!I47 -> 0 | G32: ='Overview IB'!J47 -> 0 | H32: ='Overview IB'!K47 -> 0 | I32: ='Overview IB'!L47 -> 0 | J32: ='Overview IB'!M47 -> 0 | K32: ='Overview IB'!N47 -> 0 | L32: ='Overview IB'!O47 -> 0 | M32: ='Overview IB'!P47 -> 0 | ... O32: ='Overview IB'!R47 -> 0 | Q32: =SUM(U32:AD32) -> 0 | S32: =IF(D32=0,0,IF(E32=0,IF(R32=0,Q32/D32,R32/D32),IF(R32=0,Q32/E32,R32/E32))) -> 0
C33: Bereich Sprache | D33: Anzahl SOLL | E33: Anzahl SOLL berichtigt | F33: M 1 | G33: M 2 | H33: M 3 | I33: M 4 | J33: M 5 | K33: M 6 | L33: M 7 | M33: M 8 | N33: M 9 | O33: M 10 | Q33: IST | R33: IST berichtigt | S33: Erfüllt in % | T33: Anmerkungen | U33: M 1 | V33: M 2 | W33: M 3 | X33: M 4 | Y33: M 5 | Z33: M 6 | AA33: M 7 | AB33: M 8 | AC33: M 9 | AD33: M 10
C34: Anzahl der Fachsprach- bzw. Sprachkurse gesamt | D34: ='Overview IB'!D49 -> 0 | E34: ='Overview IB'!E49 -> 0 | F34: ='Overview IB'!I49 -> 0 | G34: ='Overview IB'!J49 -> 0 | H34: ='Overview IB'!K49 -> 0 | I34: ='Overview IB'!L49 -> 0 | J34: ='Overview IB'!M49 -> 0 | K34: ='Overview IB'!N49 -> 0 | L34: ='Overview IB'!O49 -> 0 | M34: ='Overview IB'!P49 -> 0 | ... O34: ='Overview IB'!R49 -> 0 | Q34: =SUM(Q35:Q39) -> 0 | R34: =SUM(R35:R39) -> 0 | S34: =IF(D34=0,0,IF(E34=0,IF(R34=0,Q34/D34,R34/D34),IF(R34=0,Q34/E34,R34/E34))) -> 0 | U34: =SUM(U35:U39) -> 0 | V34: =SUM(V35:V39) -> 0 | W34: =SUM(W35:W39) -> 0 | X34: =SUM(X35:X39) -> 0 | Y34: =SUM(Y35:Y39) -> 0 | Z34: =SUM(Z35:Z39) -> 0 | AA34: =SUM(AA35:AA39) -> 0 | AB34: =SUM(AB35:AB39) -> 0 | ... AD34: =SUM(AD35:AD39) -> 0
C35: davon Alphabetisierung | D35: ='Overview IB'!D50 -> 0 | E35: ='Overview IB'!E50 -> 0 | F35: ='Overview IB'!I50 -> 0 | G35: ='Overview IB'!J50 -> 0 | H35: ='Overview IB'!K50 -> 0 | I35: ='Overview IB'!L50 -> 0 | J35: ='Overview IB'!M50 -> 0 | K35: ='Overview IB'!N50 -> 0 | L35: ='Overview IB'!O50 -> 0 | M35: ='Overview IB'!P50 -> 0 | ... O35: ='Overview IB'!R50 -> 0 | Q35: =SUM(U35:AD35) -> 0 | S35: =IF(D35=0,0,IF(E35=0,IF(R35=0,Q35/D35,R35/D35),IF(R35=0,Q35/E35,R35/E35))) -> 0
C36: davon A1 | D36: ='Overview IB'!D51 -> 0 | E36: ='Overview IB'!E51 -> 0 | F36: ='Overview IB'!I51 -> 0 | G36: ='Overview IB'!J51 -> 0 | H36: ='Overview IB'!K51 -> 0 | I36: ='Overview IB'!L51 -> 0 | J36: ='Overview IB'!M51 -> 0 | K36: ='Overview IB'!N51 -> 0 | L36: ='Overview IB'!O51 -> 0 | M36: ='Overview IB'!P51 -> 0 | ... O36: ='Overview IB'!R51 -> 0 | Q36: =SUM(U36:AD36) -> 0 | S36: =IF(D36=0,0,IF(E36=0,IF(R36=0,Q36/D36,R36/D36),IF(R36=0,Q36/E36,R36/E36))) -> 0
C37: davon A2 | D37: ='Overview IB'!D52 -> 0 | E37: ='Overview IB'!E52 -> 0 | F37: ='Overview IB'!I52 -> 0 | G37: ='Overview IB'!J52 -> 0 | H37: ='Overview IB'!K52 -> 0 | I37: ='Overview IB'!L52 -> 0 | J37: ='Overview IB'!M52 -> 0 | K37: ='Overview IB'!N52 -> 0 | L37: ='Overview IB'!O52 -> 0 | M37: ='Overview IB'!P52 -> 0 | ... O37: ='Overview IB'!R52 -> 0 | Q37: =SUM(U37:AD37) -> 0 | S37: =IF(D37=0,0,IF(E37=0,IF(R37=0,Q37/D37,R37/D37),IF(R37=0,Q37/E37,R37/E37))) -> 0
C38: davon B1 | D38: ='Overview IB'!D53 -> 0 | E38: ='Overview IB'!E53 -> 0 | F38: ='Overview IB'!I53 -> 0 | G38: ='Overview IB'!J53 -> 0 | H38: ='Overview IB'!K53 -> 0 | I38: ='Overview IB'!L53 -> 0 | J38: ='Overview IB'!M53 -> 0 | K38: ='Overview IB'!N53 -> 0 | L38: ='Overview IB'!O53 -> 0 | M38: ='Overview IB'!P53 -> 0 | ... O38: ='Overview IB'!R53 -> 0 | Q38: =SUM(U38:AD38) -> 0 | S38: =IF(D38=0,0,IF(E38=0,IF(R38=0,Q38/D38,R38/D38),IF(R38=0,Q38/E38,R38/E38))) -> 0
C39: davon B2 | D39: ='Overview IB'!D54 -> 0 | E39: ='Overview IB'!E54 -> 0 | F39: ='Overview IB'!I54 -> 0 | G39: ='Overview IB'!J54 -> 0 | H39: ='Overview IB'!K54 -> 0 | I39: ='Overview IB'!L54 -> 0 | J39: ='Overview IB'!M54 -> 0 | K39: ='Overview IB'!N54 -> 0 | L39: ='Overview IB'!O54 -> 0 | M39: ='Overview IB'!P54 -> 0 | ... O39: ='Overview IB'!R54 -> 0 | Q39: =SUM(U39:AD39) -> 0 | S39: =IF(D39=0,0,IF(E39=0,IF(R39=0,Q39/D39,R39/D39),IF(R39=0,Q39/E39,R39/E39))) -> 0
C40: Anzahl der Fachsprach- bzw. Sprachkursplätze gesamt | D40: ='Overview IB'!D55 -> 0 | E40: ='Overview IB'!E55 -> 0 | F40: ='Overview IB'!I55 -> 0 | G40: ='Overview IB'!J55 -> 0 | H40: ='Overview IB'!K55 -> 0 | I40: ='Overview IB'!L55 -> 0 | J40: ='Overview IB'!M55 -> 0 | K40: ='Overview IB'!N55 -> 0 | L40: ='Overview IB'!O55 -> 0 | M40: ='Overview IB'!P55 -> 0 | ... O40: ='Overview IB'!R55 -> 0 | Q40: =SUM(U40:AD40) -> 0 | S40: =IF(D40=0,0,IF(E40=0,IF(R40=0,Q40/D40,R40/D40),IF(R40=0,Q40/E40,R40/E40))) -> 0
C41: Anzahl der Fachsprach- bzw. Sprachkursteilnehmenden gesamt | D41: ='Overview IB'!D56 -> 0 | E41: ='Overview IB'!E56 -> 0 | F41: ='Overview IB'!I56 -> 0 | G41: ='Overview IB'!J56 -> 0 | H41: ='Overview IB'!K56 -> 0 | I41: ='Overview IB'!L56 -> 0 | J41: ='Overview IB'!M56 -> 0 | K41: ='Overview IB'!N56 -> 0 | L41: ='Overview IB'!O56 -> 0 | M41: ='Overview IB'!P56 -> 0 | ... O41: ='Overview IB'!R56 -> 0 | Q41: =SUM(U41:AD41) -> 0 | S41: =IF(D41=0,0,IF(E41=0,IF(R41=0,Q41/D41,R41/D41),IF(R41=0,Q41/E41,R41/E41))) -> 0
C42: Anzahl der Unterrichtseinheiten gesamt | D42: ='Overview IB'!D57 -> 0 | E42: ='Overview IB'!E57 -> 0 | F42: ='Overview IB'!I57 -> 0 | G42: ='Overview IB'!J57 -> 0 | H42: ='Overview IB'!K57 -> 0 | I42: ='Overview IB'!L57 -> 0 | J42: ='Overview IB'!M57 -> 0 | K42: ='Overview IB'!N57 -> 0 | L42: ='Overview IB'!O57 -> 0 | M42: ='Overview IB'!P57 -> 0 | ... O42: ='Overview IB'!R57 -> 0 | Q42: =SUM(U42:AD42) -> 0 | S42: =IF(D42=0,0,IF(E42=0,IF(R42=0,Q42/D42,R42/D42),IF(R42=0,Q42/E42,R42/E42))) -> 0
C43: Anzahl der Teilnehmenden an einer zertifizierten Abschlussprüfung | D43: ='Overview IB'!D58 -> 0 | E43: ='Overview IB'!E58 -> 0 | F43: ='Overview IB'!I58 -> 0 | G43: ='Overview IB'!J58 -> 0 | H43: ='Overview IB'!K58 -> 0 | I43: ='Overview IB'!L58 -> 0 | J43: ='Overview IB'!M58 -> 0 | K43: ='Overview IB'!N58 -> 0 | L43: ='Overview IB'!O58 -> 0 | M43: ='Overview IB'!P58 -> 0 | ... O43: ='Overview IB'!R58 -> 0 | Q43: =SUM(U43:AD43) -> 0 | S43: =IF(D43=0,0,IF(E43=0,IF(R43=0,Q43/D43,R43/D43),IF(R43=0,Q43/E43,R43/E43))) -> 0
C44: Anteil der Teilnehmenden mit positiv absolvierter, zertifizierter Abschlussprüfung | D44: ='Overview IB'!D59 -> 0 | E44: ='Overview IB'!E59 -> 0 | F44: ='Overview IB'!I59 -> 0 | G44: ='Overview IB'!J59 -> 0 | H44: ='Overview IB'!K59 -> 0 | I44: ='Overview IB'!L59 -> 0 | J44: ='Overview IB'!M59 -> 0 | K44: ='Overview IB'!N59 -> 0 | L44: ='Overview IB'!O59 -> 0 | M44: ='Overview IB'!P59 -> 0 | ... O44: ='Overview IB'!R59 -> 0 | Q44: =SUM(U44:AD44) -> 0 | S44: =IF(D44=0,0,IF(E44=0,IF(R44=0,Q44/D44,R44/D44),IF(R44=0,Q44/E44,R44/E44))) -> 0
...

Sheet 2. ZWB
C4: Zeitraum des Indikatorenberichts | I4: Angaben zum Projekt
C5: von | D5: =L5 -> 45292 | I5: Laufzeit Beginn | L5: =IF('Overview IB'!D9="","",'Overview IB'!D9) -> 45292
C6: bis | D6: 45657 | I6: Laufzeit Ende | L6: =IF('Overview IB'!D10="","",'Overview IB'!D10) -> 46022
C7: Anteil an Laufzeit | D7: =IF(OR(D5="",L7="befüllt sich automatisch"),0,((D6-D5)/30)/L7) -> 0.5 | I7: Projektdauer in Monaten | L7: =IF(IF(OR(L6="",L5=""),"",(L6-L5)/30)="","befüllt sich automatisch",IF(OR(L6="",L5=""),"",(L6-L5)/30)) -> 24.333333
C9: Zielindikatoren | D9: Anzahl SOLL lt. Vertrag | E9: Anzahl SOLL berichtigt lt. Vertrag | F9: Maßnahmen Soll lt. Vertrag | Q9: Anzahl IST - gesamt | R9: Anzahl IST - gesamt - berichtigt | S9: Erfüllt in % | T9: allgemeine Anmerkungen zu den IST-Indikatoren | U9: Maßnahmen IST lt. Vertrag
F10: M 1 | G10: M 2 | H10: M 3 | I10: M 4 | J10: M 5 | K10: M 6 | L10: M 7 | M10: M 8 | N10: M 9 | O10: M 10 | U10: M 1 | V10: M 2 | W10: M 3 | X10: M 4 | Y10: M 5 | Z10: M 6 | AA10: M 7 | AB10: M 8 | AC10: M 9 | AD10: M 10
C11: Anzahl der Projektteilnehmenden gesamt | D11: ='Overview IB'!D26 -> 194 | E11: ='Overview IB'!E26 -> 72 | F11: ='Overview IB'!I26 -> 72 | G11: ='Overview IB'!J26 -> 72 | H11: ='Overview IB'!K26 -> 50 | I11: ='Overview IB'!L26 -> 0 | J11: ='Overview IB'!M26 -> 0 | K11: ='Overview IB'!N26 -> 0 | L11: ='Overview IB'!O26 -> 0 | M11: ='Overview IB'!P26 -> 0 | ... O11: ='Overview IB'!R26 -> 0 | Q11: =SUM(U11:AD11) -> 149 | R11: 55 | S11: =IF(D11=0,0,IF(E11=0,IF(R11=0,Q11/D11,R11/D11),IF(R11=0,Q11/E11,R11/E11))) -> 0.76388889 | U11: 55 | V11: 55 | W11: 39
C12: Anzahl der verfügbaren Plätze im Projekt | D12: ='Overview IB'!D27 -> 194 | E12: ='Overview IB'!E27 -> 72 | F12: ='Overview IB'!I27 -> 72 | G12: ='Overview IB'!J27 -> 72 | H12: ='Overview IB'!K27 -> 50 | I12: ='Overview IB'!L27 -> 0 | J12: ='Overview IB'!M27 -> 0 | K12: ='Overview IB'!N27 -> 0 | L12: ='Overview IB'!O27 -> 0 | M12: ='Overview IB'!P27 -> 0 | ... O12: ='Overview IB'!R27 -> 0 | Q12: =SUM(U12:AD12) -> 149 | R12: 55 | S12: =IF(D12=0,0,IF(E12=0,IF(R12=0,Q12/D12,R12/D12),IF(R12=0,Q12/E12,R12/E12))) -> 0.76388889 | U12: 55 | V12: 55 | W12: 39
C13: Anzahl der Standorte, an denen die Maßnahmen durchgeführt werden | D13: ='Overview IB'!D28 -> 3 | E13: ='Overview IB'!E28 -> 1 | F13: ='Overview IB'!I28 -> 1 | G13: ='Overview IB'!J28 -> 1 | H13: ='Overview IB'!K28 -> 1 | I13: ='Overview IB'!L28 -> 0 | J13: ='Overview IB'!M28 -> 0 | K13: ='Overview IB'!N28 -> 0 | L13: ='Overview IB'!O28 -> 0 | M13: ='Overview IB'!P28 -> 0 | ... O13: ='Overview IB'!R28 -> 0 | Q13: =SUM(U13:AD13) -> 3 | R13: 1 | S13: =IF(D13=0,0,IF(E13=0,IF(R13=0,Q13/D13,R13/D13),IF(R13=0,Q13/E13,R13/E13))) -> 1 | U13: 1 | V13: 1 | W13: 1
C14: Bereich Veranstaltungen | D14: Anzahl SOLL | E14: Anzahl SOLL berichtigt | F14: M 1 | G14: M 2 | H14: M 3 | I14: M 4 | J14: M 5 | K14: M 6 | L14: M 7 | M14: M 8 | N14: M 9 | O14: M 10 | Q14: IST | R14: IST berichtigt | S14: Erfüllt in % | T14: Anmerkungen | U14: M 1 | V14: M 2 | W14: M 3 | X14: M 4 | Y14: M 5 | Z14: M 6 | AA14: M 7 | AB14: M 8 | AC14: M 9 | AD14: M 10
C15: Anzahl der Veranstaltungen | D15: ='Overview IB'!D30 -> 0 | E15: ='Overview IB'!E30 -> 0 | F15: ='Overview IB'!I30 -> 0 | G15: ='Overview IB'!J30 -> 0 | H15: ='Overview IB'!K30 -> 0 | I15: ='Overview IB'!L30 -> 0 | J15: ='Overview IB'!M30 -> 0 | K15: ='Overview IB'!N30 -> 0 | L15: ='Overview IB'!O30 -> 0 | M15: ='Overview IB'!P30 -> 0 | ... O15: ='Overview IB'!R30 -> 0 | Q15: =SUM(U15:AD15) -> 0 | S15: =IF(D15=0,0,IF(E15=0,IF(R15=0,Q15/D15,R15/D15),IF(R15=0,Q15/E15,R15/E15))) -> 0
C16: Anzahl der Veranstaltungsteilnehmenden gesamt | D16: ='Overview IB'!D31 -> 0 | E16: ='Overview IB'!E31 -> 0 | F16: ='Overview IB'!I31 -> 0 | G16: ='Overview IB'!J31 -> 0 | H16: ='Overview IB'!K31 -> 0 | I16: ='Overview IB'!L31 -> 0 | J16: ='Overview IB'!M31 -> 0 | K16: ='Overview IB'!N31 -> 0 | L16: ='Overview IB'!O31 -> 0 | M16: ='Overview IB'!P31 -> 0 | ... O16: ='Overview IB'!R31 -> 0 | Q16: =SUM(U16:AD16) -> 0 | S16: =IF(D16=0,0,IF(E16=0,IF(R16=0,Q16/D16,R16/D16),IF(R16=0,Q16/E16,R16/E16))) -> 0
C17: Anzahl der Kurse/Workshops/Trainings | D17: ='Overview IB'!D32 -> 0 | E17: ='Overview IB'!E32 -> 0 | F17: ='Overview IB'!I32 -> 0 | G17: ='Overview IB'!J32 -> 0 | H17: ='Overview IB'!K32 -> 0 | I17: ='Overview IB'!L32 -> 0 | J17: ='Overview IB'!M32 -> 0 | K17: ='Overview IB'!N32 -> 0 | L17: ='Overview IB'!O32 -> 0 | M17: ='Overview IB'!P32 -> 0 | ... O17: ='Overview IB'!R32 -> 0 | Q17: =SUM(U17:AD17) -> 0 | S17: =IF(D17=0,0,IF(E17=0,IF(R17=0,Q17/D17,R17/D17),IF(R17=0,Q17/E17,R17/E17))) -> 0
C18: Anzahl der Teilnehmenden an Kursen/Workshops/ Trainings | D18: ='Overview IB'!D33 -> 0 | E18: ='Overview IB'!E33 -> 0 | F18: ='Overview IB'!I33 -> 0 | G18: ='Overview IB'!J33 -> 0 | H18: ='Overview IB'!K33 -> 0 | I18: ='Overview IB'!L33 -> 0 | J18: ='Overview IB'!M33 -> 0 | K18: ='Overview IB'!N33 -> 0 | L18: ='Overview IB'!O33 -> 0 | M18: ='Overview IB'!P33 -> 0 | ... O18: ='Overview IB'!R33 -> 0 | Q18: =SUM(U18:AD18) -> 0 | S18: =IF(D18=0,0,IF(E18=0,IF(R18=0,Q18/D18,R18/D18),IF(R18=0,Q18/E18,R18/E18))) -> 0
C19: Anzahl der Kurs-, Workshop- bzw. Trainingsstunden | D19: ='Overview IB'!D34 -> 0 | E19: ='Overview IB'!E34 -> 0 | F19: ='Overview IB'!I34 -> 0 | G19: ='Overview IB'!J34 -> 0 | H19: ='Overview IB'!K34 -> 0 | I19: ='Overview IB'!L34 -> 0 | J19: ='Overview IB'!M34 -> 0 | K19: ='Overview IB'!N34 -> 0 | L19: ='Overview IB'!O34 -> 0 | M19: ='Overview IB'!P34 -> 0 | ... O19: ='Overview IB'!R34 -> 0 | Q19: =SUM(U19:AD19) -> 0 | S19: =IF(D19=0,0,IF(E19=0,IF(R19=0,Q19/D19,R19/D19),IF(R19=0,Q19/E19,R19/E19))) -> 0
C20: Bereich Beratung | D20: Anzahl SOLL | E20: Anzahl SOLL berichtigt | F20: M 1 | G20: M 2 | H20: M 3 | I20: M 4 | J20: M 5 | K20: M 6 | L20: M 7 | M20: M 8 | N20: M 9 | O20: M 10 | Q20: IST | R20: IST berichtigt | S20: Erfüllt in % | T20: Anmerkungen | U20: M 1 | V20: M 2 | W20: M 3 | X20: M 4 | Y20: M 5 | Z20: M 6 | AA20: M 7 | AB20: M 8 | AC20: M 9 | AD20: M 10
C21: Anzahl der Einzelberatungen bzw. -betreuung | D21: ='Overview IB'!D36 -> 0 | E21: ='Overview IB'!E36 -> 0 | F21: ='Overview IB'!I36 -> 0 | G21: ='Overview IB'!J36 -> 0 | H21: ='Overview IB'!K36 -> 0 | I21: ='Overview IB'!L36 -> 0 | J21: ='Overview IB'!M36 -> 0 | K21: ='Overview IB'!N36 -> 0 | L21: ='Overview IB'!O36 -> 0 | M21: ='Overview IB'!P36 -> 0 | ... O21: ='Overview IB'!R36 -> 0 | Q21: =SUM(U21:AD21) -> 0 | S21: =IF(D21=0,0,IF(E21=0,IF(R21=0,Q21/D21,R21/D21),IF(R21=0,Q21/E21,R21/E21))) -> 0
C22: Anzahl der in Einzelberatung beratenen, betreuten oder gecoachten Personen | D22: ='Overview IB'!D37 -> 144 | E22: ='Overview IB'!E37 -> 72 | F22: ='Overview IB'!I37 -> 72 | G22: ='Overview IB'!J37 -> 72 | H22: ='Overview IB'!K37 -> 0 | I22: ='Overview IB'!L37 -> 0 | J22: ='Overview IB'!M37 -> 0 | K22: ='Overview IB'!N37 -> 0 | L22: ='Overview IB'!O37 -> 0 | M22: ='Overview IB'!P37 -> 0 | ... O22: ='Overview IB'!R37 -> 0 | Q22: =SUM(U22:AD22) -> 110 | R22: 55 | S22: =IF(D22=0,0,IF(E22=0,IF(R22=0,Q22/D22,R22/D22),IF(R22=0,Q22/E22,R22/E22))) -> 0.76388889 | U22: 55 | V22: 55
C23: Anzahl der Einzelberatungs-/Betreuungs-/ Coachingstunden | D23: ='Overview IB'!D38 -> 1170 | E23: ='Overview IB'!E38 -> 1170 | F23: ='Overview IB'!I38 -> 360 | G23: ='Overview IB'!J38 -> 810 | H23: ='Overview IB'!K38 -> 0 | I23: ='Overview IB'!L38 -> 0 | J23: ='Overview IB'!M38 -> 0 | K23: ='Overview IB'!N38 -> 0 | L23: ='Overview IB'!O38 -> 0 | M23: ='Overview IB'!P38 -> 0 | ... O23: ='Overview IB'!R38 -> 0 | Q23: =SUM(U23:AD23) -> 654 | R23: 654 | S23: =IF(D23=0,0,IF(E23=0,IF(R23=0,Q23/D23,R23/D23),IF(R23=0,Q23/E23,R23/E23))) -> 0.55897436 | U23: 205.5 | V23: 448.5
C24: Anzahl der Gruppenberatungen bzw. -betreuung (min 3 Personen) | D24: ='Overview IB'!D39 -> 0 | E24: ='Overview IB'!E39 -> 0 | F24: ='Overview IB'!I39 -> 0 | G24: ='Overview IB'!J39 -> 0 | H24: ='Overview IB'!K39 -> 0 | I24: ='Overview IB'!L39 -> 0 | J24: ='Overview IB'!M39 -> 0 | K24: ='Overview IB'!N39 -> 0 | L24: ='Overview IB'!O39 -> 0 | M24: ='Overview IB'!P39 -> 0 | ... O24: ='Overview IB'!R39 -> 0 | Q24: =SUM(U24:AD24) -> 0 | S24: =IF(D24=0,0,IF(E24=0,IF(R24=0,Q24/D24,R24/D24),IF(R24=0,Q24/E24,R24/E24))) -> 0
C25: Anzahl der in Gruppenberatung beratenen oder betreuten Personen | D25: ='Overview IB'!D40 -> 50 | E25: ='Overview IB'!E40 -> 50 | F25: ='Overview IB'!I40 -> 0 | G25: ='Overview IB'!J40 -> 0 | H25: ='Overview IB'!K40 -> 50 | I25: ='Overview IB'!L40 -> 0 | J25: ='Overview IB'!M40 -> 0 | K25: ='Overview IB'!N40 -> 0 | L25: ='Overview IB'!O40 -> 0 | M25: ='Overview IB'!P40 -> 0 | ... O25: ='Overview IB'!R40 -> 0 | Q25: =SUM(U25:AD25) -> 39 | R25: 39 | S25: =IF(D25=0,0,IF(E25=0,IF(R25=0,Q25/D25,R25/D25),IF(R25=0,Q25/E25,R25/E25))) -> 0.78 | W25: 39
C26: Anzahl der Gruppenberatungs-/Betreuungsstunden | D26: ='Overview IB'!D41 -> 540 | E26: ='Overview IB'!E41 -> 540 | F26: ='Overview IB'!I41 -> 0 | G26: ='Overview IB'!J41 -> 0 | H26: ='Overview IB'!K41 -> 540 | I26: ='Overview IB'!L41 -> 0 | J26: ='Overview IB'!M41 -> 0 | K26: ='Overview IB'!N41 -> 0 | L26: ='Overview IB'!O41 -> 0 | M26: ='Overview IB'!P41 -> 0 | ... O26: ='Overview IB'!R41 -> 0 | Q26: =SUM(U26:AD26) -> 298 | R26: 298 | S26: =IF(D26=0,0,IF(E26=0,IF(R26=0,Q26/D26,R26/D26),IF(R26=0,Q26/E26,R26/E26))) -> 0.55185185 | W26: 298
C27: Anzahl der Familienberatungen (pro Familie) | D27: ='Overview IB'!D42 -> 0 | E27: ='Overview IB'!E42 -> 0 | F27: ='Overview IB'!I42 -> 0 | G27: ='Overview IB'!J42 -> 0 | H27: ='Overview IB'!K42 -> 0 | I27: ='Overview IB'!L42 -> 0 | J27: ='Overview IB'!M42 -> 0 | K27: ='Overview IB'!N42 -> 0 | L27: ='Overview IB'!O42 -> 0 | M27: ='Overview IB'!P42 -> 0 | ... O27: ='Overview IB'!R42 -> 0 | Q27: =SUM(U27:AD27) -> 0 | S27: =IF(D27=0,0,IF(E27=0,IF(R27=0,Q27/D27,R27/D27),IF(R27=0,Q27/E27,R27/E27))) -> 0
C28: Anzahl der familienberatenen oder betreuten Personen | D28: ='Overview IB'!D43 -> 0 | E28: ='Overview IB'!E43 -> 0 | F28: ='Overview IB'!I43 -> 0 | G28: ='Overview IB'!J43 -> 0 | H28: ='Overview IB'!K43 -> 0 | I28: ='Overview IB'!L43 -> 0 | J28: ='Overview IB'!M43 -> 0 | K28: ='Overview IB'!N43 -> 0 | L28: ='Overview IB'!O43 -> 0 | M28: ='Overview IB'!P43 -> 0 | ... O28: ='Overview IB'!R43 -> 0 | Q28: =SUM(U28:AD28) -> 0 | S28: =IF(D28=0,0,IF(E28=0,IF(R28=0,Q28/D28,R28/D28),IF(R28=0,Q28/E28,R28/E28))) -> 0
C29: Anzahl der Beratungs-/Betreuungsstunden für Familien | D29: ='Overview IB'!D44 -> 0 | E29: ='Overview IB'!E44 -> 0 | F29: ='Overview IB'!I44 -> 0 | G29: ='Overview IB'!J44 -> 0 | H29: ='Overview IB'!K44 -> 0 | I29: ='Overview IB'!L44 -> 0 | J29: ='Overview IB'!M44 -> 0 | K29: ='Overview IB'!N44 -> 0 | L29: ='Overview IB'!O44 -> 0 | M29: ='Overview IB'!P44 -> 0 | ... O29: ='Overview IB'!R44 -> 0 | Q29: =SUM(U29:AD29) -> 0 | S29: =IF(D29=0,0,IF(E29=0,IF(R29=0,Q29/D29,R29/D29),IF(R29=0,Q29/E29,R29/E29))) -> 0
C30: Anzahl der Hausbesuche | D30: ='Overview IB'!D45 -> 0 | E30: ='Overview IB'!E45 -> 0 | F30: ='Overview IB'!I45 -> 0 | G30: ='Overview IB'!J45 -> 0 | H30: ='Overview IB'!K45 -> 0 | I30: ='Overview IB'!L45 -> 0 | J30: ='Overview IB'!M45 -> 0 | K30: ='Overview IB'!N45 -> 0 | L30: ='Overview IB'!O45 -> 0 | M30: ='Overview IB'!P45 -> 0 | ... O30: ='Overview IB'!R45 -> 0 | Q30: =SUM(U30:AD30) -> 0 | S30: =IF(D30=0,0,IF(E30=0,IF(R30=0,Q30/D30,R30/D30),IF(R30=0,Q30/E30,R30/E30))) -> 0
C31: Anzahl besuchter Haushalte | D31: ='Overview IB'!D46 -> 0 | E31: ='Overview IB'!E46 -> 0 | F31: ='Overview IB'!I46 -> 0 | G31: ='Overview IB'!J46 -> 0 | H31: ='Overview IB'!K46 -> 0 | I31: ='Overview IB'!L46 -> 0 | J31: ='Overview IB'!M46 -> 0 | K31: ='Overview IB'!N46 -> 0 | L31: ='Overview IB'!O46 -> 0 | M31: ='Overview IB'!P46 -> 0 | ... O31: ='Overview IB'!R46 -> 0 | Q31: =SUM(U31:AD31) -> 0 | S31: =IF(D31=0,0,IF(E31=0,IF(R31=0,Q31/D31,R31/D31),IF(R31=0,Q31/E31,R31/E31))) -> 0
C32: Anzahl besuchter Personen | D32: ='Overview IB'!D47 -> 0 | E32: ='Overview IB'!E47 -> 0 | F32: ='Overview IB'!I47 -> 0 | G32: ='Overview IB'!J47 -> 0 | H32: ='Overview IB'!K47 -> 0 | I32: ='Overview IB'!L47 -> 0 | J32: ='Overview IB'!M47 -> 0 | K32: ='Overview IB'!N47 -> 0 | L32: ='Overview IB'!O47 -> 0 | M32: ='Overview IB'!P47 -> 0 | ... O32: ='Overview IB'!R47 -> 0 | Q32: =SUM(U32:AD32) -> 0 | S32: =IF(D32=0,0,IF(E32=0,IF(R32=0,Q32/D32,R32/D32),IF(R32=0,Q32/E32,R32/E32))) -> 0
C33: Bereich Sprache | D33: Anzahl SOLL | E33: Anzahl SOLL berichtigt | F33: M 1 | G33: M 2 | H33: M 3 | I33: M 4 | J33: M 5 | K33: M 6 | L33: M 7 | M33: M 8 | N33: M 9 | O33: M 10 | Q33: IST | R33: IST berichtigt | S33: Erfüllt in % | T33: Anmerkungen | U33: M 1 | V33: M 2 | W33: M 3 | X33: M 4 | Y33: M 5 | Z33: M 6 | AA33: M 7 | AB33: M 8 | AC33: M 9 | AD33: M 10
C34: Anzahl der Fachsprach- bzw. Sprachkurse gesamt | D34: ='Overview IB'!D49 -> 0 | E34: ='Overview IB'!E49 -> 0 | F34: ='Overview IB'!I49 -> 0 | G34: ='Overview IB'!J49 -> 0 | H34: ='Overview IB'!K49 -> 0 | I34: ='Overview IB'!L49 -> 0 | J34: ='Overview IB'!M49 -> 0 | K34: ='Overview IB'!N49 -> 0 | L34: ='Overview IB'!O49 -> 0 | M34: ='Overview IB'!P49 -> 0 | ... O34: ='Overview IB'!R49 -> 0 | Q34: =SUM(Q35:Q39) -> 0 | R34: =SUM(R35:R39) -> 0 | S34: =IF(D34=0,0,IF(E34=0,IF(R34=0,Q34/D34,R34/D34),IF(R34=0,Q34/E34,R34/E34))) -> 0 | U34: =SUM(U35:U39) -> 0 | V34: =SUM(V35:V39) -> 0 | W34: =SUM(W35:W39) -> 0 | X34: =SUM(X35:X39) -> 0 | Y34: =SUM(Y35:Y39) -> 0 | Z34: =SUM(Z35:Z39) -> 0 | AA34: =SUM(AA35:AA39) -> 0 | AB34: =SUM(AB35:AB39) -> 0 | ... AD34: =SUM(AD35:AD39) -> 0
C35: davon Alphabetisierung | D35: ='Overview IB'!D50 -> 0 | E35: ='Overview IB'!E50 -> 0 | F35: ='Overview IB'!I50 -> 0 | G35: ='Overview IB'!J50 -> 0 | H35: ='Overview IB'!K50 -> 0 | I35: ='Overview IB'!L50 -> 0 | J35: ='Overview IB'!M50 -> 0 | K35: ='Overview IB'!N50 -> 0 | L35: ='Overview IB'!O50 -> 0 | M35: ='Overview IB'!P50 -> 0 | ... O35: ='Overview IB'!R50 -> 0 | Q35: =SUM(U35:AD35) -> 0 | S35: =IF(D35=0,0,IF(E35=0,IF(R35=0,Q35/D35,R35/D35),IF(R35=0,Q35/E35,R35/E35))) -> 0
C36: davon A1 | D36: ='Overview IB'!D51 -> 0 | E36: ='Overview IB'!E51 -> 0 | F36: ='Overview IB'!I51 -> 0 | G36: ='Overview IB'!J51 -> 0 | H36: ='Overview IB'!K51 -> 0 | I36: ='Overview IB'!L51 -> 0 | J36: ='Overview IB'!M51 -> 0 | K36: ='Overview IB'!N51 -> 0 | L36: ='Overview IB'!O51 -> 0 | M36: ='Overview IB'!P51 -> 0 | ... O36: ='Overview IB'!R51 -> 0 | Q36: =SUM(U36:AD36) -> 0 | S36: =IF(D36=0,0,IF(E36=0,IF(R36=0,Q36/D36,R36/D36),IF(R36=0,Q36/E36,R36/E36))) -> 0
C37: davon A2 | D37: ='Overview IB'!D52 -> 0 | E37: ='Overview IB'!E52 -> 0 | F37: ='Overview IB'!I52 -> 0 | G37: ='Overview IB'!J52 -> 0 | H37: ='Overview IB'!K52 -> 0 | I37: ='Overview IB'!L52 -> 0 | J37: ='Overview IB'!M52 -> 0 | K37: ='Overview IB'!N52 -> 0 | L37: ='Overview IB'!O52 -> 0 | M37: ='Overview IB'!P52 -> 0 | ... O37: ='Overview IB'!R52 -> 0 | Q37: =SUM(U37:AD37) -> 0 | S37: =IF(D37=0,0,IF(E37=0,IF(R37=0,Q37/D37,R37/D37),IF(R37=0,Q37/E37,R37/E37))) -> 0
C38: davon B1 | D38: ='Overview IB'!D53 -> 0 | E38: ='Overview IB'!E53 -> 0 | F38: ='Overview IB'!I53 -> 0 | G38: ='Overview IB'!J53 -> 0 | H38: ='Overview IB'!K53 -> 0 | I38: ='Overview IB'!L53 -> 0 | J38: ='Overview IB'!M53 -> 0 | K38: ='Overview IB'!N53 -> 0 | L38: ='Overview IB'!O53 -> 0 | M38: ='Overview IB'!P53 -> 0 | ... O38: ='Overview IB'!R53 -> 0 | Q38: =SUM(U38:AD38) -> 0 | S38: =IF(D38=0,0,IF(E38=0,IF(R38=0,Q38/D38,R38/D38),IF(R38=0,Q38/E38,R38/E38))) -> 0
C39: davon B2 | D39: ='Overview IB'!D54 -> 0 | E39: ='Overview IB'!E54 -> 0 | F39: ='Overview IB'!I54 -> 0 | G39: ='Overview IB'!J54 -> 0 | H39: ='Overview IB'!K54 -> 0 | I39: ='Overview IB'!L54 -> 0 | J39: ='Overview IB'!M54 -> 0 | K39: ='Overview IB'!N54 -> 0 | L39: ='Overview IB'!O54 -> 0 | M39: ='Overview IB'!P54 -> 0 | ... O39: ='Overview IB'!R54 -> 0 | Q39: =SUM(U39:AD39) -> 0 | S39: =IF(D39=0,0,IF(E39=0,IF(R39=0,Q39/D39,R39/D39),IF(R39=0,Q39/E39,R39/E39))) -> 0
C40: Anzahl der Fachsprach- bzw. Sprachkursplätze gesamt | D40: ='Overview IB'!D55 -> 0 | E40: ='Overview IB'!E55 -> 0 | F40: ='Overview IB'!I55 -> 0 | G40: ='Overview IB'!J55 -> 0 | H40: ='Overview IB'!K55 -> 0 | I40: ='Overview IB'!L55 -> 0 | J40: ='Overview IB'!M55 -> 0 | K40: ='Overview IB'!N55 -> 0 | L40: ='Overview IB'!O55 -> 0 | M40: ='Overview IB'!P55 -> 0 | ... O40: ='Overview IB'!R55 -> 0 | Q40: =SUM(U40:AD40) -> 0 | S40: =IF(D40=0,0,IF(E40=0,IF(R40=0,Q40/D40,R40/D40),IF(R40=0,Q40/E40,R40/E40))) -> 0
C41: Anzahl der Fachsprach- bzw. Sprachkursteilnehmenden gesamt | D41: ='Overview IB'!D56 -> 0 | E41: ='Overview IB'!E56 -> 0 | F41: ='Overview IB'!I56 -> 0 | G41: ='Overview IB'!J56 -> 0 | H41: ='Overview IB'!K56 -> 0 | I41: ='Overview IB'!L56 -> 0 | J41: ='Overview IB'!M56 -> 0 | K41: ='Overview IB'!N56 -> 0 | L41: ='Overview IB'!O56 -> 0 | M41: ='Overview IB'!P56 -> 0 | ... O41: ='Overview IB'!R56 -> 0 | Q41: =SUM(U41:AD41) -> 0 | S41: =IF(D41=0,0,IF(E41=0,IF(R41=0,Q41/D41,R41/D41),IF(R41=0,Q41/E41,R41/E41))) -> 0
C42: Anzahl der Unterrichtseinheiten gesamt | D42: ='Overview IB'!D57 -> 0 | E42: ='Overview IB'!E57 -> 0 | F42: ='Overview IB'!I57 -> 0 | G42: ='Overview IB'!J57 -> 0 | H42: ='Overview IB'!K57 -> 0 | I42: ='Overview IB'!L57 -> 0 | J42: ='Overview IB'!M57 -> 0 | K42: ='Overview IB'!N57 -> 0 | L42: ='Overview IB'!O57 -> 0 | M42: ='Overview IB'!P57 -> 0 | ... O42: ='Overview IB'!R57 -> 0 | Q42: =SUM(U42:AD42) -> 0 | S42: =IF(D42=0,0,IF(E42=0,IF(R42=0,Q42/D42,R42/D42),IF(R42=0,Q42/E42,R42/E42))) -> 0
C43: Anzahl der Teilnehmenden an einer zertifizierten Abschlussprüfung | D43: ='Overview IB'!D58 -> 0 | E43: ='Overview IB'!E58 -> 0 | F43: ='Overview IB'!I58 -> 0 | G43: ='Overview IB'!J58 -> 0 | H43: ='Overview IB'!K58 -> 0 | I43: ='Overview IB'!L58 -> 0 | J43: ='Overview IB'!M58 -> 0 | K43: ='Overview IB'!N58 -> 0 | L43: ='Overview IB'!O58 -> 0 | M43: ='Overview IB'!P58 -> 0 | ... O43: ='Overview IB'!R58 -> 0 | Q43: =SUM(U43:AD43) -> 0 | S43: =IF(D43=0,0,IF(E43=0,IF(R43=0,Q43/D43,R43/D43),IF(R43=0,Q43/E43,R43/E43))) -> 0
C44: Anteil der Teilnehmenden mit positiv absolvierter, zertifizierter Abschlussprüfung | D44: ='Overview IB'!D59 -> 0 | E44: ='Overview IB'!E59 -> 0 | F44: ='Overview IB'!I59 -> 0 | G44: ='Overview IB'!J59 -> 0 | H44: ='Overview IB'!K59 -> 0 | I44: ='Overview IB'!L59 -> 0 | J44: ='Overview IB'!M59 -> 0 | K44: ='Overview IB'!N59 -> 0 | L44: ='Overview IB'!O59 -> 0 | M44: ='Overview IB'!P59 -> 0 | ... O44: ='Overview IB'!R59 -> 0 | Q44: =SUM(U44:AD44) -> 0 | S44: =IF(D44=0,0,IF(E44=0,IF(R44=0,Q44/D44,R44/D44),IF(R44=0,Q44/E44,R44/E44))) -> 0
...

Sheet 3. ZWB
C4: Zeitraum des Indikatorenberichts | I4: Angaben zum Projekt
C5: von | D5: =L5 -> 45292 | I5: Laufzeit Beginn | L5: =IF('Overview IB'!D9="","",'Overview IB'!D9) -> 45292
C6: bis | D6: 45838 | I6: Laufzeit Ende | L6: =IF('Overview IB'!D10="","",'Overview IB'!D10) -> 46022
C7: Anteil an Laufzeit | D7: =IF(OR(D5="",L7="befüllt sich automatisch"),0,((D6-D5)/30)/L7) -> 0.74794521 | I7: Projektdauer in Monaten | L7: =IF(IF(OR(L6="",L5=""),"",(L6-L5)/30)="","befüllt sich automatisch",IF(OR(L6="",L5=""),"",(L6-L5)/30)) -> 24.333333
C9: Zielindikatoren | D9: Anzahl SOLL lt. Vertrag | E9: Anzahl SOLL berichtigt lt. Vertrag | F9: Maßnahmen Soll lt. Vertrag | Q9: Anzahl IST - gesamt | R9: Anzahl IST - gesamt - berichtigt | S9: Erfüllt in % | T9: allgemeine Anmerkungen zu den IST-Indikatoren | U9: Maßnahmen IST lt. Vertrag
F10: M 1 | G10: M 2 | H10: M 3 | I10: M 4 | J10: M 5 | K10: M 6 | L10: M 7 | M10: M 8 | N10: M 9 | O10: M 10 | U10: M 1 | V10: M 2 | W10: M 3 | X10: M 4 | Y10: M 5 | Z10: M 6 | AA10: M 7 | AB10: M 8 | AC10: M 9 | AD10: M 10
C11: Anzahl der Projektteilnehmenden gesamt | D11: ='Overview IB'!D26 -> 194 | E11: ='Overview IB'!E26 -> 72 | F11: ='Overview IB'!I26 -> 72 | G11: ='Overview IB'!J26 -> 72 | H11: ='Overview IB'!K26 -> 50 | I11: ='Overview IB'!L26 -> 0 | J11: ='Overview IB'!M26 -> 0 | K11: ='Overview IB'!N26 -> 0 | L11: ='Overview IB'!O26 -> 0 | M11: ='Overview IB'!P26 -> 0 | ... O11: ='Overview IB'!R26 -> 0 | Q11: =SUM(U11:AD11) -> 194 | R11: 74 | S11: =IF(D11=0,0,IF(E11=0,IF(R11=0,Q11/D11,R11/D11),IF(R11=0,Q11/E11,R11/E11))) -> 1.0277778 | U11: 74 | V11: 74 | W11: 46
C12: Anzahl der verfügbaren Plätze im Projekt | D12: ='Overview IB'!D27 -> 194 | E12: ='Overview IB'!E27 -> 72 | F12: ='Overview IB'!I27 -> 72 | G12: ='Overview IB'!J27 -> 72 | H12: ='Overview IB'!K27 -> 50 | I12: ='Overview IB'!L27 -> 0 | J12: ='Overview IB'!M27 -> 0 | K12: ='Overview IB'!N27 -> 0 | L12: ='Overview IB'!O27 -> 0 | M12: ='Overview IB'!P27 -> 0 | ... O12: ='Overview IB'!R27 -> 0 | Q12: =SUM(U12:AD12) -> 194 | R12: 74 | S12: =IF(D12=0,0,IF(E12=0,IF(R12=0,Q12/D12,R12/D12),IF(R12=0,Q12/E12,R12/E12))) -> 1.0277778 | U12: 74 | V12: 74 | W12: 46
C13: Anzahl der Standorte, an denen die Maßnahmen durchgeführt werden | D13: ='Overview IB'!D28 -> 3 | E13: ='Overview IB'!E28 -> 1 | F13: ='Overview IB'!I28 -> 1 | G13: ='Overview IB'!J28 -> 1 | H13: ='Overview IB'!K28 -> 1 | I13: ='Overview IB'!L28 -> 0 | J13: ='Overview IB'!M28 -> 0 | K13: ='Overview IB'!N28 -> 0 | L13: ='Overview IB'!O28 -> 0 | M13: ='Overview IB'!P28 -> 0 | ... O13: ='Overview IB'!R28 -> 0 | Q13: =SUM(U13:AD13) -> 3 | R13: 1 | S13: =IF(D13=0,0,IF(E13=0,IF(R13=0,Q13/D13,R13/D13),IF(R13=0,Q13/E13,R13/E13))) -> 1 | U13: 1 | V13: 1 | W13: 1
C14: Bereich Veranstaltungen | D14: Anzahl SOLL | E14: Anzahl SOLL berichtigt | F14: M 1 | G14: M 2 | H14: M 3 | I14: M 4 | J14: M 5 | K14: M 6 | L14: M 7 | M14: M 8 | N14: M 9 | O14: M 10 | Q14: IST | R14: IST berichtigt | S14: Erfüllt in % | T14: Anmerkungen | U14: M 1 | V14: M 2 | W14: M 3 | X14: M 4 | Y14: M 5 | Z14: M 6 | AA14: M 7 | AB14: M 8 | AC14: M 9 | AD14: M 10
C15: Anzahl der Veranstaltungen | D15: ='Overview IB'!D30 -> 0 | E15: ='Overview IB'!E30 -> 0 | F15: ='Overview IB'!I30 -> 0 | G15: ='Overview IB'!J30 -> 0 | H15: ='Overview IB'!K30 -> 0 | I15: ='Overview IB'!L30 -> 0 | J15: ='Overview IB'!M30 -> 0 | K15: ='Overview IB'!N30 -> 0 | L15: ='Overview IB'!O30 -> 0 | M15: ='Overview IB'!P30 -> 0 | ... O15: ='Overview IB'!R30 -> 0 | Q15: =SUM(U15:AD15) -> 0 | S15: =IF(D15=0,0,IF(E15=0,IF(R15=0,Q15/D15,R15/D15),IF(R15=0,Q15/E15,R15/E15))) -> 0
C16: Anzahl der Veranstaltungsteilnehmenden gesamt | D16: ='Overview IB'!D31 -> 0 | E16: ='Overview IB'!E31 -> 0 | F16: ='Overview IB'!I31 -> 0 | G16: ='Overview IB'!J31 -> 0 | H16: ='Overview IB'!K31 -> 0 | I16: ='Overview IB'!L31 -> 0 | J16: ='Overview IB'!M31 -> 0 | K16: ='Overview IB'!N31 -> 0 | L16: ='Overview IB'!O31 -> 0 | M16: ='Overview IB'!P31 -> 0 | ... O16: ='Overview IB'!R31 -> 0 | Q16: =SUM(U16:AD16) -> 0 | S16: =IF(D16=0,0,IF(E16=0,IF(R16=0,Q16/D16,R16/D16),IF(R16=0,Q16/E16,R16/E16))) -> 0
C17: Anzahl der Kurse/Workshops/Trainings | D17: ='Overview IB'!D32 -> 0 | E17: ='Overview IB'!E32 -> 0 | F17: ='Overview IB'!I32 -> 0 | G17: ='Overview IB'!J32 -> 0 | H17: ='Overview IB'!K32 -> 0 | I17: ='Overview IB'!L32 -> 0 | J17: ='Overview IB'!M32 -> 0 | K17: ='Overview IB'!N32 -> 0 | L17: ='Overview IB'!O32 -> 0 | M17: ='Overview IB'!P32 -> 0 | ... O17: ='Overview IB'!R32 -> 0 | Q17: =SUM(U17:AD17) -> 0 | S17: =IF(D17=0,0,IF(E17=0,IF(R17=0,Q17/D17,R17/D17),IF(R17=0,Q17/E17,R17/E17))) -> 0
C18: Anzahl der Teilnehmenden an Kursen/Workshops/ Trainings | D18: ='Overview IB'!D33 -> 0 | E18: ='Overview IB'!E33 -> 0 | F18: ='Overview IB'!I33 -> 0 | G18: ='Overview IB'!J33 -> 0 | H18: ='Overview IB'!K33 -> 0 | I18: ='Overview IB'!L33 -> 0 | J18: ='Overview IB'!M33 -> 0 | K18: ='Overview IB'!N33 -> 0 | L18: ='Overview IB'!O33 -> 0 | M18: ='Overview IB'!P33 -> 0 | ... O18: ='Overview IB'!R33 -> 0 | Q18: =SUM(U18:AD18) -> 0 | S18: =IF(D18=0,0,IF(E18=0,IF(R18=0,Q18/D18,R18/D18),IF(R18=0,Q18/E18,R18/E18))) -> 0
C19: Anzahl der Kurs-, Workshop- bzw. Trainingsstunden | D19: ='Overview IB'!D34 -> 0 | E19: ='Overview IB'!E34 -> 0 | F19: ='Overview IB'!I34 -> 0 | G19: ='Overview IB'!J34 -> 0 | H19: ='Overview IB'!K34 -> 0 | I19: ='Overview IB'!L34 -> 0 | J19: ='Overview IB'!M34 -> 0 | K19: ='Overview IB'!N34 -> 0 | L19: ='Overview IB'!O34 -> 0 | M19: ='Overview IB'!P34 -> 0 | ... O19: ='Overview IB'!R34 -> 0 | Q19: =SUM(U19:AD19) -> 0 | S19: =IF(D19=0,0,IF(E19=0,IF(R19=0,Q19/D19,R19/D19),IF(R19=0,Q19/E19,R19/E19))) -> 0
C20: Bereich Beratung | D20: Anzahl SOLL | E20: Anzahl SOLL berichtigt | F20: M 1 | G20: M 2 | H20: M 3 | I20: M 4 | J20: M 5 | K20: M 6 | L20: M 7 | M20: M 8 | N20: M 9 | O20: M 10 | Q20: IST | R20: IST berichtigt | S20: Erfüllt in % | T20: Anmerkungen | U20: M 1 | V20: M 2 | W20: M 3 | X20: M 4 | Y20: M 5 | Z20: M 6 | AA20: M 7 | AB20: M 8 | AC20: M 9 | AD20: M 10
C21: Anzahl der Einzelberatungen bzw. -betreuung | D21: ='Overview IB'!D36 -> 0 | E21: ='Overview IB'!E36 -> 0 | F21: ='Overview IB'!I36 -> 0 | G21: ='Overview IB'!J36 -> 0 | H21: ='Overview IB'!K36 -> 0 | I21: ='Overview IB'!L36 -> 0 | J21: ='Overview IB'!M36 -> 0 | K21: ='Overview IB'!N36 -> 0 | L21: ='Overview IB'!O36 -> 0 | M21: ='Overview IB'!P36 -> 0 | ... O21: ='Overview IB'!R36 -> 0 | Q21: =SUM(U21:AD21) -> 0 | S21: =IF(D21=0,0,IF(E21=0,IF(R21=0,Q21/D21,R21/D21),IF(R21=0,Q21/E21,R21/E21))) -> 0
C22: Anzahl der in Einzelberatung beratenen, betreuten oder gecoachten Personen | D22: ='Overview IB'!D37 -> 144 | E22: ='Overview IB'!E37 -> 72 | F22: ='Overview IB'!I37 -> 72 | G22: ='Overview IB'!J37 -> 72 | H22: ='Overview IB'!K37 -> 0 | I22: ='Overview IB'!L37 -> 0 | J22: ='Overview IB'!M37 -> 0 | K22: ='Overview IB'!N37 -> 0 | L22: ='Overview IB'!O37 -> 0 | M22: ='Overview IB'!P37 -> 0 | ... O22: ='Overview IB'!R37 -> 0 | Q22: =SUM(U22:AD22) -> 148 | R22: 74 | S22: =IF(D22=0,0,IF(E22=0,IF(R22=0,Q22/D22,R22/D22),IF(R22=0,Q22/E22,R22/E22))) -> 1.0277778 | U22: 74 | V22: 74
C23: Anzahl der Einzelberatungs-/Betreuungs-/ Coachingstunden | D23: ='Overview IB'!D38 -> 1170 | E23: ='Overview IB'!E38 -> 1170 | F23: ='Overview IB'!I38 -> 360 | G23: ='Overview IB'!J38 -> 810 | H23: ='Overview IB'!K38 -> 0 | I23: ='Overview IB'!L38 -> 0 | J23: ='Overview IB'!M38 -> 0 | K23: ='Overview IB'!N38 -> 0 | L23: ='Overview IB'!O38 -> 0 | M23: ='Overview IB'!P38 -> 0 | ... O23: ='Overview IB'!R38 -> 0 | Q23: =SUM(U23:AD23) -> 952 | R23: 952 | S23: =IF(D23=0,0,IF(E23=0,IF(R23=0,Q23/D23,R23/D23),IF(R23=0,Q23/E23,R23/E23))) -> 0.81367521 | U23: 288.5 | V23: 663.5
C24: Anzahl der Gruppenberatungen bzw. -betreuung (min 3 Personen) | D24: ='Overview IB'!D39 -> 0 | E24: ='Overview IB'!E39 -> 0 | F24: ='Overview IB'!I39 -> 0 | G24: ='Overview IB'!J39 -> 0 | H24: ='Overview IB'!K39 -> 0 | I24: ='Overview IB'!L39 -> 0 | J24: ='Overview IB'!M39 -> 0 | K24: ='Overview IB'!N39 -> 0 | L24: ='Overview IB'!O39 -> 0 | M24: ='Overview IB'!P39 -> 0 | ... O24: ='Overview IB'!R39 -> 0 | Q24: =SUM(U24:AD24) -> 0 | S24: =IF(D24=0,0,IF(E24=0,IF(R24=0,Q24/D24,R24/D24),IF(R24=0,Q24/E24,R24/E24))) -> 0
C25: Anzahl der in Gruppenberatung beratenen oder betreuten Personen | D25: ='Overview IB'!D40 -> 50 | E25: ='Overview IB'!E40 -> 50 | F25: ='Overview IB'!I40 -> 0 | G25: ='Overview IB'!J40 -> 0 | H25: ='Overview IB'!K40 -> 50 | I25: ='Overview IB'!L40 -> 0 | J25: ='Overview IB'!M40 -> 0 | K25: ='Overview IB'!N40 -> 0 | L25: ='Overview IB'!O40 -> 0 | M25: ='Overview IB'!P40 -> 0 | ... O25: ='Overview IB'!R40 -> 0 | Q25: =SUM(U25:AD25) -> 46 | R25: 46 | S25: =IF(D25=0,0,IF(E25=0,IF(R25=0,Q25/D25,R25/D25),IF(R25=0,Q25/E25,R25/E25))) -> 0.92 | W25: 46
C26: Anzahl der Gruppenberatungs-/Betreuungsstunden | D26: ='Overview IB'!D41 -> 540 | E26: ='Overview IB'!E41 -> 540 | F26: ='Overview IB'!I41 -> 0 | G26: ='Overview IB'!J41 -> 0 | H26: ='Overview IB'!K41 -> 540 | I26: ='Overview IB'!L41 -> 0 | J26: ='Overview IB'!M41 -> 0 | K26: ='Overview IB'!N41 -> 0 | L26: ='Overview IB'!O41 -> 0 | M26: ='Overview IB'!P41 -> 0 | ... O26: ='Overview IB'!R41 -> 0 | Q26: =SUM(U26:AD26) -> 435.5 | R26: 435.5 | S26: =IF(D26=0,0,IF(E26=0,IF(R26=0,Q26/D26,R26/D26),IF(R26=0,Q26/E26,R26/E26))) -> 0.80648148 | W26: 435.5
C27: Anzahl der Familienberatungen (pro Familie) | D27: ='Overview IB'!D42 -> 0 | E27: ='Overview IB'!E42 -> 0 | F27: ='Overview IB'!I42 -> 0 | G27: ='Overview IB'!J42 -> 0 | H27: ='Overview IB'!K42 -> 0 | I27: ='Overview IB'!L42 -> 0 | J27: ='Overview IB'!M42 -> 0 | K27: ='Overview IB'!N42 -> 0 | L27: ='Overview IB'!O42 -> 0 | M27: ='Overview IB'!P42 -> 0 | ... O27: ='Overview IB'!R42 -> 0 | Q27: =SUM(U27:AD27) -> 0 | S27: =IF(D27=0,0,IF(E27=0,IF(R27=0,Q27/D27,R27/D27),IF(R27=0,Q27/E27,R27/E27))) -> 0
