Workbook

Sheet 2019
A1: Gesamtübersicht Integrationsprojekte 2019
A2: Topf | B2: Projektträger | C2: Projektname | D2: FSWP | E2: Kurzbeschreibung | F2: Bundesland(e) | G2: AMIF-Mittel 2019 | H2: BKA-Mittel 2019 | I2: Gesamt 2019
A3: AMIF | B3: Berufsförderungsinstitut Oberösterreich (bfi OÖ) | C3: MESO - Bildungsmaßnahmen für Drittstaatsangehörige in Oberösterreich | D3: Deutsch | E3: Meso verfolgt das Ziel einer Verbesserung der Sprachkompetenz in Deutsch. Dazu werden Sprachfördermaßnahmen auf verschiedensten Levels zielgruppenspezifisch, kompetenzorientiert in ganz Oberösterreich angeboten. Ein Alphabetisierungskurs arbeitet mit der Methode der funktionalen Alphabetisierung bei gleichzeitiger Vermittlung von Deutschkenntnissen. Im Kontext der Sprachvermittlung werden kulturelle und gesellschaftsrelevante Inhalte (ua. das Modul Länderkunde) bearbeitet und auf die Erweiterung und (Re)aktivierung von Selbstkompetenzen besonderer Wert gelegt. Die Vorbereitung zur Integration in den Arbeitsmarkt setzt Bildungs- und Ausbildungsberatung, Berufsorientierung und Bewerbungstraining in den Mittelpunkt des zweiten Maßnahmenschwerpunkts. Weitere Module: Connecting People (Kommunikation mit „autochthonen“ ÖsterreicherInnen), Radfahrschule( Erhöhung von Mobilität ), IKT-Basics | F3: OÖ | G3: 135000 | H3: 45000 | I3: 180000
A4: AMIF | B4: Caritas Akademie der Diözese Graz-Seckau | C4: Spracherwerbsmaßnahmen in der Steiermark II | D4: Deutsch | E4: Das Projekt SEM II bietet ein auf den Bedarf der Zielgruppe des AMIF abgestimmtes Angebot für den Spracherwerb in Deutsch, welches auch den regionalen Anforderungen in der Steiermark Rechnung trägt. Um das Sprachniveau der Zielgruppe in der Steiermark nachhaltig zu entwickeln und zu verbessern, legt das vorliegende Projekt alles daran, nicht nur unter Einhaltung sämtlicher Qualitätsstandards für einen gehaltvollen, erwachsenengerechten und motivierenden Unterricht zu sorgen, sondern auch einen Beitrag im Sinne der regionalen Ausgewogenheit von Deutschkursangeboten in der Steiermark zu leisten. In Abstimmung auf Sonderinitiativen öffentlicher Stellen als Reaktion auf den gestiegenen Bedarf an Spracherwerbsmaßnahmen, hat dieses Projekt neben der grundsätzlichen Bedarfsorientierung einen Schwerpunkt auf Kursangeboten zu gehobenen Sprachniveaus wie B1, B2 und C1. | F4: ST | G4: 234702.75 | H4: 78234.25 | I4: 312937
A5: AMIF | B5: Peregrina - Bildungs-, Beratungs- und Therapiezentrum für Immigrantinnen | C5: Deutsch zum Mitnehmen und Anknüpfen | D5: Deutsch | E5: "Deutsch zum Mitnehmen und Anknüpfen" ist ein Sprachprojekt für Migrantinnen mit zumeist qualifizierten Berufsausbildungen, die ihre Deutschkenntnisse zwecks Weiterbildung und Vorbereitung auf einen erneuten Berufseinstieg verbessern wollen. Angeboten werden im Projektzeitraum acht Deutschkurse auf den Sprachniveaus B1 und B2, wobei vorgesehen ist, dass ein Teil der Teilnehmerinnen aufbauend beide Stufen absolviert. In die Kursmaßnahmen integriert sind die Module "Soziokulturelles Lernen" und "Bildung und Orientierung". Somit sollen die sprachlichen (ÖSD-B1 bzw. B2-Prüfung) und soziokulturellen Aspekte der Integration gefördert und die Teilnehmerinnen beim Finden und Setzen von realistischen Bildungszielen unterstützt werden. Am Kursende verfügen sie über Kompetenzen zur Herstellung sozialer Kontakte sowie über umfassende Orientierung zu Angeboten der Erwachsenenbildung in Österreich. | F5: W | G5: 58125 | H5: 19375 | I5: 77500
A6: AMIF | B6: Caritas der Diözese Graz-Seckau | C6: Lerncafés Steiermark - Graz(Gries), Leoben, Knittelfeld, Leibnitz, Mürzzuschlag | D6: Kinder, Jugendliche und Elternarbeit | E6: Lerncafés Steiermark sind von Mo-Do (Fr) jeweils von 13-17Uhr geöffnet und stellen ein kostenloses Lern- und Nachmittagsangebot für die Zielgruppe dar.Die Hauptaufgabe besteht darin, den PflichtschülerInnen Unterstützung und Hilfestellung beim Bewältigen der schulischen Pflichten zu geben und die Deutschkompetenz zu stärken.Über den Pflichtschulabschluss hinaus eine weiterführende Bildungskarriere einzuschlagen ist Hauptziel.Eltern,Interessierte werden gezielt zu Werten,Pflichten und Aufgaben informiert und mit kommunalen Vertretern gezielt Möglichkeiten zur Partizipation und Teilhabe im dialogischen Austausch geschaffen.Lerncafés fördern die TeilnehmerInnen auch gezielt im Sinne des Anti Bias Ansatz und wirken so gezielt gegen Radikalisierung und Rassismus. | F6: ST | G6: 102750 | H6: 34250 | I6: 137000
A7: NAT | B7: Verein SprachBrücke Betriebsgesellschaft GmbH | C7: Deutsch im Alltag | D7: Deutsch | E7: DEUTSCH IM ALLTAG ist ein international erfolgreiches, wissensbasiertes Programm zur frühen Bildungsförderung in Familien mit Migrationserfahrung. Es zielt darauf ab, die Entwicklungsmöglichkeiten von Kindern frühzeitig und nachhaltig zu verbessern. Zielgruppe sind sozial- und bildungsbenachteiligte Familien mit Kindern im Alter von 3 bis 7 Jahren. In aufsuchender Familienarbeit durch muttersprachliche Hausbesucherinnen werden innerfamiliäre Bildungsaktivitäten auf spielerische Weise angeregt und vertieft und die Kinder auf den Schulbesuch vorbereitet. Durch begleitende Gruppentreffen und Exkursionen im sozialen Umfeld werden Kultur, Werte und Lebensweisen der Aufnahmegesellschaft vermittelt. Die Bildungssensibilisierung der gesamten Familie und die Verbesserung der sozialen Integration stellen einen wichtigen Beitrag zur Chancengerechtigkeit für Familien mit Migrationserfahrung dar. | F7: Steiermark | H7: 421422 | I7: 421422
A8: NAT | B8: Jugendzentrum Bunterhaufen | C8: YouthConnect – Jugendliche gestalten Integration | D8: Arbeitsmarkt | E8: Das Projekt YOUTHCONNECT versteht sich als sozialpädagogisches Projekt für Kinder und Jugendliche sowie als Plattform für Sportintegration. Es setzt sich zum Ziel, das sozialintegrative Potential des Sports in seiner gesamten Bandbreite zu nützen, und somit die Integration der Zielgruppe entscheidend voranzutreiben. KlientInnen können an den regelmäßig stattfindenden Sport- und Sprachförderungs-Modulen, an Sportveranstaltungen, dem Lern- und Sportprogramm GRAgustl, an beruflichen Qualifizierungsangeboten sowie Adventuretagen und Sportfesten teilnehmen, Workshops absolvieren, ehrenamtlich mitarbeiten oder auch Mitglied in einem der YOUTHCONNECTPartnervereine werden. Das Angebot von YOUTHCONNECT ist aufbauend und interdisziplinär und in vier Kernbereiche untergliedert: Sport+Teilnahme, + Teilhabe, + Bildung und Öffentlichkeitsarbeit. | F8: Steiermark | H8: 232142 | I8: 232142
A9: NAT | B9: Kulturverein Brücken Bauen | C9: Begegnungsräume – Kultur verbindet | D9: Gemeinde und Identität | E9: Das Projekt Begegnungsräume - Dialog und Integration" zielt auf die Verbesserung der Integration und des positiven Miteinanders von neu Zugewanderten und der Wohnbevölkerung in Gemeinden im ländlichen Raum im Pongau, Pinzgau und Lungau ab. Integration versteht sich als chancengleiche Teilnahme am sozialen und gesellschaftlichen Leben und soll wechselseitig (Zugezogene und autochthone Wohnbevölkerung) erfolgen. Innovativ in diesem Projekt sind die intensive regionale Vernetzungsarbeit und Bündelung lokaler und ehrenamtlicher Intiativen. Angebote und Maßnahmen im Integrationsbereich sollen attraktiv, überschaubar, punktuell, aber auch effizient und ergänzend gestaltet werden. Sie richten sich gleichermaßen an alle Bürger*innen einer Gemeinde. Durch Beratungsgespräche mit wichtigen Akteur*innen in den Projektgemeinden kann bedarfsorientiert mit Angeboten reagiert werden. | F9: Salzburg | H9: 80000 | I9: 80000
A10: AMIF | B10: Österreichische Jungarbeiterbewegung - Berufspädagogisches Institut der ÖJAB | C10: uBUNTu 2 – Ich bin, weil Wir sind. Sprachkompetenz - Bildungsvorbereitung - Ori-entierung - Integration: Fit mit Sprache und Basiskompetenzen. Mein Schlüssel zu Integration und Erfolg | D10: Deutsch | E10: Im Projekt uBUNTu 2 erhalten junge Erwachsene aus Drittstaaten mit längerfristiger Aufenthaltsperspektive aber geringen Deutschkenntnissen und Bildungserfahrung eine umfassende Basisbildung, die die Deutschsprachkompetenz und die Orientierung in Österreich in den Fokus rückt. Parallel dazu werden Kompetenzen trainiert, die wesentlich sind, um an weiteren Bildungsmaßnahmen teilnehmen zu können. Dazu zählen Berufsorientierung, EDV, Werteschulung und weitere Bereiche. Es werden insgesamt 9 Deutschkurse inkl. Berufsorientierung und Werteschulung (6xA2 und 3xB1) angeboten welche durch eine sozialpädagogische Begleitung und Einzelcoaching ergänzt werden. Am Ende der Projektlaufzeit haben die TeilnehmerInnen so die sprachlichen Voraussetzungen für eine Weiterbildung erreicht, sie sind Berufs- und Werteorientiert und damit in der Lage an eine weiterführende Bildungsmaßnahme vermittelt zu werden. | F10: W | G10: 122483.92 | H10: 40827.975 | I10: 163311.9
A11: AMIF | B11: DANAIDA - Bildung und Treffpunkt für Frauen | C11: Alphabetisierung und Zweitschrifterwerb für Frauen | D11: Frauen | E11: Im Projekt "Alphabetisierung für Frauen" sind zwei Angebote geplant: Alphabetisierungs- und Zweitschriftkurse zur Vorbereitung auf den Besuch eines Standarddeutschkurses. In allen Kursen findet begleitende Beratung statt, parallel zu den Kursen wird Kinderbetreuung angeboten. Die Kursinhalte orientieren sich an den Vorkenntnissen, Interessen und am Alltag der Teilnehmerinnen und sollen neben Lesen und Schreiben auch DaZ-Kenntnisse im mündlichen und schriftlichen Bereich vermitteln und festigen, aber auch Mathematik und Informationen zu Sachthemen. In allen Kursen werden Computer und Tablets eingesetzt, um die Teilnehmerinnen mit neuen Technologien vertraut zu machen und ihnen Möglichkeiten des Einsatzes von IKT zum (selbstständigen) Lernen aufzuzeigen. In allen Kursen wird auch außerhalb des Kursraums gelernt, bei Exkursionen und in direkter Kommunikation mit deutschsprachigen Personen. | F11: ST | G11: 52452 | H11: 17484 | I11: 69936
A12: AMIF | B12: Die Wiener Volkshochschulen GmbH | C12: Bildungscoaching und berufsbezogenes Deutsch für Drittstaatsangehörige, Asylberechtigte und subsidiär Schutzberechtigte bis 25 | D12: Deutsch | E12: Drittstaatsangehörige, Asylberechtigte und subsidiär Schutzberechtigte von 19 bis 25 Jahren, die eine Maßnahme der Basisbildung, des erwachsenengerechten Pflichtschulabschlusses, eine NEBA-Maßnahme oder das Jugendcollege besuchen oder abgeschlossen haben bzw. über eine Clearings- und Beratungsstelle zugewiesen werden und Begleitung bei der Erweiterung ihrer sprachl. und persönl. Kompetenzen benötigen, um im österr. (Aus-)Bildungssystem bzw. am Arbeitsmarkt Fuß zu fassen, sollen durch individuelles Bildungscoaching, einem darin erstellten individuellen Bildungsplan u. sich daraus ergebenden Kursbesuchen ihre bildungs- und berufssprachlichen Kompetenzen erweitern und eine damit verbundene ausbildungsbezogene bzw. berufliche Orientierung erhalten, sodass der Besuch einer weiterführenden Schule oder die Integration in den Arbeitsmarkt wahrscheinlicher gelingt. | F12: W | G12: 57654 | H12: 19218 | I12: 76872
A13: AMIF | B13: Einstieg - Einstieg ins Berufsleben GmbH | C13: Integrationskurs Deutsch zur Vorbereitung für Bildungsmaßnahmen | D13: Deutsch | E13: Für TeilnehmerInnen aus der beschriebenen Zielgruppe ist eine Integration in einen Externisten- Pflichtschulabschlusskurs, eine höhere Schule oder eine sonstige Bildungsmaßnahme (Berufsschule, Qualifizierungsmaßnahme, Studium) oft nicht möglich, da hierfür die Sprach- und Bildungsdefizite noch zu gross sind. Ziel und Nutzen dieser Bildungsmaßnahme ist es hier ein Ergänzungsangebot zu stellen, um • die Teilnahme an Externisten-Pflichtschulabschlusskursen zu ermöglichen • die Voraussetzungen für weiterführende Schulen zu ermöglichen • die Teilnahme an Berufsschulbesuchen zu ermöglichen • die Verbesserung der Deutschkenntnisse für berufliche (Qualifizierungs-) Maßnahmen zu schaffen | F13: S | G13: 142057.12 | H13: 47352.375 | I13: 189409.5
A14: AMIF | B14: Kärntner Berufsförderungsinstitut GmbH | C14: SpracheInklusive | D14: Deutsch | E14: Durch dieses Projekt erhalten Drittsaatsangehörige einen Sprachkurs mit interkulturellen, gesellschafts- und arbeitsmarktpolitischen Schwerpunkten, wodurch die Integration in Österreich nachhaltig unterstützt werden soll. Nach einem Einstufungsverfahren besteht die Möglichkeit - je nach vorhandenem Sprachniveau - ein ÖSD/ÖIF Sprachzertifikat A1 oder A2 zu erlangen. Zusätzlich erhalten die Teilnehmer/innen kompetenz- und biographieorientierte Beratung, welche bei Nostrifizierungsangelegenheiten, Bildungs- und Berufsberatung sowie der Darlegung von formellen und informellen Kompetenzen mit Hilfe eines Profilpasses unterstützend wirken soll. Insgesamt werden 10 Kurse angeboten. | F14: K | G14: 95625 | H14: 31875 | I14: 127500
A15: AMIF | B15: Bildungs- und Beratungseinrichtung Frauen aus allen Ländern | C15: Hier lebe ich, hier lerne ich. Deutschkursangebote für Frauen aus Drittstaaten in Tirol. | D15: Deutsch | E15: Mit dem Projekt hat sich die Bildungs- und Beratungseinrichtung Frauen aus allen Ländern das Ziel gesetzt, mit Kursangeboten in verschiedenen Formaten jene Frauen zu erreichen, die sonst - aus unterschiedlichen Gründen - herkömmliche Bildungs- und Integrationsangebote nicht nutzen können. Im Projektzeitraum werden in geschlechtshomogenen Gruppen mit ressourcen- und alltagsbezogenen Ansätzen Kurse auf unterschiedlichen Niveaustufen einerseits in Innsbruck, andererseits in Landeck im Tiroler Oberland angeboten. Parallel dazu findet an beiden Orten wöchentlich ein freier Lernnachmittag statt. Dazu gibt es eine kostenlose und professionelle Kinderbetreuung sowie vielseitige Zusatzangebote. In der Leitung und Durchführung ebensolcher Projekte blickt Frauen aus allen Ländern auf langjährige Erfahrung und mehrjährige Professionalisierung zurück. | F15: T | G15: 64075.875 | H15: 21358.625 | I15: 85434.5
A16: AMIF | B16: ISOP - Innovative Sozialprojekte GmbH | C16: Deutschoffensive zur Förderung der kommunalen Integration im Bezirk Südoststeiermark | D16: Deutsch | E16: In Feldbach bzw. im Bezirk Südoststeiermark lebenden Asylberechtigten, subsidiär Schutzberechtigten und Drittstaatsangehörigen sollen bedarfsorientiert Deutschkurse & Lernbetreung angeboten werden. Schulungsort ist nicht nur der traditionelle Kursraum, sondern auch der kommunale Lebensraum. Zielgruppen sind Vorschul- und Schulkinder, denen auf spielerischer Basis bzw. schulgerecht deutsch vermittelt wird. Für Erwachsene werden Kurse für bildungsferne und für besser gebildete Personen angeboten, die mit einem anerkannten Zertifikat abgeschlossen werden sollen. Elternbildung und der Vermittlung von Werten kommt eine besondere Bedeutung zu. Alle Kurse werden von fachlich qualifizierten Personen mit langjähriger Berufserfahrung geleitet. Die Herausforderung des Projektes besteht darin, dass auf sehr unterschiedliche Bedarfe durch ein maßgeschneidertes Kursprogramm reagiert wird. | F16: ST | G16: 91746 | H16: 30582 | I16: 122328
A17: AMIF | B17: Hilfswerk Niederösterreich Betriebs GmbH | C17: Integrativer Lernclub | D17: Kinder, Jugendliche und Elternarbeit | E17: Der Integrative Lernclub für schulpflichtige Drittstaatsangehörige, insbesondere Asylberechtigte und Subsidiär Schutzberechtigte soll die Integration der Kinder in Österreich erleichtern und dadurch bestmögliche Ausgangsbedingungen für eine erfolgreiche persönliche, soziale und berufliche Zukunft schaffen. Die Behebung des Sprachdefizits ist hier nicht ausreichend, vielmehr sind auch die Kultur, Religion, Werthaltungen sowie der persönliche Hintergrund und die Muttersprache des Kindes im Rahmen einer interkulturellen Erziehung zu berücksichtigen. Betreuungsziele sind daher die Verbesserung der Kenntnisse der deutschen Sprache, Ausgleich bereits entstandener schulischer Defizite, Erlernen sozialer Kompetenzen, Förderung der Selbständigkeit sowie die Vermittlung kultureller Werte. Die Betreuung erfolgt längerfristig 2 x pro Woche je 2 Stunden in Kleingruppen von max. 8 Kindern. | F17: NÖ | G17: 53432.662 | H17: 17810.888 | I17: 71243.55
A18: AMIF | B18: CONCORDIA Verein für Sozialprojekte | C18: CONCORDIA Lern- und Familienzentrum LenZ" Familienorientierte Integrationsbegleitung | D18: Kinder, Jugendliche und Elternarbeit | E18: Das CONCORDIA Lern- und Familienzentrum LenZ bietet ab Jänner 2017 kostenlose Bildungs- und Beratungsangebote für Kinder und Jugendliche sowie deren Eltern: Gerade Familien mit Migrations- und Fluchterfahrung benötigen individuelle und punktgenaue Unterstützung. Im Rahmen der Lernbegleitung erhalten die Kinder und Jugendlichen die Möglichkeit, ihre Sprachkenntnisse kontinuierlich zu festigen und werden Schritt für Schritt an die Bewältigung ihrer schulischen Aufgaben herangeführt. Ziel ist, die Talente der Kinder und Jugendlichen zu fördern und ihre Potenziale nachhaltig zu stärken, um ihnen optimale Perspektiven auf ihrem weiteren Bildungsweg zu eröffnen. Die Einbindung der Eltern in Form von Elternbildungs- und Beratungsangeboten ist dabei zentral und erleichtert die Orientierung im neuen Umfeld. Bei der Umsetzung des Projektes setzt CONCORDIA großteils auf Freiwillige. | F18: W | G18: 70000 | I18: 70000
A19: AMIF | B19: Österreichische Jungarbeiterbewegung - Berufspädagogisches Institut der ÖJAB | C19: MQA 2 – Modulare Qualifizierung und Aktivierung für Drittstaatsangehörige, Asylbe-rechtigte und subsidiär Schutzberechtigte | D19: Arbeitsmarkt | E19: Im Rahmen des Projektes wird Drittstaatsangehörigen, Asylberechtigten und subsidiär Schutzberechtigten durch verbesserte Sprachkompetenz und dem Erwerb eines ÖSD Diploms sowie einer europaweit anerkannten Fachqualifizierung (LAP Bürokaufmann/-frau) eine sichere Arbeitsmarktintegration in Österreich ermöglicht. Es werden insgesamt 3 Kurse inkl. Deutschunterricht mit je 24 TeilnehmerInnen angeboten. Das Projekt richtet sich ausschließlich an arbeitssuchende, motivierte und lernwillige Erwachsene Personen mit geringen Deutschkenntnissen. Es wird versucht den Frauenanteil der TeilnehmerInnen auf über 75% zu bringen. Während der Fachausbildung sind auch Praktikumstage inkludiert. Die Notwendigkeit dieses Projektes beruht auf der Tatsache, dass es für diese Zielgruppe kein vergleichbares Angebot gibt. Während der gesamten Projektlaufzeit unterstützen wir die Lösung von persönlichen Problemen der TeilnehmerInnen. | F19: NÖ, W | G19: 76801.868 | H19: 25600.623 | I19: 102402.49
A20: AMIF | B20: Berufsförderungsinstitut Oberösterreich (bfi OÖ) | C20: Fachwerkstatt04 - ein Projekt zur arbeitsmarktnahen Qualifizierung | D20: Arbeitsmarkt | E20: Das Projekt Fachwerkstatt04 beinhaltet eine (Vor-) Qualifizierung für unterschiedliche Segmente am Arbeitsmarkt: Gesundheitsberufe, Ausbildungsbegleitung Fachsozialbetreuer, Metall, Gastronomie und Baunebengewerbe. Das Hauptaugenmerk der inhaltlichen Ausgestaltung der Lehrgänge liegt in der Fachqualifizierung und in der fachsprachlichen Förderung. IKT und Kommunikation sowie Förderung der interkulturellen Kompetenzlagen und out-going Maßnahmen wie Bewerbungstraining und Vermittlungsunterstützung sind Module, die je nach Lehrgang additive Bestandteile darstellen. Die Lehrgänge sind mit einem praktischen Ausbildungsteil und einem zu absolvierendem Praktikum im zukünftigen Berufsfeld verbunden. Die Ausbildungsbegleitung unterstützt Personen der Zielgruppe parallel zur weiterführenden Qualifizierung im Gesundheitsbereich in Form von Fachsprachtraining, Lern- und Prüfungsvorbereitung. | F20: OÖ | G20: 15862.5 | H20: 5287.5 | I20: 21150
A21: AMIF | B21: BFI Tirol Bildungs GmbH | C21: Pole Position - Startklar für den Arbeitsmarkt | D21: Arbeitsmarkt | E21: Die berufliche Integration von Drittstaatsangehörigen in den Tiroler Arbeitsmarkt soll durch sprachliche und fachliche Qualifizierungen über das Projekt Pole Position für die Zielgruppe (Drittstaatsangehörige nach NAG sowie anerkannte Flüchtlinge und subsidiär Schutzberechtigte mit längerfristiger Aufenthaltsperspektive) erleichtert werden. Durch arbeitsmarktrelevante fachspezifische Sprachkurse und Qualifizierungsmaßnahmen in den Bereichen "Orientierung, Perspektiven und Kommunikation", "Vorbereitung für Matura und Studium", "Pflege", "Gastronomie", "gewerblich-technische Berufe" und "Verkauf" soll den Teilnehmer/innen eine nachhaltige Befähigung zur Arbeitsmarktintegration zukommen. Dadurch wird der Zielgruppe zu einem selbstständigen Leben in Österreich verholfen. | F21: T | G21: 124612.5 | H21: 41537.5 | I21: 166150
A22: AMIF | B22: Caritas der Erzdiözese Wien - Hilfe in Not | C22: Quantensprung II - Modulare Qualifizierung und Arbeitsmarktintegration von Asylberechtigten und subsidiär Schutzberechtigten | D22: Arbeitsmarkt | E22: Das Projekt Quantensprung II hat die Verbesserung des nachhaltigen Zugangs für die TeilnehmerInnen zum Arbeitsmarkt zum Ziel. Angesetzt wird an identifizierten Hürden, welche die systematische Benachteiligung der Zielgruppenangehörigen am Arbeitsmarkt bedingen. Eine Reihe ineinandergreifender Maßnahmen werden bedarfsgerecht in modular kombinierbarer Form angeboten, welche sich zu den folgenden Clustern zusammenfassen lassen: 1. Maßnahmen zur Vermittlung von Fachsprachkenntnissen, 2. Orientierungsmaßnahmen zu Bewerbungsverfahren und Abläufen in österreichischen Betrieben, 3. Maßnahmen zur Unterstützung bei dem Knüpfen relevanter Kontakte und dem Sammeln von Erfahrung in den angestrebten Berufssparten und 4. Qualifizierungsmaßnahmen im Berufsfeld Heimhilfe. | F22: W | G22: 130500 | H22: 43500 | I22: 174000
A23: AMIF | B23: ABZ*AUSTRIA - Verein zur Förderung von Arbeit, Bildung und Zukunft von Frauen | C23: abz*Handel(n) für Migrantinnen | D23: Frauen | E23: abz*Handel(n) für Migrantinnen verfolgt das Ziel die Erwerbsbeteiligung von drittstaatenangehörigen Migrantinnen, die über Deutschkenntnisse auf dem Niveau B1 verfügen, durch eine Arbeitsmarktvorbereitung im Bereich Handel (Fokus Online-Handel) zu erhöhen bzw. sie auf eine Höherqualifizierung für diesen Bereich (insbesondere das Absolvieren einer LAP) vorzubereiten. In Wien fehlen Angebote für Migrantinnen, die an Deutschkurse anschließen und auf eine Spezialisierung/Qualifizierung in einem bestimmten Berufsfeld vorbereiten. Das Projekt unterstützt die Frauen professionell und arbeitsmarktnahe durch die Umsetzung von drei Maßnahmen: 1. Arbeitsmarktvorbereitungskurse, 2. Einzelberatung in "offener" Beratung, 3. Veranstaltungen: "Lebende Bibliothek der Berufsperspektiven im Handel" und „Roll&fly“. | F23: W | G23: 53804.25 | H23: 17934.75 | I23: 71739
A24: AMIF | B24: Kärntner Berufsförderungsinstitut GmbH | C24: SprachPflege – Intensivvorbereitung für den Pflege- und Betreuungsbereich | D24: Arbeitsmarkt | E24: SprachPflege ist eine Maßnahme für Drittstaatsangehörige, subsidiär schutzberechtigte und asylberechtigte Personen, welche diese durch einen Sprachkurs mit sozialen, kulturellen, gesellschafts- und arbeitsmarktpolitischen, gesundheitsrelevanten sowie persönlichkeitsbildenden Schwerpunkten auf die Ausbildung im Pflege- oder Betreuungsbereich vorbereiten soll. Am Ende der Maßnahme sollen die Personen sowohl sprachlich als auch persönlich soweit vorbereitet sein, um in die Pflegehelferausbildung oder eine andere weiterführende Ausbildung/Betreuung einzusteigen. Diese Ausbildung wurde entwickelt, da die Nachfrage an Personen im pflegenden Bereich, durch die Alterung der Gesellschaft, steigt und Personal mit Mehrsprachigkeit in den unterschiedlichsten Gesundheitseinrichtungen immer stärker benötigt wird. Durch dieses Projekt werden die Personen der Zielgruppe sprachlich sehr gut qualifiziert, wodurch sich deren Chancen auf berufliche Weiterqualifizierung und einen Einstieg in den Arbeitsmarkt erhöhen. | F24: K | G24: 94875 | H24: 31625 | I24: 126500
A25: AMIF | B25: alea + partner GmbH | C25: work stages | D25: Arbeitsmarkt | E25: Das Projekt „work stages“ („Arbeitsschritte") unterstützt anerkannte junge Flüchtlinge (15 - 25 Jahre) auf dem Weg in die Arbeitswelt. Ziel ist die Vorbereitung und nachhaltige Integration in den Arbeitsmarkt bzw. die berufliche Ausbildung. Orientierung und Zielearbeit schaffen konkrete Perspektiven, bedarfsgerechte Bildungs- und Beratungsangebote sichern den Erwerb arbeitsplatzrelevanter Handlungskompetenz. Individuell gestaltete, strukturierte, gesteuerte Integrationsprozesse, die von einem Integrations-Coach verantwortet werden, sichern die Einbindung aller relevanten AkteurInnen sowie zielgerichtete, konsistente Teilprozesse ohne Leerläufe und Redundanzen. Die aktive Einbindung regionaler Betriebe und das Management der Übergänge in die Arbeitswelt sichern über einen ausreichend langen Zeitraum (24 Monate) den Einstieg und den nachhaltigen Verbleib in der beruflichen Ausbildung. | F25: ST | G25: 81969 | H25: 27323 | I25: 109292
A26: AMIF | B26: MTOP Potential:Integration GmbH | C26: MORE THAN ONE PERSPECTIVE ganzheitliche Vorbereitung zum Arbeitsmarkteintritt und gezielte Arbeitsmarktvorbereitung für Asylberechtigte mit akademischem Abschluss | D26: Arbeitsmarkt | E26: Das MTOP associate program ist ein integratives Ausbildungsprogramm für geflüchtete Menschen mit akademischen Abschluss. Die TeilnehmerInnen werden ausgewählt, ausgebildet und mit potentiellen ArbeitgeberInnen vernetzt. Die MTOP associates werden auf die Integration im Unternehmen vorbereitet und im Prozess begleitet. Durch regelmäßige Feedbackgespräche wird das Ausbildungsprogramm stetig verbessert und die Schlüsselfaktoren für Arbeitsmarktintegration von Menschen mit Migrationshintergrund identifiziert. Diese Expertise sichert eine erfolgreiche Integrationsbegleitung bzw. Integrationsberatung von Unternehmen. | F26: W | G26: 52500 | H26: 17500 | I26: 70000
A27: AMIF | B27: Caritas der Diözese Graz-Seckau | C27: Mobile Integrationsbetreuung in der Steiermark XI | D27: Gemeinde und Identität | E27: Die „Mobile Integrationsbetreuung in der Steiermark“ ist die zentrale Anlaufstelle für Asylberechtigte und subsidiär Schutzberechtigte für den Start in ein selbstständiges Leben in der Frühphase nach Statuszuerkennung. Der mobile Betreuungsansatz ermöglicht die Abdeckung des Landesgebiets Steiermark. Der Schwerpunkt der Projektarbeit liegt beim Verzug vom organisierten Quartier in die erste Privatwohnung. Die Angebote des Projektes umfassen: *(Mobile) Betreuung, Beratung und Information *Hilfestellung bei der Schaffung von geeigneten Wohnraum (tw. finanzielle Unterstützung) *Suche nach Weiterbildungsmaßnahmen *Konversationsgruppen *Beratung zum Arbeitseinstieg * Kontakte mit Ämtern, Behörden und im persönlichen Umfeld *Wohnpatenschaften, Sprachtandems, Patentreffen und interkulturelle Besuche fördern den interkulturellen Dialog *Frauentreffs, Workshops vermitteln österreichische Werte | F27: ST | G27: 114375 | H27: 38125 | I27: 152500
A28: AMIF | B28: Caritas der Erzdiözese Wien - Hilfe in Not | C28: Treff.punkt Österreich - Integrationsprojekt für Asylberechtigte und subsidiär Schutzberechtigte in NÖ | D28: Deutsch | E28: Das Projekt unterstützt Asyl- und subs. Schutzberechtigte im östlichen NÖ auf ihrem Integrationsweg und besteht aus drei aufeinander abgestimmten Modulen, die eine aktive Teilhabe am gesellschaftlichen, wirtschaftlichen und kulturellen Leben in Österreich ermöglichen sollen. Im Zentrum steht eine umfassende Beratung/Begleitung (u.a. Frauen-, Integrations- und Wohnberatung). Das Modul Spracherwerb bietet • Deutsch-Integrationskurse mit Kinderbetreuung • Flexibles Kursmodulsystem • Möglichkeit der Absolvierung zertifizierter ÖSD-Prüfungen Das Modul Arbeitsmarkttintegration soll bei der Vorbereitung auf den Arbeitsmarkt und den Einstieg in Berufssparten mit Nachfrage (Zusammenarbeit mit AMS NÖ) unterstützen. KlientInnen werden unterstützt durch • (Fach-)Sprachkurse und Höherqualifizierung B1 • Begleitung und Nachbetreuung durch Einzelcoaching • Arbeitstraining und Praxisprojekte | F28: NÖ | G28: 270000 | H28: 90000 | I28: 360000
A29: AMIF | B29: Volkshilfe Flüchtlings- und MigrantInnenbetreuung GmbH | C29: SI – Starthilfe zur Integration von Asylberechtigten und subsidiär Schutzberechtigten in Oberösterreich | D29: Gemeinde und Identität | E29: Das Projekt „SI – Starthilfe zur Integration“ richtet sich an Asylberechtigte und subsidiär Schutzberechtigten in den Bezirken: Braunau, Freistadt, Gmunden/Bad Ischl, Linz, Linz-Land, Perg, Rohrbach, Urfahr-Umgebung und Vöcklabruck. Ziel des Projektes ist eine chancengleiche Teilhabe in der Gesellschaft durch wirtschaftliche, individuelle und soziale Eingliederung von Asylberechtigten und subsidiär Schutzberechtigten zu erreichen. Dies soll mit dem Angebot und Umsetzung der Projektmaßnahmen erreicht werden. Das Projekt setzt dabei Schwerpunkte auf fünf Bereiche (Wohnen, Bildung, Arbeit, Soziale Sicherheit und interkulturelle Kompetenz) sowie zwei Querschnittsthematiken (Frauen und Bedürfnisse von vulnerablen Personen). Die im Projekt „SI – Starthilfe zur Integration“ angebotenen Beratungen und Betreuungen sind bedarfsorientiert, mehrsprachig, ganzheitlich und daher nachhaltig. | F29: OÖ | G29: 270254.25 | H29: 90084.75 | I29: 360339
A30: AMIF | B30: Diakonie - Flüchtlingsdienst gemeinnützige GmbH | C30: Integrations- und Bildungszentren Salzburg | D30: Deutsch | E30: Das IBZ Salzburg leistet prozesshafte und bedarfsorientierte Starthilfe zur Integration von Flüchtlingen direkt ab Zuerkennung von Asyl oder subsidiärem Schutz. Die Leistungen des Beratungsteams beinhalten Wohnungsplatzvermittlung und -beratung, Angebot von Deutschkursen im Integrationshaus und Sprachclearing zur besseren Vermittlung zu relevanten Sprachkursen, sozial-psychologische Beratung und Unterstützung bei der Integration am Arbeitsmarkt. Die Beratung ist an die Bedürfnisse, Ressourcen und Defizite der KlientInnen abgestimmt und erfasst alle Lebensbereiche. Im individuellen Rhythmus erreichen die TeilnehmerInnen Schritt für Schritt die Meilensteine ihrer Integrationsplanung und schaffen die Grundlagen für ihre wirtschaftliche, soziale, kulturelle und gesellschaftliche Gleichberechtigung. | F30: S | G30: 267272.62 | H30: 89090.875 | I30: 356363.5
... A38: AMIF | B38: Österreichisches Rotes Kreuz | C38: crosstalk | D38: Gemeinde und Identität | E38: Crosstalk ermöglicht und begleitet Gespräche über kulturelle Grenzen hinweg und stellt damit das Verbindende vor das Trennende. Im Rahmen des Projektes werden Begegnungen zwischen Drittstaatsangehörigen und Mitgliedern der österreichischen Bevölkerung initiiert und begleitet mit dem Ziel, Ängsten zu begegnen und das friedliche Zusammenleben zu fördern. Es werden drei Arten von Begegnungen angeboten: 1) Welcome Talks, bei denen ein Crosstalk-Botschafter einen österreichischen Verein, eine Firma etc. in der Gemeinde besucht 2) Community Talks, bei denen ein Crosstalk-Botschafter einen migrantischen Verein (Kulturverein) etc. besucht 3) Smart Talks, das sind kleine Gesprächsrunden mit dem Bürgermeister der Gemeinde. Im Vordergrund steht jeweils die Person des Botschafters, Schwerpunktthemen sind darüber hinaus „Frauenbilder“, „Männerbilder“ und „Interreligiöser Austausch“. | F38: W, NÖ, OÖ, S, ST | G38: 105000 | H38: 35000 | I38: 140000
A39: AMIF | B39: Magistrat der Stadt Wels | C39: Neu in Wels?! | D39: Gemeinde und Identität | E39: Das Projekt widmet sich besonders den Asylberechtigten/subsidiär Schutzberechtigten, und hier besonders Personen, die BMS beziehen. Diese Personen sowie andere Drittstaatsangehörige und die angestammte Bevölkerung werden ebenso einbezogen. Das Projekt soll die Zielgruppe im Integrationsprozess unterstützen und fördern und ihnen das Ankommen in der Österr. Gesellschaft erleichtern. Meilensteine sind regelmäßige Beratung, Unterstützung im Spracherwerb und Orientierung in Wels sowie Vermittlung und Leben von Werten. Bei der Vermittlung von Werten wird die angestammte Bevölkerung über Dialogforen und Workshops (gemeinsamer Wertediskurs) eingebunden. Ein weiterer Meilenstein sind Buddy-Systeme für Freizeit, Sport und Ehrenamt. Kinder der Zielgruppe erfahren Unterstützung in der Schule beim Spracherwerb und Sprachkompetenz sowie bei der Vermittlung von Werten und sozialem Lernen. | F39: OÖ | G39: 70000 | I39: 70000
A40: AMIF | B40: Bundesanstalt Statistik Austria | C40: Österreichische Integrationsindikatorenberichte 2017, 2018 und 2019 | D40: Gemeinde und Identität | E40: In Fortsetzung des 2010 eingerichteten Integrationsmonitorings soll das Projekt die im NAP Integration definierten Indikatoren erheben, um gesicherte Aussagen über den Stand/ die Veränderung der Eingliederung von ZuwanderInnen zu ermöglichen. Es beinhaltet sowohl eine Zusammenstellung objektiv messbarer Indikatoren, wie beispielsweise Einkommen oder Haushaltsgröße, als auch Informationen über die subjektive Einschätzung, Wahrnehmung und Einstellung der zugewanderten Bevölkerung sowie der Mehrheitsbevölkerung zur Integration. Der Indikatorenbericht als Endprodukt des Projekts wird in einer Auflage von 10.000 Stück gedruckt und an Entscheidungsträger und Multiplikatoren in ganz Österreich verschickt sowie zusätzlich in Kooperation mit dem Österreichischen Integrationsfonds als Online-Version im Internet zugänglich gemacht. | F40: Gesamt Ö | G40: 108357.38 | H40: 36119.125 | I40: 144476.5
A41: AMIF | B41: Department für Migration und Globalisierung/ Donau-Universität Krems | C41: Dialogforum - Dialog zwischen Politik, Wissenschaft und Praxis | D41: Gemeinde und Identität | E41: Das Dialogforum ist eine Plattform des Dialogs und Wissensaustausches zwischen innerstaatlichen Akteuren (polit. Entscheidungsträger Bund/ Länder/ Gemeinden) im Migrations- und Integrationsbereich, (inter)nationalen ForscherInnen und zivilgesellschaftlicher Einrichtungen. Die Wissenschaft informiert über Forschungserkenntnisse zu Integration und Migration, in Ergänzung werden Projekte der Zivilgesellschaft miteinbezogen und die Vernetzung der TeilnehmerInnen mit interaktiven Maßnahmen unterstützt. Die Zusammenführung wissenschaftlicher Erkenntnisse und der Umsetzung in die Praxis sind zentrale Aspekte in der gemeinsamen Arbeit. Das Dialogforum als interaktive Plattform ermöglicht österr. Akteuren der Integrationspolitik ihre Erfahrungen und Fähigkeiten weiterzugeben und sich neue anzueignen (Capacity building). Dokumentation und Dissemination erfolgen durch Websites und Tagungsbände. | F41: NÖ | G41: 53625 | H41: 17875 | I41: 71500
A42: AMIF | B42: SPES GmbH - SPES Familien-Akademie | C42: Netzwerk - Integration von Familien mit Kindern | D42: Gemeinde und Identität | E42: Das Netzwerk – Integration von Familien mit Kindern hat zum Ziel, Familien aus Drittstaaten bzw. mit Asylberechtigung über Lotsen und Vernetzungsmaßnahmen auf mehreren Ebenen an die österreichische Gesellschaft heranzuführen. In 2 Lehrgängen werden jeweils 20 Lotsen für die Leitung interkultureller Eltern-Kind-Gruppen sowie für die Assistenz bei Vereinen und Initiativen ausgebildet. Sie fungieren als BrückenbauerInnen zwischen Familien aus Drittstaaten und Aufnahmegesellschaft. In 10 oö. Pilotgemeinden werden Mikro-Netzwerke aufgebaut, um familienrelevante, zivilgesellschaftliche Einrichtungen wie Eltern-Kind-Zentren, Vereine und öffentliche Leistungsträger zu vernetzen und sensibilisieren und so Unterstützungsnetzwerke für die Lotsen und die Familien zu schaffen. 7 Bezirksvernetzungstreffen und 1 Fachtagung dienen dem interkulturellen Kapazitätenaufbau und der regionalen Vernetzung. | F42: OÖ | G42: 53250 | H42: 17750 | I42: 71000
A43: AMIF | B43: Universität Wien - Postgraduate Center | C43: Universitätslehrgang Muslime in Europa | D43: Gemeinde und Identität | E43: Der Lehrgang befähigt die AbsolventInnen zur kompetenten und gegenwartsbezogenen Präsentation und Erläuterung islamischer Inhalte im europäischen Kontext. Durch diese spezielle Ausbildung werden die TeilnehmerInnen für ihre Tätigkeiten in den verschiedenen integrationsfördernden Institutionen, Moscheegemeinden und sozialen Einrichtungen in Österreich weitergebildet. Die AbsolventInnen können nach der Weiterbildung die Integration der muslimischen Minderheit gezielt fördern und aktiv als ExpertIn begleiten. Die TeilnehmerInnen werden mit genderspezifischen Fragestellungen, sowie der Geschichte und Entwicklung islamwissenschaftlicher Traditionen und Standpunkte vertraut gemacht. Neben fünf Pflichtmodulen ist zusätzlich ein Praktikum zu absolvieren, in dem die Herausforderungen des Zusammenlebens verschiedener Kulturen und Religionen im Vordergrund stehen. | F43: W | G43: 70000 | I43: 70000
A44: National | B44: Universität Graz, Institut für Katechetik und Religionspädagogik | C44: Integration durch interreligiöse Bildung III | D44: Kinder, Jugendliche und Elternarbeit | E44: Das dreijährige Projekt „Integration durch interreligiöse Bildung“ (2017-2020) hat zum Ziel, durch konkrete Bildungsinitiativen einen Beitrag zur Integration muslimischer SchülerInnen zu leisten. Aufbauend auf einer Ist-Stands-Analyse in Kärnten und in der Steiermark werden Qualitätsentwicklungsmaßnahmen für den Islamischen Religionsunterricht etabliert, die dem Anliegen dienen, im Unterricht einen aufgeklärten Islam europäischer Prägung zu vermitteln sowie Kinder und Jugendliche im Blick auf ihre religiösen Überzeugungen dialogfähig zu machen. Neben der Entwicklung und Durchführung eines Hochschullehrgangs für Islamische ReligionslehrerInnen werden im Rahmen des Projekts interreligiöse Unterrichtseinheiten erprobt und erforscht. Zusätzlich werden in einer juristischen Analyse die rechtlichen Rahmenbedingungen des schulischen islamischen Religionsunterrichts geprüft. | F44: ST, K | H44: 58598 | I44: 58598
A45: National | B45: Österreichisches Rotes Kreuz, Landesverband Salzburg | C45: Qualifizierungsmaßnahme für arbeitsmarktferne Menschen mit Migrationshintergrund im Bundesland Salzburg | D45: Arbeitsmarkt | E45: Eine rasche und erfolgreiche Arbeitsmarktintegration ist neben einer frühen und nachhaltigen Selbsterhaltungsfähigkeit der Zielgruppe für eine gelungene und langfristige Sozialintegration in die Österreichische Gesellschaft wichtig. Durch eine praxisnahe Ausbildung in den verschiedensten Aspekten der Gastronomie in Verbindung mit Fachdeutschkursen, wird den Teilnehmerinnen und Teilnehmern eine Basisqualifikation vermittelt, die sie später in den Bereichen der Gastronomie und Hotellerie, in denen zurzeit ein Arbeitskräftemangel herrscht, sinnvoll Nützen können. Weiters sollen die erworbenen Kenntnisse den Einstieg in weiterführende Schulungsmaßnahmen und eventuelle Lehrausbildungen im Bereich Gastronomie ermöglichen. So soll ein breites Spektrum an Möglichkeiten zur Nutzung von beruflichen Potenzialen eröffnet werden. | F45: S | H45: 73704 | I45: 73704
A46: National | B46: ASPIS - Psychosoziales Zentrum für Flüchtlinge und Opfer von Gewalt | C46: Integrationsinitiative Familie 2019: Ein Präventivprojekt mit Menschen aus Kriegs- und Krisengebieten | D46: Kinder, Jugendliche und Elternarbeit | E46: Wir haben in den letzten zweieinhalb Jahren Präventivarbeit gegen Radikalisierung durchführen können. Die von uns betreuten und beratenen Familien werden aufgesucht (kulturspezifischer, psychologischer Zugang). Für Kinder und Jugendliche werden wöchentliche Workshops und Sportbegegnungen angeboten. Weiters ist unser Fußballteam ein idealer Platz für Jugendliche und junge Männer um ihren Selbstwert zu stärken. Zusätzlich finden Familienausflüge statt um die jeweiligen Familiensysteme zu stärken. Die Themen, die wir bei den Besuchen zu bearbeiten haben, handeln von Kränkungen, Familie, Rechtssystem, Schule, Rechte der Frauen, Gesundheitssystem und vieles mehr. | F46: K | H46: 33200 | I46: 33200
A47: National | B47: Verein Impulse Krems | C47: Krems Interkulturell 2019 - Förderung von Begegnung, Sprache und Integration im Alltag - Schwerpunkt | D47: Kinder, Jugendliche und Elternarbeit | E47: Krems Interkulturell ist eine Informations-, Förder- und Koordinationsstelle sowie Ansprechpartner in allen Anliegen/Maßnahmen der Integration im Raum Krems. Die Arbeitsschwerpunkte werden auf Sprach- und Freizeitkurse, Begegnung im Alltag, Anschluss an vorhandene gesellschaftliche Ressourcen, niederschwellige Beratung/Begleitung sowie gemeinwesenorientierte Angebote gelegt. Im Mittelpunkt stehen dabei die Arbeit mit Kindern, Jugendlichen und Frauen sowie die lebensweltnahe Ausrichtung (Grätzlarbeit) der Angebote. Aufbauend auf 20-jährige Erfahrung in der Integrationsarbeit sowie dem Niederösterreich-weiten Leitlinienprozess "Sozialräumliche Integrationsarbeit" werden bisherige Angebote bedarfsgerecht adaptiert. Neben kontinuerlicher Kooperation mit diversen Einrichtungen stellen wöchentliche Kurs- und Beziehungsangebote sowie gezielte Projekte die Grundlage für niederschwellige Integrationsarbeit dar. | F47: NÖ | H47: 16600 | I47: 16600
...

Sheet 2020
A1: Gesamtübersicht Integrationsprojekte 2020
A2: Topf | B2: Projektträger | C2: Projektname | D2: FSWP | E2: Kurzbeschreibung | F2: Bundesland(e) | G2: AMIF-Mittel 2020 | H2: BKA-Mittel 2020 | I2: Gesamt 2020
A55: NAT | B55: Verein SprachBrücke Betriebsgesellschaft GmbH | C55: Deutsch im Alltag | D55: Deutsch | E55: DEUTSCH IM ALLTAG ist ein international erfolgreiches, wissensbasiertes Programm zur frühen Bildungsförderung in Familien mit Migrationserfahrung. Es zielt darauf ab, die Entwicklungsmöglichkeiten von Kindern frühzeitig und nachhaltig zu verbessern. Zielgruppe sind sozial- und bildungsbenachteiligte Familien mit Kindern im Alter von 3 bis 7 Jahren. In aufsuchender Familienarbeit durch muttersprachliche Hausbesucherinnen werden innerfamiliäre Bildungsaktivitäten auf spielerische Weise angeregt und vertieft und die Kinder auf den Schulbesuch vorbereitet. Durch begleitende Gruppentreffen und Exkursionen im sozialen Umfeld werden Kultur, Werte und Lebensweisen der Aufnahmegesellschaft vermittelt. Die Bildungssensibilisierung der gesamten Familie und die Verbesserung der sozialen Integration stellen einen wichtigen Beitrag zur Chancengerechtigkeit für Familien mit Migrationserfahrung dar. | F55: Steiermark | H55: 421422 | I55: 421422
A56: NAT | B56: Jugendzentrum Bunterhaufen | C56: YouthConnect – Jugendliche gestalten Integration | D56: Arbeitsmarkt | E56: Das Projekt YOUTHCONNECT versteht sich als sozialpädagogisches Projekt für Kinder und Jugendliche sowie als Plattform für Sportintegration. Es setzt sich zum Ziel, das sozialintegrative Potential des Sports in seiner gesamten Bandbreite zu nützen, und somit die Integration der Zielgruppe entscheidend voranzutreiben. KlientInnen können an den regelmäßig stattfindenden Sport- und Sprachförderungs-Modulen, an Sportveranstaltungen, dem Lern- und Sportprogramm GRAgustl, an beruflichen Qualifizierungsangeboten sowie Adventuretagen und Sportfesten teilnehmen, Workshops absolvieren, ehrenamtlich mitarbeiten oder auch Mitglied in einem der YOUTHCONNECTPartnervereine werden. Das Angebot von YOUTHCONNECT ist aufbauend und interdisziplinär und in vier Kernbereiche untergliedert: Sport+Teilnahme, + Teilhabe, + Bildung und Öffentlichkeitsarbeit. | F56: Steiermark | H56: 232142 | I56: 232142
A57: NAT | B57: Kulturverein Brücken Bauen | C57: Begegnungsräume – Kultur verbindet | D57: Gemeinde und Identität | E57: Das Projekt Begegnungsräume - Dialog und Integration" zielt auf die Verbesserung der Integration und des positiven Miteinanders von neu Zugewanderten und der Wohnbevölkerung in Gemeinden im ländlichen Raum im Pongau, Pinzgau und Lungau ab. Integration versteht sich als chancengleiche Teilnahme am sozialen und gesellschaftlichen Leben und soll wechselseitig (Zugezogene und autochthone Wohnbevölkerung) erfolgen. Innovativ in diesem Projekt sind die intensive regionale Vernetzungsarbeit und Bündelung lokaler und ehrenamtlicher Intiativen. Angebote und Maßnahmen im Integrationsbereich sollen attraktiv, überschaubar, punktuell, aber auch effizient und ergänzend gestaltet werden. Sie richten sich gleichermaßen an alle Bürger*innen einer Gemeinde. Durch Beratungsgespräche mit wichtigen Akteur*innen in den Projektgemeinden kann bedarfsorientiert mit Angeboten reagiert werden. | F57: Salzburg | H57: 80000 | I57: 80000
A60: National | B60: ASPIS - Psychosoziales Zentrum für Flüchtlinge und Opfer von Gewalt | C60: Integrationsinitiative Familie 2019: Ein Präventivprojekt mit Menschen aus Kriegs- und Krisengebieten | D60: Kinder, Jugendliche und Elternarbeit | E60: Wir haben in den letzten zweieinhalb Jahren Präventivarbeit gegen Radikalisierung und Identitätsdifussionen durchführen können. Die von uns betreuten und beratenen Familien werden aufgesucht (kulturspezifischer, psychologischer Zugang). Für Kinder und Jugendliche werden wöchentliche Workshops und Sportbegegnungen angeboten. Weiters ist unser Fußballteam ein idealer Platz für Jugendliche und junge Männer um ihren Selbstwert zu stärken. Zusätzlich finden Familienausflüge statt um die jeweiligen Familiensysteme zu stärken. Die Themen die wir bei den Besuchen zu bearbeiten haben handeln von Kränkungen, Familie, Rechtssystem, Schule, Rechte der Frauen, Gesundheitssystem u.v.m. | F60: K | H60: 33200 | I60: 33200
A61: National | B61: Verein Impulse Krems | C61: Krems Interkulturell 2019 - Förderung von Begegnung, Sprache und Integration im Alltag - Schwerpunkt | D61: Kinder, Jugendliche und Elternarbeit | E61: Krems Interkulturell ist eine Informations-, Förder- und Koordinationsstele sowie Ansprechpartner in allen Anliegen/Maßnahmen der Integration im Raum Krems. Die Arbeitsschwerpunkte werden auf Sprach- u Freizeitkurse, Begegnung im Alltag, Anschluss an vorhandene gesellsch. Ressourcen, niederschwellige Beratung/Begleitung sowie gemeinwesenorientierte Angebote gelegt. Im Mittelpunkt stehen dabei die Arbeit mit Kindern, Jugendlichen u Frauen sowie die lebensweltnahe Ausrichtung (Grätzlarbeit) der Angebote. Aufbauend auf 20J-Erfahrung in der Integrationsarbeit sowie dem NÖweiten Leitlinienprozess "Sozialräumliche Integrationsarbeit" werden bisherige Angebote bedarfsgerecht adaptiert. Neben kontinuerlicher Kooperation mit div. Einrichtungen stellen wöchentliche Kurs- und Beziehungsangebote sowie gezielte Projekte die Grundlage für niederschwellige Integrationsarbeit dar. | F61: NÖ | H61: 16600 | I61: 16600
A62: National | B62: Pronegg & Schleich Soziale Dienste GmbH | C62: BEAM Beratung_Begleitung Eltern Alltagskompetenz Migration | D62: Frauen | E62: Im Projekt BEAM (Beratung_Begleitung Eltern Alltagskompetenz Migration) gehen Prävention mit Information und Wissenstransfer Hand in Hand: Modul Mamaplausch bietet niederschwellige Information zu kindlicher Entwicklung und Gestaltung des Familienalltags - auch in interkulturellen Gruppen. Im Modul Beratung begleiten wir Familien und Kinder mit Unterstützungsbedarf und (drohender) Behinderung. Wissenstransfer: Durch Weitergabe von Informationen an Freiwillige, unsere Kolleginnen aus verschiedenen Kulturen und MultiplikatorInnen sollen Familien gut begleitet werden. Ziel ist es, Wissen und Kompetenzen zu erweitern und Netzwerke zu etablieren, um Kinder früh und umfassend zu fördern, Familien zu stärken und über vorhandene Angebote zu informieren | F62: ST | H62: 80095 | I62: 80095
A63: National | B63: Frauenberatung Waldviertel | C63: Beratungs- und Bildungsangebot für Migrantinnen zur Untertützung von Integration und eigenständiger Lebensgestaltung | D63: Frauen | E63: Das vorliegende Projekt richtet sich ausschließlich an Frauen und Mädchen im Waldviertel, welche entweder Drittstaatsangehörige mit Bleibeperspektive, Asylberechtigte oder subsidär Schutzberechtigte, EU Bürgerinnen oder Österreicherinnen mit Migrationshintergrund und dauerhafter Niederlassung in Österreich sind. Wesentliches Projektziel ist, diesen Frauen ein niederschwelliges, gut zugängliches Beratungs- Informations-und Kommunikationsangebot zu den Themen: Gesundheit, Arbeit, Rechtsstaat und Werte sowie theaterpädagogische Sprachförderung anzubieten, welches sie in die Lage versetzt, ihr Leben in Österreich eigenständig zu bewerkstelligen. | F63: NÖ | H63: 16600 | I63: 16600
A64: National | B64: ISK - Institut für Soziale Kompetenz | C64: Job4Life - Erfolg durch Berufsvorbereitung und Integration | D64: Kinder, Jugendliche und Elternarbeit | E64: Jugendliche mit Migrationshintergrund haben oft nur einen Pflichtschulabschluss und sind überproportional von Arbeitslosigkeit betroffen. Sie haben am Ende der Pflichtschule häufiger Orientierungsprobleme und brechen ihren Bildungsweg ab. Eine erfolgreiche berufliche Qualifizierung setzt daher eine fundierte Berufsvorbereitung voraus und ist eine wichtige Maßnahme zur langfristigen Erwerbstätigkeit und Integration. Das Projekt Job4Life unterstützt Jugendliche beim Einstieg in die berufliche Qualifizierung (Lehre) in der 7. – 9. Schulstufe mit einem umfassenden Berufsvorbereitungs-Lehrgang (Workshops, Beratung, Praxistage, Firmenkontakte, Bewerbungscoaching, etc.) an Schulen in OÖ im Rahmen der regulären Unterreichtseinheiten sowie der schulischen Nachmittagsbetreuung. Job4Life bezieht die Eltern ein und baut eine nachhaltige Brücke zwischen Schule und regionalen Unternehmen. | F64: OÖ | H64: 29050 | I64: 29050
A65: National | B65: Gemeinsam - Verein Initiative Interkulturelle Arbeit | C65: Deutschförderung und Integration von Schüler/innen aus Drittstaaten im Alter von 8-12 durch Mentoring nach dem Konzept Nightignale | D65: Deutsch | E65: 132 Student/innen (=Mentor/innen) begleiten und unterstützen 132 Schüler/innen aus Drittstaaten mit Förderbedarf im Deutschspracherwerb und bei Fragen der Integration. Nach Einschulung treffen sich die Tandems, die an 9-11 Standorten gebildet werden (7 in Wien, 1-2 in Graz, 1-2in Salzburg) je ca. 18 mal zu gemeinsamen Bildungs- und Freizeitaktivitäten, um implizit den Deutsch-Spracherwerb der Kinder zu verbessern. Die Schüler werden nach Förderbedarf ausgewählt, die Student/innen kommen aus verschiedenen Studienrichtungen und absolvieren mit dem Projekt ein freiwilliges Praktikum. Mentoring („Nightingale“- Konzept) bewirkt bei den Kindern: Zuwachs an Deutsch-Sprachkompetenz (wiss. bestätigt 2016) Selbstwert, Orientierung in der Stadt, Bildungsmöglichkeiten (Kultur, Museen, etc.), Nutzung öffentlicher Verkehrsmittel, Schwimmen, Radfahren, Verhalten der Mehrheitsgesellschaft, usw. | F65: S, ST, W | H65: 44827.06 | I65: 44827.06
A66: National | B66: Verein NL 40 | C66: Psychosoziales Lernhilfeprojekt für bildungs- und sozial benachteiligte Kinder und Jugendliche | D66: Kinder, Jugendliche und Elternarbeit | E66: Das „OMA/OPA-Projekt" ist ein psychosoziales Lernhilfeprojekt für bildungs- und sozial benachteiligte Kinder und Jugendliche. SchülerInnen der Volks- und Mittelschule werden kontinuierlich in einem Eins-zu-Eins-Verhältnis von freiwillig engagierten SeniorInnen und jüngeren Menschen betreut und dabei von einem multiprofessionellen Team begleitet. Die Basis der nachhaltigen Lernhilfe und Sprachförderung bildet die vertrauensvolle Beziehung zwischen den SchülerInnen, den LernhelferInnen und dem Projektteam. Dabei wird ein interkultureller und intergenerationeller Dialog eröffnet sowie Chancengerechtigkeit und gesellschaftliche Teilhabe junger und älterer Menschen durch gemeinsames Lernen gestärkt. Das Projekt schafft an seinen Standorten in Wien, Krems und Amstetten Orte der Begegnung und des respektvollen und toleranten Miteinanders. | F66: W, NÖ | H66: 74700 | I66: 74700
A67: National | B67: Volkshilfe Flüchtlings- und MigrantInnenbetreuung GmbH | C67: Lernförderung für Volks- und HauptschülerInnen mit nichtdeutscher Muttersprache | D67: Kinder, Jugendliche und Elternarbeit | E67: Das Angebot richtet sich vor allem an Kinder/Jugendliche mit Migrationshintergrund, die Schwierigkeiten im Umgang mit der deutschen Sprache und dadurch bei der Bewältigung des Schulalltags haben. Die Lernförderung findet in Kleingruppen von 5 bis 12 Schüler*innen statt. Die Einheiten werden zur Sprachförderung bzw. für Hilfestellung bei Deutsch-Hausaufgaben verwendet. Zudem werden die Deutschkenntnisse mithilfe verschiedener Methoden (Gesprächskreise, Dialoge, Frage-Antwort-Spiele, Lernspiele) ausgebaut, die Schüler*innen zum (freien) Sprechen angeregt sowie das Lernen in Gemeinschaft gefördert und Sozialkompetenzen gestärkt. Es wird eine Verbesserung der Chancengleichheit im Bildungsbereich durch Hilfestellung in schulischen Belangen und beim Erwerb der deutschen Sprache sowie eine gelingende Integration der betroffenen Schüler*innen in den Unterrichtsverlauf erreicht. | F67: OÖ | H67: 66400 | I67: 66400
A68: National | B68: Volkshilfe Flüchtlings- und MigrantInnenbetreuung GmbH | C68: Regionale Kompetenzzentren für Integration und Diversität | D68: Gemeinde und Identität | E68: Das Projekt hat die bedarfsgerechte Prozessbegleitung von oberösterreichischen Gemeinden bei der Integrationsarbeit zum Ziel. Als Maßnahmen werden etwa Moderation, Fachexpertise, Koordination und Vernetzung angeboten. Außerdem werden Weiterbildungsformate für engagierte Zivilgesellschaft und andere Akteure angeboten und Projektförderungen vermittelt. Informationen über Integrationsangebote und -maßnahmen werden regelmäßig und bedarfsgerecht an die Zielgruppe vermittelt. ReKIs begleiten und unterstützen Gemeinden bei Integrationsthemen und den damit verbundenen Herausforderungen. Sie sind kompetente Partner*innen der Kommunen, der Bezirksverwaltungen, der Regelsysteme und der lokalen und landesweiten Akteure im Integrationsbereich und optimieren Mitteleinsatz und Abstimmung angebotener Maßnahmen und Projekte. | F68: OÖ | H68: 53950 | I68: 53950
... A130: National | B130: Verein START-Stipendien Österreich | C130: START-Österreich Bildungsprogramm und Bundesländerarbeit bzw. -ausbau | D130: Kinder, Jugendliche und Elternarbeit | E130: 1) Finanzierung der zentral durchgeführten Bildungsseminare, an denen alle START-StipendiatInnen aus ganz Österreich teilnehmen. Hier werden Sachkosten in Form von Trainerhonoraren abgerechnet. 2) Finanzierung der Organisation und Durchführung von allen österreichweit bzw. bundesländerübergreifenden Veranstaltungen im Rahmen des START-Programms durch die Zurverfügungstellung von Personalressourcen (15 Wochenstunden ) 3) Finanzierung des Bundesländerausbaus (Personalressourcen 5 Wochenstunden und Sachkosten in Form von Reisekosten) 4) Finanzierung des START-Österreich Alumninetzwerks (Sachkosten für Weiterbildung und integrative Workshops) | F130: W, V, S, OÖ, NÖ | H130: 66400 | I130: 66400
A132: =SUMPRODUCT((A3:A130="AMIF")*SUBTOTAL(103,OFFSET(A3,ROW(A3:A130)-ROW(A3),0))) -> 0 | B132: Zwischensumme: AMIF | G132: =SUMPRODUCT((A3:A130="AMIF")*SUBTOTAL(103,OFFSET(A3,ROW(A3:A130)-ROW(A3),0))*G3:G130) -> 0 | H132: =SUMPRODUCT((A3:A130="AMIF")*SUBTOTAL(103,OFFSET(A3,ROW(A3:A130)-ROW(A3),0))*H3:H130) -> 0 | I132: =SUMPRODUCT((A3:A130="AMIF")*SUBTOTAL(103,OFFSET(A3,ROW(A3:A130)-ROW(A3),0))*I3:I130) -> 0
A133: =SUMPRODUCT((A3:A130="National")*SUBTOTAL(103,OFFSET(A3,ROW(A3:A130)-ROW(A3),0))) -> 71 | B133: Zwischensumme: National | G133: =SUMPRODUCT((A3:A130="National")*SUBTOTAL(103,OFFSET(A3,ROW(A3:A130)-ROW(A3),0))*G3:G130) -> 0 | H133: =SUMPRODUCT((A3:A130="National")*SUBTOTAL(103,OFFSET(A3,ROW(A3:A130)-ROW(A3),0))*H3:H130) -> 4537695 | I133: =SUMPRODUCT((A3:A130="National")*SUBTOTAL(103,OFFSET(A3,ROW(A3:A130)-ROW(A3),0))*I3:I130) -> 4537695
A134: =SUMPRODUCT(((A3:A130="AMIF")+(A3:A130="AMIF-UKR")+(A3:A130="NATÜ")+(A3:A130="National"))*SUBTOTAL(103,OFFSET(A3,ROW(A3:A130)-ROW(A3),0))) -> 71 | B134: GESAMT 2020 | G134: =SUBTOTAL(9,G3:G130) -> 0 | H134: =SUBTOTAL(9,H3:H130) -> 5271259 | I134: =SUBTOTAL(9,I3:I130) -> 5271259
A136: * Summen reagieren auf Filter und Zeilenlöschung | Quelle: BKA Integrationsprojekte 2020

Sheet 2021
A2: Topf | B2: Projektträger | C2: Projektname | D2: FSWP | E2: Kurzbeschreibung | F2: Bundesland(e) | G2: AMIF-Mittel 2021 | H2: BKA-Mittel 2021 | I2: Gesamt 2021
A3: NAT | B3: Verein Gemeinsam Wachsen | C3: „SchulStart – Begleitprogramm für neu zugewanderte Schulkinder | D3: Bildung | E3: SchulStart bietet Bildungsberatung und Berufsorientierungstraining, arbeitet aufsuchend und online mit individuellen Trainingsmaßnahmen sowie ausgebildeten Buddies u. Native Speaker für Bildungsabschluss, zur (Re)Integration am Arbeitsmarkt, zur Teilhabe an der Gesellschaft. | F3: Salzburg | H3: 45000 | I3: 45000
A4: NAT | B4: Verein NeueWege Österreich | C4: HandWerk.Zukunft – Berufsvorbereitungskurse mit Lehrvermittlung | D4: Arbeitsmarkt | E4: HandWerk.Zukunft – Berufsvorbereitungskurse mit Lehrv! ist ein Arbeitsmarktintegrationsprojekt des Verein NeueWege Österreich für Menschen mit Migrationshintergrund, die eine Lehre beginnen wollen. Das modular aufgebaute Programm qualifiziert Teilnehmende durch Beratung, Schulung und Training.Ziel von HandWerk.Zukunft ist es, TeilnehmerInnen durch ein breites Maßnahmenpaket aus kompetenzbildenden Workshops, fachspezifischen Deutschkursen und intensiver fachlicher Begleitung auf ihre Lehrausbildung vorzubereiten und zu qualifizieren. Praktika in Unternehmen ergänzen die Kursmaßnahme. | F4: Steiermark | H4: 280000 | I4: 280000
A125: =SUMPRODUCT((A3:A123="AMIF")*SUBTOTAL(103,OFFSET(#REF!,ROW(A3:A123)-ROW(#REF!),0))) -> #REF! | B125: Zwischensumme: AMIF | G125: =SUMPRODUCT((A3:A123="AMIF")*SUBTOTAL(103,OFFSET(#REF!,ROW(A3:A123)-ROW(#REF!),0))*G3:G123) -> #REF! | H125: =SUMPRODUCT((A3:A123="AMIF")*SUBTOTAL(103,OFFSET(#REF!,ROW(A3:A123)-ROW(#REF!),0))*H3:H123) -> #REF! | I125: =SUMPRODUCT((A3:A123="AMIF")*SUBTOTAL(103,OFFSET(#REF!,ROW(A3:A123)-ROW(#REF!),0))*I3:I123) -> #REF!
A126: =SUMPRODUCT((A3:A123="National")*SUBTOTAL(103,OFFSET(#REF!,ROW(A3:A123)-ROW(#REF!),0))) -> #REF! | B126: Zwischensumme: National | G126: =SUMPRODUCT((A3:A123="National")*SUBTOTAL(103,OFFSET(#REF!,ROW(A3:A123)-ROW(#REF!),0))*G3:G123) -> #REF! | H126: =SUMPRODUCT((A3:A123="National")*SUBTOTAL(103,OFFSET(#REF!,ROW(A3:A123)-ROW(#REF!),0))*H3:H123) -> #REF! | I126: =SUMPRODUCT((A3:A123="National")*SUBTOTAL(103,OFFSET(#REF!,ROW(A3:A123)-ROW(#REF!),0))*I3:I123) -> #REF!
A127: =SUMPRODUCT(((A3:A123="AMIF")+(A3:A123="AMIF-UKR")+(A3:A123="NATÜ")+(A3:A123="National"))*SUBTOTAL(103,OFFSET(#REF!,ROW(A3:A123)-ROW(#REF!),0))) -> #REF! | B127: GESAMT 2021 | G127: =SUBTOTAL(9,G3:G123) -> 0 | H127: =SUBTOTAL(9,H3:H123) -> 325000 | I127: =SUBTOTAL(9,I3:I123) -> 325000
A129: * Summen reagieren auf Filter und Zeilenlöschung | Quelle: BKA Integrationsprojekte 2021

Sheet 2022
A1: Gesamtübersicht Integrationsprojekte 2022
A2: Topf | B2: Projektträger | C2: Projektname | D2: FSWP | E2: Kurzbeschreibung | F2: Bundesland(e) | G2: AMIF-Mittel 2022 | H2: BKA-Mittel 2022 | I2: Gesamt 2022
B3: Helpservice Österreich | C3: Lernstube - Kostenlose Lernbegleitung für Kinder und Jugendliche | D3: Biludng | E3: Kostenlose Lern- und Nachmittagsbetreuung für Kinder und Jugendliche zwischen 6 bis 15 Jahren aus sozial benachteiligten und bildungsfernen Schichten. Im Fokus stehen: gezielte Lernhilfe, Vorbereitung auf Schularbeiten/Tests, Stärkung der Deutsch-, Sprach- und Lesekompetenzen, Lernen lernen, Persönlichkeitsentwicklung, wertschätzenden Umgang mit diversen Kulturen/Religionen fördern, gesunde Jause, Workshops und Aktivitäten zur Horizonterweiterung, etc. | F3: Österreichweit | H3: 860000 | I3: 860000
B4: TARO - Verein zur interkulturellen Gesundheitsförderung | C4: Wurzeln fassen – Traumasensible Begleitung | D4: Biludng | E4: Wurzeln fassen – Traumasensible Begleitung ist ein wirksames Programm zur Traumabewältigung. Schulkinder erlernen Techniken, die Lernfähigkeit und soziale Interaktion verbessern. Während der Pandemie wurde das Programm auch für die Anwendung in Familien adaptiert und evaluiert. Nach einer Pilotphase in Graz folgt die weitere Ausrollung nach Tirol. | F4: Wien, Niederösterreich, Steiermark, Tirol | H4: 231000 | I4: 231000
